Workbook
Name Discount: #REF!
Name Discount: #REF!
Name Discount: #REF!
Name Discount: #REF!
Name Discount: #REF!
Name Discount: #REF!
Name Discount: #REF!
Name Discount: #REF!
Name Discount: #REF!
Name Discount: #REF!
Name Discount: #REF!
Name Discount: #REF!
Name Discount: #REF!
Name Discount: #REF!
Name Discount: #REF!

Sheet Cost Data
A1: Division | B1: 2
B2: 01 00 00 | C2: General Requirements
B3: 01 11 00 | C3: Preconstruction Costs | D3: ='1'!K24 -> 0
B4: 01 31 00 | C4: Project Management and Coordination | D4: ='1'!K35 -> 165000
B5: 01 41 00 | C5: Permits | D5: ='1'!K67 -> 3000
B6: 01 45 00 | C6: Quality Control | D6: ='1'!K76 -> 8000
B7: 01 51 00 | C7: Temporary Utilities | D7: ='1'!K87 -> 15000
B8: 01 52 00 | C8: Construction Facilities | D8: ='1'!K97 -> 35468.079
B9: 01 54 00 | C9: Construction Aids | D9: ='1'!K105 -> 203313.04
B10: 01 56 00 | C10: Temporary Barriers & Enclosures | D10: ='1'!K128 -> 25000
B11: 01 74 00 | C11: Cleaning & Waste Management | D11: ='1'!K136 -> 54500
A13: Division | B13: 2
B15: 02 00 00 | C15: Existing Conditions
B16: 02 41 00 | C16: Demolition | D16: ='2'!K26 -> 0
B17: 02 82 00 | C17: Asbestos Remediation | D17: ='2'!K37 -> 0
B18: 02 83 00 | C18: Trenching | D18: ='2'!K48 -> 0
A21: Division | B21: 3
B22: 03 00 00 | C22: Concrete
B23: 03 11 00 | C23: Concrete Forming | D23: ='3'!K26 -> 302400
B24: 03 20 00 | C24: Concrete Reinforcing | D24: ='3'!K37 -> 0
B25: 03 30 00 | C25: Cast-in-Place Concrete | D25: ='3'!K50 -> 177795.86
B26: 03 35 00 | C26: Concrete Finishing | D26: ='3'!K59 -> 44527
B27: 03 40 00 | C27: Precast Concrete | D27: ='3'!K70 -> 77850
B28: 03 60 00 | C28: Grouting | D28: ='3'!K79 -> 68035
A31: Division | B31: 4
B32: 04 00 00 | C32: Masonry
B33: 04 20 00 | C33: Unit Masonry | D33: ='4'!K26 -> 140360
B34: 04 43 00 | C34: Stone Masonry | D34: ='4'!K37 -> 0
A36: Division | B36: 5
B37: 05 00 00 | C37: Metals
B38: 05 12 00 | C38: Structural Steel Framing | D38: ='5'!K26 -> 141400
B39: 05 20 00 | C39: Metal Joists | D39: ='5'!K37 -> 0
B40: 05 30 00 | C40: Metal Decking | D40: ='5'!K45 -> 0
B41: 05 51 00 | C41: Metal Stairs | D41: ='5'!K54 -> 0
B42: 05 52 00 | C42: Metal Railings | D42: ='5'!K65 -> 73570
B43: 05 59 00 | C43: Metal Specialties | D43: ='5'!K74 -> 0
A46: Division | B46: 6
B47: 06 00 00 | C47: Wood, Plastics, and Composites
B48: 06 11 00 | C48: Framing | D48: ='6'!K19 -> 571330
B49: 06 20 00 | C49: Finish Carpentry | D49: ='6'!K36 -> 1261823.7
...

Sheet Cost Report
B1: Division | C1: Sub - Division | D1: Discription | E1: Cost
B2: 01 00 00 | D2: General Requirements | E2: ='Estimate Summary'!H15 -> 584281.12
B3: 01 11 00 | D3: Preconstruction Costs | E3: ='1'!K24 -> 0
B4: 01 31 00 | D4: Project Management and Coordination | E4: ='1'!K35 -> 165000
B5: 01 31 00 | C5: 01 31 01 | D5: Senior Construction Manager | E5: ='1'!K27 -> 0
B6: 01 31 00 | C6: 01 31 02 | D6: Senior Estimator | E6: ='1'!K28 -> 0
B7: 01 31 00 | C7: 01 31 03 | D7: Senior Project Manager | E7: ='1'!K29 -> 0
B8: 01 31 00 | C8: 01 31 04 | D8: Project Coordinator | E8: ='1'!K30 -> 0
B9: 01 31 00 | C9: 01 31 05 | D9: Project Superintendent | E9: ='1'!K31 -> 165000
B10: 01 31 00 | C10: 01 31 06 | D10: Project Foreman | E10: ='1'!K32 -> 0
B11: 01 32 00 | C11: 01 32 00 | D11: Travel
B12: 01 41 00 | D12: Permits | E12: ='1'!K67 -> 3000
B13: 01 45 00 | D13: Quality Control | E13: ='1'!K76 -> 8000
B14: 01 51 00 | D14: Temporary Utilities | E14: ='1'!K87 -> 15000
B15: 01 52 00 | D15: Construction Facilities | E15: ='1'!K97 -> 35468.079
B16: 01 52 00 | C16: 01 52 01 | D16: Construction Field Office | E16: ='1'!K90 -> 12375
B17: 01 52 00 | C17: 01 52 02 | D17: Sanitary Facilities | E17: ='1'!K92 -> 12000
B18: 01 52 00 | C18: 01 52 03 | D18: Drawing Reprographics | E18: ='1'!K93 -> 5503.0789
B19: 01 52 00 | C19: 01 52 04 | D19: First-Aid / Safety | E19: ='1'!K94 -> 3750
B20: 01 52 00 | C20: 01 52 05 | D20: Job Sign | E20: ='1'!K95 -> 0
B21: 01 54 00 | D21: Construction Aids | E21: ='1'!K105 -> 203313.04
B22: 01 55 00 | C22: 01 55 00 | D22: Winter Conditions
B23: 01 56 00 | D23: Temporary Barriers & Enclosures | E23: ='1'!K128 -> 25000
B24: 01 74 00 | D24: Cleaning & Waste Management | E24: ='1'!K136 -> 54500
B25: 01 74 00 | C25: 01 74 01 | D25: Progress Cleaning | E25: ='1'!K131 -> 0
B26: 01 74 00 | C26: 01 74 02 | D26: Site Maintenance | E26: ='1'!K132 -> 14400
B27: 01 74 00 | C27: 01 74 03 | D27: Construction Waste Mgmt & Disposal | E27: ='1'!K133 -> 16500
B28: 01 74 00 | C28: 01 74 04 | D28: Final Cleaning | E28: ='1'!K134 -> 23600
B29: 02 00 00 | D29: Existing Conditions | E29: ='Estimate Summary'!H17 -> 0
B30: 02 41 00 | D30: Demolition | E30: ='2'!K26 -> 0
B31: 02 82 00 | D31: Asbestos Remediation | E31: ='2'!K37 -> 0
B32: 02 83 00 | D32: Trenching | E32: ='2'!K48 -> 0
B33: 03 00 00 | D33: Concrete | E33: ='Estimate Summary'!H19 -> 670607.86
B34: 03 11 00 | D34: Concrete Forming | E34: ='3'!K26 -> 302400
B35: 03 20 00 | D35: Concrete Reinforcing | E35: ='3'!K37 -> 0
B36: 03 30 00 | D36: Cast-in-Place Concrete | E36: ='3'!K50 -> 177795.86
B37: 03 35 00 | D37: Concrete Finishing | E37: ='3'!K59 -> 44527
B38: 03 40 00 | D38: Precast Concrete | E38: ='3'!K70 -> 77850
B39: 03 60 00 | D39: Foundation Materials | E39: ='3'!K79 -> 68035
B40: 03 60 00 | C40: 03 60 01 | D40: Insulation | E40: ='3'!K73 -> 15640
...

Sheet DATA
B2: Quarter | C2: Column1 | D2: Province | H2: Project Definition | J2: Contract Type | K2: Payment Method | M2: A | N2: >5M
B3: Q1 | D3: NB | H3: Multi Residential | J3: CCDC 2 | K3: Stipulated Price | M3: B | N3: 2-5M
B4: Q2 | D4: PEI | H4: Office | J4: CCDC 5B | K4: Fixed Fee | M4: C | N4: 500K - 2M | R4: Status | T4: Result
B5: Q3 | D5: NS | H5: Retail | J5: CCDC 5A | M5: D | N5: 100K - 500K | R5: Awarded | T5: Successful
B6: Q4 | D6: Other | H6: Food | J6: Design Build | M6: E | N6: less than 100K | R6: Not Awarded | T6: Unsuccessful
R7: Pending
A10: Closing Date | B10: Budget Year | C10: Quarter | D10: Province | E10: City/Town | F10: Estimate Number | G10: Estimate Name | H10: Type of Construction | I10: Area | J10: Contract Type | K10: Payment Method | L10: Estimate Price | M10: Price Category | N10: Schedule | O10: Soft Cost | P10: Cost per Week | Q10: Margin | R10: Status | S10: Bid Docs | T10: Successful / Unsuccessful
A11: =+'Estimate Summary'!B3 -> 45379 | B11: =+'Estimate Summary'!B7 -> 2024 | C11: =+'Estimate Summary'!B8 -> Q2 | D11: =+'Estimate Summary'!B5 -> NB | E11: ='Estimate Summary'!B6 -> Moncton | F11: ='Estimate Summary'!B4 -> 2989 | G11: ='Estimate Summary'!D5 -> 2500 Mountain Road Multi-Res | H11: =+'Estimate Summary'!F8 -> 0 | I11: =+'Estimate Summary'!D11 -> 65592 | J11: ='Estimate Summary'!D7 -> CCDC 5B | K11: =+'Estimate Summary'!D8 -> Fixed Fee | L11: =+'Estimate Summary'!D75 -> 11119373 | M11: =IF(L11<100000,"E",IF(L11<500000,"D",IF(L11<2000000,"C",IF(L11<5000000,"B",IF(L11>=5000000,"A"))))) -> A | N11: ='Estimate Summary'!D81 -> 60 | O11: ='Estimate Summary'!D82 -> 737710.08 | P11: ='Estimate Summary'!E82 -> 12295.168 | Q11: ='Estimate Summary'!D84 -> 0.066344575 | R11: ='Estimate Summary'!F6 -> 0 | S11: ='Estimate Summary'!F5 -> 0 | T11: ='Estimate Summary'!F7 -> 0

Sheet Estimate Version Comparison
B2: ='Estimate Summary'!D5 -> 2500 Mountain Road Multi-Res | I2: CLIENT SUMMARY
B3: ='Estimate Summary'!D6 -> Ashish Goel
B4: Date: | C4: ='Estimate Summary'!B3 -> 45379
G7: ='Estimate Summary'!B3 -> 45379 | H7: ='Estimate Summary'!G8 -> 0
B8: 01 00 00 | C8: General Requirements | E8: =SUM(D9:D17) -> 0 | H8: =SUM(G9:G17) -> 509281.12 | J8: =IF(H8>E8,"Increase","Decrease or No Change") -> Increase | K8: =H8-E8 -> 509281.12
B9: 01 11 00 | C9: Preconstruction Costs | D9: 0 | G9: ='1'!K24 -> 0
B10: 01 31 00 | C10: Project Management and Coordination | D10: 0 | G10: ='1'!K35 -> 165000
B11: 01 41 00 | C11: Permits | D11: 0 | G11: ='1'!K67 -> 3000
B12: 01 45 00 | C12: Quality Control | D12: 0 | G12: ='1'!K76 -> 8000
B13: 01 51 00 | C13: Temporary Utilities | D13: 0 | G13: ='1'!K87 -> 15000
B14: 01 52 00 | C14: Construction Facilities | D14: 0 | G14: ='1'!K97 -> 35468.079
B15: 01 54 00 | C15: Construction Aids | D15: 0 | G15: ='1'!K105 -> 203313.04
B16: 01 56 00 | C16: Temporary Barriers & Enclosures | D16: 0 | G16: ='1'!K128 -> 25000
B17: 01 74 00 | C17: Cleaning & Waste Management | D17: 0 | G17: ='1'!K136 -> 54500
B19: 02 00 00 | C19: Existing Conditions | E19: =SUM(D20:D22) -> 0 | H19: =SUM(G20:G22) -> 0 | J19: =IF(H19>E19,"Increase","Decrease or No Change") -> Decrease or No Change | K19: =H19-E19 -> 0
B20: 02 41 00 | C20: Demolition | D20: 0 | G20: ='2'!K13 -> 0
B21: 02 82 00 | C21: Asbestos Remediation | D21: 0 | G21: ='2'!K37 -> 0
B22: 02 83 00 | C22: Trenching | D22: 0 | G22: ='2'!K48 -> 0
B24: 03 00 00 | C24: Concrete | E24: =SUM(D25:D29) -> 0 | H24: =SUM(G25:G29) -> 670607.86 | J24: =IF(H24>E24,"Increase","Decrease or No Change") -> Increase | K24: =H24-E24 -> 670607.86
B25: 03 11 00 | C25: Concrete Forming | D25: 0 | G25: ='3'!K26 -> 302400
B26: 03 20 00 | C26: Concrete Reinforcing | D26: 0 | G26: ='3'!K37 -> 0
B27: 03 30 00 | C27: Cast-in-Place Concrete | D27: 0 | G27: ='3'!K50+'3'!K59 -> 222322.86
B28: 03 40 00 | C28: Precast Concrete | D28: 0 | G28: ='3'!K70 -> 77850
B29: 03 60 00 | C29: Grouting | D29: 0 | G29: ='3'!K79 -> 68035
B31: 04 00 00 | C31: Masonry | E31: =SUM(D32:D33) -> 0 | H31: =SUM(G32:G33) -> 140360 | J31: =IF(H31>E31,"Increase","Decrease or No Change") -> Increase | K31: =H31-E31 -> 140360
B32: 04 20 00 | C32: Unit Masonry | D32: 0 | G32: ='4'!K26 -> 140360
B33: 04 40 00 | C33: Stone Assemblies | D33: 0 | G33: ='4'!K37 -> 0
B35: 05 00 00 | C35: Metals | E35: =SUM(D36:D39) -> 0 | H35: =SUM(G36:G39) -> 214970 | J35: =IF(H35>E35,"Increase","Decrease or No Change") -> Increase | K35: =H35-E35 -> 214970
B36: 05 12 00 | C36: Structural Steel Framing | D36: 0 | G36: ='5'!K26 -> 141400
B37: 05 20 00 | C37: Metal Joists | D37: 0 | G37: ='5'!K37 -> 0
B38: 05 30 00 | C38: Metal Decking | D38: 0 | G38: ='5'!K45 -> 0
B39: 05 50 00 | C39: Metal Fabrications | D39: 0 | G39: ='5'!K54+'5'!K65+'5'!K74 -> 73570
B41: 06 00 00 | C41: Wood, Plastics, and Composites | E41: =SUM(D42:D45) -> 0 | H41: =SUM(G42:G45) -> 2574857.6 | J41: =IF(H41>E41,"Increase","Decrease or No Change") -> Increase | K41: =H41-E41 -> 2574857.6
B42: 06 11 00 | C42: Framing Labour | D42: 0 | G42: ='6'!K19 -> 571330
B43: 06 11 00 | C43: Framing Material | D43: 0 | G43: ='6'!K36 -> 1261823.7
B44: 06 22 00 | C44: Millwork | D44: 0 | G44: ='6'!K47 -> 425900
B45: 06 40 00 | C45: Architectural Woodwork | D45: 0 | G45: ='6'!K55+'6'!K64+'6'!K75+'6'!K84+'6'!K91 -> 315803.89
B47: 07 00 00 | C47: Thermal and Moisture Protection | E47: =SUM(D48:D57) -> 0 | H47: =SUM(G48:G57) -> 1179521 | J47: =IF(H47>E47,"Increase","Decrease or No Change") -> Increase | K47: =H47-E47 -> 1179521
B48: 07 21 00 | C48: Thermal Insulation | D48: 0 | G48: ='7'!K16 -> 237835
B49: 07 24 00 | C49: EIFS | D49: 0 | G49: ='7'!K22 -> 271678.01
...

Sheet Client  Detailed Summary 
B3: ='Estimate Summary'!D5 -> 2500 Mountain Road Multi-Res | F3: CLIENT SUMMARY
B5: Date: | C5: 45421
B7: 01 00 00 | C7: General Requirements | H7: =SUM(G8:G18) -> 584281.12
B8: 01 11 00 | C8: Preconstruction Costs | G8: ='1'!K24 -> 0
B9: 01 31 00 | C9: Project Management and Coordination | G9: ='1'!K35 -> 165000
B10: 01 32 00 | C10: Insurance | G10: ='1'!K45+'1'!K56 -> 0 | H10: By Client
B11: 01 41 00 | C11: Permits | G11: ='1'!K67 -> 3000 | H11: By Client
B12: 01 45 00 | C12: Quality Control | G12: ='1'!K76 -> 8000
B13: 01 51 00 | C13: Temporary Utilities | G13: ='1'!K87 -> 15000
B14: 01 52 00 | C14: Construction Facilities | G14: ='1'!K97 -> 35468.079
B15: 01 54 00 | C15: Security | G15: ='1'!K100 -> 30000
B16: 01 54 00 | C16: Construction Aids & Winter Conditions | G16: ='1'!K105+'1'!K120-G15 -> 248313.04
B17: 01 56 00 | C17: Temporary Barriers & Enclosures | G17: ='1'!K128 -> 25000
B18: 01 74 00 | C18: Cleaning & Waste Management | G18: ='1'!K136 -> 54500
B20: 02 00 00 | C20: Existing Conditions | H20: =SUM(G21:G23) -> 0
B21: 02 41 00 | C21: Demolition | G21: ='2'!K26 -> 0
B22: 02 82 00 | C22: Asbestos Remediation | G22: ='2'!K37 -> 0
B23: 02 83 00 | C23: Trenching | G23: ='2'!K48 -> 0
B25: 03 00 00 | C25: Concrete | H25: =SUM(G26:G30) -> 670607.86
B26: 03 11 00 | C26: Concrete Forming | G26: ='3'!K26 -> 302400
B27: 03 20 00 | C27: Concrete Reinforcing | G27: ='3'!K37 -> 0
B28: 03 30 00 | C28: Cast-in-Place Concrete | G28: ='3'!K50+'3'!K59 -> 222322.86
B29: 03 40 00 | C29: Precast Concrete | G29: ='3'!K70 -> 77850
B30: 03 60 00 | C30: Grouting | G30: ='3'!K79 -> 68035
B32: 04 00 00 | C32: Masonry | H32: =SUM(G33:G34) -> 140360
B33: 04 20 00 | C33: Exterior Stone Veneer | G33: ='4'!K26 -> 140360
B34: 04 40 00 | C34: Stone Assemblies | G34: ='4'!K37 -> 0
B36: 05 00 00 | C36: Metals | H36: =SUM(G37:G40) -> 214970
B37: 05 12 00 | C37: Structural Steel Framing | G37: ='5'!K26 -> 141400
B38: 05 20 00 | C38: Metal Joists | G38: ='5'!K37 -> 0
B39: 05 30 00 | C39: Metal Decking | G39: ='5'!K45 -> 0
B40: 05 50 00 | C40: Balcony Handrails | G40: ='5'!K54+'5'!K65+'5'!K74 -> 73570
B42: 06 00 00 | C42: Wood, Plastics, and Composites | H42: =SUM(G43:G46) -> 2574857.6
B43: 06 11 00 | C43: Framing Labour | G43: ='6'!K19 -> 571330
B44: 06 11 00 | C44: Framing Material | G44: ='6'!K36 -> 1261823.7
B45: 06 22 00 | C45: Millwork | G45: ='6'!K47 -> 425900
B46: 06 40 00 | C46: Architectural Woodwork | G46: ='6'!K55+'6'!K64+'6'!K75+'6'!K84+'6'!K91 -> 315803.89
B48: 07 00 00 | C48: Thermal and Moisture Protection | H48: =SUM(G49:G58) -> 1179521
B49: 07 21 00 | C49: Thermal Insulation | G49: ='7'!K16 -> 237835
B50: 07 24 00 | C50: Acoustiboard floor soundproofing | G50: ='7'!K22 -> 271678.01
...

Sheet Estimate Summary
A2: Project Information
A3: Closing Date : | B3: 45379
A4: Estimate # E- | B4: 2989 | C4: Area: | D4: 65592
A5: Province : | B5: NB | C5: Estimate Name : | D5: 2500 Mountain Road Multi-Res | E5: Bid Documents :
A6: City/Town : | B6: Moncton | C6: Client : | D6: Ashish Goel | E6: Status :
A7: Budget Year : | B7: 2024 | C7: Contract Type : | D7: CCDC 5B | E7: Result:
A8: Quarter: | B8: Q2 | C8: Payment Method : | D8: Fixed Fee
C11: Area: | D11: =D4 -> 65592 | E11: Sq. Ft. | K11: Belle Foret | L11: 77648 | M11: SF
A13: CODE | B13: DESCRIPTION | D13: M&E $$ | E13: M-HRS | F13: LAB $$ | G13: SUB CONT. | H13: Total | K13: Comparable Project
C14: % | I14: $/SF
A15: 01 00 00 | B15: General Requirements | C15: =H15/D$66 -> 0.05517354 | D15: =SUM('1'!F139:F140) -> 401881.12 | E15: =SUM('1'!G139:G140) -> 241 | F15: =SUM('1'!I139:I140) -> 179400 | G15: =SUM('1'!J139:J140) -> 3000 | H15: =D15+F15+G15 -> 584281.12 | I15: =ROUNDUP(H15/D$11,1)&"$/SF" -> 9$/SF | K15: =669794.47+187000 -> 856794.47 | L15: =K15/$L$11 -> 11.03434
A17: 02 00 00 | B17: Existing Conditions | C17: =H17/D$66 -> 0 | D17: =SUM('2'!F51:F52) -> 0 | E17: =SUM('2'!G51:G52) -> 0 | F17: =SUM('2'!I51:I52) -> 0 | G17: =SUM('2'!J51:J52) -> 0 | H17: =D17+F17+G17 -> 0 | I17: =ROUNDUP(H17/D$11,1)&"$/SF" -> 0$/SF
A19: 03 00 00 | B19: Concrete | C19: =H19/D$66 -> 0.063325356 | D19: =SUM('3'!F82:F83) -> 236330.86 | E19: =SUM('3'!G82:G83) -> 158.33333 | F19: =SUM('3'!I82:I83) -> 9500 | G19: =SUM('3'!J82:J83) -> 424777 | H19: =D19+F19+G19 -> 670607.86 | I19: =ROUNDUP(H19/D$11,1)&"$/SF" -> 10.3$/SF | K19: 1469856 | L19: =K19/$L$11 -> 18.929734
A21: 04 00 00 | B21: Masonry | C21: =H21/D$66 -> 0.013254164 | D21: =SUM('4'!F68:F69) -> 0 | E21: =SUM('4'!G68:G69) -> 0 | F21: =SUM('4'!I68:I69) -> 0 | G21: =SUM('4'!J68:J69) -> 140360 | H21: =D21+F21+G21 -> 140360 | I21: =ROUNDUP(H21/D$11,1)&"$/SF" -> 2.2$/SF | K21: 240000 | L21: =K21/$L$11 -> 3.0908716
A23: 05 00 00 | B23: Metals | C23: =H23/D$66 -> 0.020299571 | D23: =SUM('5'!F77:F78) -> 800 | E23: =SUM('5'!G77:G78) -> 0 | F23: =SUM('5'!I77:I78) -> 0 | G23: =SUM('5'!J77:J78) -> 214170 | H23: =D23+F23+G23 -> 214970 | I23: =ROUNDUP(H23/D$11,1)&"$/SF" -> 3.3$/SF | K23: 141945.5 | L23: =K23/$L$11 -> 1.8280638
A25: 06 00 00 | B25: Wood, Plastics, and Composites | C25: =H25/D$66 -> 0.24314324 | D25: =SUM('6'!F94:F95) -> 551103.89 | E25: =SUM('6'!G94:G95) -> 0 | F25: =SUM('6'!I94:I95) -> 0 | G25: =SUM('6'!J94:J95) -> 2023753.7 | H25: =D25+F25+G25 -> 2574857.6 | I25: =ROUNDUP(H25/D$11,1)&"$/SF" -> 39.3$/SF | K25: 2971859.6 | L25: =K25/$L$11 -> 38.273486
A27: 07 00 00 | B27: Thermal and Moisture Protection | C27: =H27/D$66 -> 0.11138191 | D27: =SUM('7'!F93:F94) -> 545786.81 | E27: =SUM('7'!G93:G94) -> 59077.8 | F27: =SUM('7'!I93:I94) -> 99349.2 | G27: =SUM('7'!J93:J94) -> 534385 | H27: =D27+F27+G27 -> 1179521 | I27: =ROUNDUP(H27/D$11,1)&"$/SF" -> 18$/SF | K27: 1267203.6 | L27: =K27/$L$11 -> 16.319849
A29: 08 00 00 | B29: Openings | C29: =H29/D$66 -> 0.025914348 | D29: =SUM('8'!F108:F109) -> 8000 | E29: =SUM('8'!G108:G109) -> 0 | F29: =SUM('8'!I108:I109) -> 0 | G29: =SUM('8'!J108:J109) -> 266429.81 | H29: =D29+F29+G29 -> 274429.81 | I29: =ROUNDUP(H29/D$11,1)&"$/SF" -> 4.2$/SF | K29: 508342.1 | L29: =K29/$L$11 -> 6.5467507
A31: 09 00 00 | B31: Finishes | C31: =H31/D$66 -> 0.16499952 | D31: =SUM('9'!F65:F66) -> 121100 | E31: =SUM('9'!G65:G66) -> 0 | F31: =SUM('9'!I65:I66) -> 0 | G31: =SUM('9'!J65:J66) -> 1626225 | H31: =D31+F31+G31 -> 1747325 | I31: =ROUNDUP(H31/D$11,1)&"$/SF" -> 26.7$/SF | K31: 1804882.8 | L31: =K31/$L$11 -> 23.24442
A33: 10 00 00 | B33: Specialties | C33: =H33/D$66 -> 0.0083262291 | D33: =SUM('10'!F74:F75) -> 13329.39 | E33: =SUM('10'!G74:G75) -> 5 | F33: =SUM('10'!I74:I75) -> 300 | G33: =SUM('10'!J74:J75) -> 74544.37 | H33: =D33+F33+G33 -> 88173.76 | I33: =ROUNDUP(H33/D$11,1)&"$/SF" -> 1.4$/SF | K33: 101680 | L33: =K33/$L$11 -> 1.3094993
A35: 11 00 00 | B35: Equipment | C35: =H35/D$66 -> 0.018942615 | D35: =SUM('11'!F99:F100) -> 200600 | E35: =SUM('11'!G99:G100) -> 0 | F35: =SUM('11'!I99:I100) -> 0 | G35: =SUM('11'!J99:J100) -> 0 | H35: =D35+F35+G35 -> 200600 | I35: =ROUNDUP(H35/D$11,1)&"$/SF" -> 3.1$/SF | K35: 234000 | L35: =K35/$L$11 -> 3.0135998
A37: 12 00 00 | B37: Furnishings | C37: =H37/D$66 -> 0.0038999501 | D37: =SUM('12'!F99:F100) -> 41300 | E37: =SUM('12'!G99:G100) -> 0 | F37: =SUM('12'!I99:I100) -> 0 | G37: =SUM('12'!J99:J100) -> 0 | H37: =D37+F37+G37 -> 41300 | I37: =ROUNDUP(H37/D$11,1)&"$/SF" -> 0.7$/SF | K37: 47669 | L37: =K37/$L$11 -> 0.6139115
A39: 13 00 00 | B39: Special Construction | C39: =H39/D$66 -> 0.011463776 | D39: =+SUM('13'!F99:F100) -> 10000 | E39: =SUM('13'!G99:G100) -> 0 | F39: =SUM('13'!I99:I100) -> 0 | G39: =SUM('13'!J99:J100) -> 111400 | H39: =D39+F39+G39 -> 121400 | I39: =ROUNDUP(H39/D$11,1)&"$/SF" -> 1.9$/SF
A41: 14 00 00 | B41: Conveying Equipment | C41: =H41/D$66 -> 0.014663529 | D41: =SUM('14'!F99:F100) -> 0 | E41: =SUM('14'!G99:G100) -> 0 | F41: =SUM('14'!I99:I100) -> 0 | G41: =SUM('14'!J99:J100) -> 155285 | H41: =D41+F41+G41 -> 155285 | I41: =ROUNDUP(H41/D$11,1)&"$/SF" -> 2.4$/SF | K41: 324859 | L41: =K41/$L$11 -> 4.1837394
A43: 21 00 00 | B43: Fire Suppression | C43: =H43/D$66 -> 0.020019114 | D43: =SUM('21'!F99:F100) -> 0 | E43: =SUM('21'!G99:G100) -> 0 | F43: =SUM('21'!I99:I100) -> 0 | G43: =SUM('21'!J99:J100) -> 212000 | H43: =D43+F43+G43 -> 212000 | I43: =ROUNDUP(H43/D$11,1)&"$/SF" -> 3.3$/SF | K43: 256043.6 | L43: =K43/$L$11 -> 3.2974912
A45: 22 00 00 | B45: Plumbing | C45: =H45/D$66 -> 0.06372594 | D45: =SUM('22'!F94:F95) -> 0 | E45: =SUM('22'!G94:G95) -> 0 | F45: =SUM('22'!I94:I95) -> 0 | G45: =SUM('22'!J94:J95) -> 674850 | H45: =D45+F45+G45 -> 674850 | I45: =ROUNDUP(H45/D$11,1)&"$/SF" -> 10.3$/SF | K45: 813490.08 | L45: =K45/$L$11 -> 10.476639
A47: 23 00 00 | B47: HVAC | C47: =H47/D$66 -> 0.044160089 | D47: =SUM('23'!F102:F103) -> 0 | E47: =SUM('23'!G102:G103) -> 0 | F47: =SUM('23'!I102:I103) -> 0 | G47: =SUM('23'!J102:J103) -> 467650 | H47: =D47+F47+G47 -> 467650 | I47: =ROUNDUP(H47/D$11,1)&"$/SF" -> 7.2$/SF | K47: 641638.63 | L47: =K47/$L$11 -> 8.2634276
A49: 25 00 00 | B49: Integrated Automation | C49: =H49/D$66 -> 0 | D49: =SUM('25'!F54:F55) -> 0 | E49: =SUM('25'!G54:G55) -> 0 | F49: =SUM('25'!I54:I55) -> 0 | G49: =SUM('25'!J54:J55) -> 0 | H49: =D49+F49+G49 -> 0 | I49: =ROUNDUP(H49/D$11,1)&"$/SF" -> 0$/SF
A51: 26 00 00 | B51: Electrical | C51: =H51/D$66 -> 0.077705986 | D51: =SUM('26'!F58:F59) -> 52897 | E51: =SUM('26'!G58:G59) -> 0 | F51: =SUM('26'!I58:I59) -> 0 | G51: =SUM('26'!J58:J59) -> 770000 | H51: =D51+F51+G51 -> 822897 | I51: =ROUNDUP(H51/D$11,1)&"$/SF" -> 12.6$/SF | K51: 1110432.1 | L51: =K51/$L$11 -> 14.300846
A53: 27 00 00 | B53: Communications | C53: =H53/D$66 -> 0 | D53: =SUM('27'!F99:F100) -> 0 | E53: =SUM('27'!G99:G100) -> 0 | F53: =SUM('27'!I99:I100) -> 0 | G53: =SUM('27'!J99:J100) -> 0 | H53: =D53+F53+G53 -> 0 | I53: =ROUNDUP(H53/D$11,1)&"$/SF" -> 0$/SF
A55: 28 00 00 | B55: Electronic Safety and Security | C55: =H55/D$66 -> 0 | D55: =SUM('28'!F55:F56) -> 0 | E55: =SUM('28'!G55:G56) -> 0 | F55: =SUM('28'!I55:I56) -> 0 | G55: =SUM('28'!J55:J56) -> 0 | H55: =D55+F55+G55 -> 0 | I55: =ROUNDUP(H55/D$11,1)&"$/SF" -> 0$/SF
A57: 31 00 00 | B57: Earthwork | C57: =H57/D$66 -> 0.025335511 | D57: =SUM('31'!F69:F70) -> 40000 | E57: =SUM('31'!G69:G70) -> 0 | F57: =SUM('31'!I69:I70) -> 0 | G57: =SUM('31'!J69:J70) -> 228300 | H57: =D57+F57+G57 -> 268300 | I57: =ROUNDUP(H57/D$11,1)&"$/SF" -> 4.1$/SF | K57: 771509.48 | L57: =K57/$L$11 -> 9.9359865
A59: 32 00 00 | B59: Exterior Improvements | C59: =H59/D$66 -> 0.014265603 | D59: =SUM('32'!F97:F98) -> 0 | E59: =SUM('32'!G97:G98) -> 0 | F59: =SUM('32'!I97:I98) -> 0 | G59: =SUM('32'!J97:J98) -> 151071.01 | H59: =D59+F59+G59 -> 151071.01 | I59: =ROUNDUP(H59/D$11,1)&"$/SF" -> 2.4$/SF | K59: 211970 | L59: =K59/$L$11 -> 2.7298836
A61: 33 00 00 | B61: Utilities | C61: =H61/D$66 -> 0 | D61: =SUM('33'!F57:F58) -> 0 | E61: =SUM('33'!G57:G58) -> 0 | F61: =SUM('33'!I57:I58) -> 0 | G61: =SUM('33'!J57:J58) -> 0 | H61: =D61+F61+G61 -> 0 | I61: =ROUNDUP(H61/D$11,1)&"$/SF" -> 0$/SF
B64: Sub Totals>>>>>> | C64: =SUM(C15:C63) -> 1 | D64: =SUM(D15:D63) -> 2223129.1 | E64: =SUM(E15:E63) -> 59482.133 | F64: =SUM(F15:F63) -> 288549.2 | G64: =SUM(G15:G63) -> 8078200.9 | H64: =SUM(H15:H63) -> 10589879 | I64: =ROUNDUP(H64/D$11,1)&"$/SF" -> 161.5$/SF
B66: Total Construction Cost>>>>>> | D66: =D64+F64+G64 -> 10589879
N67: Total Job | O67: 12246313
B68: OH&P>>>>>> | D68: =(D66*E68) -> 529493.96 | E68: 0.05 | K68: =D68/59 -> 8974.4738 | N68: Ready to award / Awarded | O68: ='3'!M13+'3'!J14+'5'!M14+'6'!J33+'6'!J11+'7'!M76+'7'!M36+'8'!M13+'8'!M38+'9'!J11+'9'!J57+'9'!K47+'10'!M48+'10'!M54+'13'!M15+'14'!J12+'21'!J12+'22'!J14+'23'!J12+'26'!J16+'31'!M31+'3'!M40+'5'!M58+'8'!K69 -> 8049129.9
F69: HST | G69: TOTAL | N69: % | O69: =O68/O67 -> 0.65726967
F70: 0.15
...

Sheet 1
C1: ='Estimate Summary'!C1:H1 -> 0
G5: General Requirements | J5: Schedule
D6: ='Estimate Summary'!C11 -> Area: | E6: ='Estimate Summary'!D11 -> 65592 | F6: ='Estimate Summary'!E11 -> Sq. Ft. | J6: ='Estimate Summary'!D81 -> 60 | K6: Weeks
A9: CODE | B9: DESCRIPTION | C9: Materials & Equipment | G9: Labor | L9: Sub Contractor | M9: Quote Total | N9: Additional Quote Info
A10: 01 11 00 | B10: Preconstruction Costs | C10: Qty | D10: Unit | E10: U. Price | F10: Sub Total | G10: MHrs | H10: U. Price | I10: Sub Total | J10: Quote | K10: Total
A11: 01 11 13 | B11: Senior Construction Manager | D11: LS | E11: 0 | F11: =C11*E11 -> 0 | H11: 0 | I11: =G11*H11 -> 0 | K11: =F11+I11+J11 -> 0
A12: 01 11 16 | B12: Senior Estimator | D12: LS | E12: 0 | F12: =C12*E12 -> 0 | H12: 0 | I12: =G12*H12 -> 0 | K12: =F12+I12+J12 -> 0
A13: 01 11 19 | B13: Junior Estimator | D13: LS | E13: 0 | F13: =C13*E13 -> 0 | H13: 0 | I13: =G13*H13 -> 0 | K13: =F13+I13+J13 -> 0
A14: 01 11 23 | B14: Reprographics | D14: LS | E14: 0 | F14: =C14*E14 -> 0 | H14: 0 | I14: =G14*H14 -> 0 | K14: =F14+I14+J14 -> 0
A15: 01 11 26 | B15: Design Costs | D15: LS | E15: 0 | F15: =C15*E15 -> 0 | H15: 0 | I15: =G15*H15 -> 0 | K15: =F15+I15+J15 -> 0
A16: 01 11 26.13 | B16: Architectural | D16: LS | E16: 0 | F16: =C16*E16 -> 0 | H16: 0 | I16: =G16*H16 -> 0 | K16: =F16+I16+J16 -> 0
A17: 01 11 26.16 | B17: Civil | D17: LS | E17: 0 | F17: =C17*E17 -> 0 | H17: 0 | I17: =G17*H17 -> 0 | K17: =F17+I17+J17 -> 0
A18: 01 11 26.19 | B18: Structural | D18: LS | E18: 0 | F18: =C18*E18 -> 0 | H18: 0 | I18: =G18*H18 -> 0 | K18: =F18+I18+J18 -> 0
A19: 01 11 26.23 | B19: HVAC | D19: LS | E19: 0 | F19: =C19*E19 -> 0 | H19: 0 | I19: =G19*H19 -> 0 | K19: =F19+I19+J19 -> 0
A20: 01 11 26.26 | B20: Plumbing | D20: LS | E20: 0 | F20: =C20*E20 -> 0 | H20: 0 | I20: =G20*H20 -> 0 | K20: =F20+I20+J20 -> 0
A21: 01 11 26.29 | B21: Electrical | D21: LS | E21: 0 | F21: =C21*E21 -> 0 | H21: 0 | I21: =G21*H21 -> 0 | K21: =F21+I21+J21 -> 0
A22: 01 11 26.33 | B22: Geotechnical | D22: LS | E22: 0 | F22: =C22*E22 -> 0 | H22: 0 | I22: =G22*H22 -> 0 | K22: =F22+I22+J22 -> 0
J24: Sub Total | K24: =SUM(K11:K23) -> 0
A25: CODE | B25: DESCRIPTION | C25: Materials & Equipment | G25: Labor
A26: 01 31 00 | B26: Project Management and Coordination | C26: Qty | D26: Unit | E26: U. Price | F26: Sub Total | G26: MHrs | H26: U. Price | I26: Sub Total | J26: Quote | K26: Total
A27: 01 31 01 | B27: Senior Construction Manager | D27: LS | E27: 0 | F27: =C27*E27 -> 0 | H27: 0 | I27: =G27*H27 -> 0 | K27: =F27+I27+J27 -> 0
A28: 01 31 02 | B28: Senior Estimator | D28: LS | E28: 0 | F28: =C28*E28 -> 0 | H28: 0 | I28: =G28*H28 -> 0 | K28: =F28+I28+J28 -> 0
A29: 01 31 03 | B29: Senior Project Manager | C29: =J6 -> 60 | D29: LS | E29: 0 | F29: =C29*E29 -> 0 | H29: 100 | I29: =H29*G29*C29 -> 0 | K29: =F29+I29+J29 -> 0
A30: 01 31 04 | B30: Project Coordinator | C30: =J6 -> 60 | D30: LS | E30: 0 | F30: =C30*E30 -> 0 | H30: 75 | I30: =H30*G30*C30 -> 0 | K30: =F30+I30+J30 -> 0
A31: 01 31 05 | B31: Project Superintendent | C31: =J6 -> 60 | D31: LS | E31: 0 | F31: =C31*E31 -> 0 | G31: 1 | H31: 2750 | I31: =H31*G31*C31 -> 165000 | K31: =F31+I31+J31 -> 165000 | L31: Ekinox | M31: 188344 | N31: Spent to date $168k
A32: 01 31 06 | B32: Project Foreman | D32: LS | E32: 0 | F32: =C32*E32 -> 0 | H32: 0 | I32: =G32*H32 -> 0 | K32: =F32+I32+J32 -> 0
D33: LS | E33: 0 | F33: =C33*E33 -> 0 | H33: 0 | I33: =G33*H33 -> 0 | K33: =F33+I33+J33 -> 0
K34: =F34+I34+J34 -> 0
J35: Sub Total | K35: =SUM(K27:K34) -> 165000
A36: CODE | B36: DESCRIPTION
A37: 01 32 00 | B37: Insurance | D37: /$1000 | E37: Cost | F37: Rate | G37: Toll Cost | H37: Frequency | J37: Sub Total | K37: Total
A38: 01 32 01 | B38: General Liability & Contractor's Pollution Liability | C38: =SUM('Estimate Summary'!H17:H61)/1000 -> 10005.598 | D38: /$1000 | E38: 0.63 | K38: =F38 -> 0
B39: Contractor's Pollution Liability | C39: =SUM('Estimate Summary'!H17:H61)/1000 -> 10005.598 | D39: /$1000 | E39: 1.29 | K39: =F39 -> 0 | L39: By Client
B40: Builders Risk | C40: =+J6/4.5 -> 13.333333 | D40: $1000/month | E40: 0.75 | K40: =F40 -> 0 | L40: Ekinox | M40: 188344
B41: Wrap-up Liability | C41: =SUM('Estimate Summary'!H17:H61)/1000 -> 10005.598 | D41: /$1000 | E41: 1.88 | K41: =F41 -> 0
A45: 01 32 00 | J45: Sub Total | K45: =SUM(K38:K44) -> 0
A46: CODE | B46: DESCRIPTION | C46: Materials & Equipment | G46: Labor
A47: CODE | B47: DESCRIPTION
A48: 01 32 00 | B48: Travel | C48: Frequency | D48: Weeks | E48: Distance (Round Trip) | F48: Rate | G48: Toll Cost | H48: Frequency | J48: Sub Total | K48: Total
B49: PM KM | D49: =J6 -> 60 | E49: 0 | F49: 0.45 | H49: =C49*D49 -> 0 | J49: =C49*D49*E49*F49+G49*H49 -> 0 | K49: =J49+(G49*H49) -> 0
...

Sheet 2
C1: ='Estimate Summary'!C1:H1 -> 0
G5: Existing Conditions | J5: Schedule
D6: ='Estimate Summary'!C11 -> Area: | E6: ='Estimate Summary'!D11 -> 65592 | F6: ='Estimate Summary'!E11 -> Sq. Ft. | J6: ='1'!J6 -> 60 | K6: Weeks
A11: CODE | B11: DESCRIPTION | C11: Materials & Equipment | G11: Labor | L11: Sub Contractor | M11: Quote Total | N11: Additional Quote Info
A12: 02 00 00 | B12: Existing Conditions | C12: Qty | D12: Unit | E12: U. Price | F12: Sub Total | G12: MHrs | H12: U. Price | I12: Sub Total | J12: Quote | K12: Total
A13: 02 41 00 | B13: Demolition | D13: LS | E13: 0 | F13: =C13*E13 -> 0 | H13: 0 | I13: =G13*H13 -> 0 | K13: =F13+I13+J13 -> 0
D14: LS | E14: 0 | F14: =C14*E14 -> 0 | H14: 0 | I14: =G14*H14 -> 0 | K14: =F14+I14+J14 -> 0
D15: LS | E15: 0 | F15: =C15*E15 -> 0 | H15: 0 | I15: =G15*H15 -> 0 | K15: =F15+I15+J15 -> 0
D16: LS | E16: 0 | F16: =C16*E16 -> 0 | H16: 0 | I16: =G16*H16 -> 0 | K16: =F16+I16+J16 -> 0
D17: LS | E17: 0 | F17: =C17*E17 -> 0 | H17: 0 | I17: =G17*H17 -> 0 | K17: =F17+I17+J17 -> 0
D18: LS | E18: 0 | F18: =C18*E18 -> 0 | H18: 0 | I18: =G18*H18 -> 0 | K18: =F18+I18+J18 -> 0
D19: LS | E19: 0 | F19: =C19*E19 -> 0 | H19: 0 | I19: =G19*H19 -> 0 | K19: =F19+I19+J19 -> 0
D20: LS | E20: 0 | F20: =C20*E20 -> 0 | H20: 0 | I20: =G20*H20 -> 0 | K20: =F20+I20+J20 -> 0
D21: LS | E21: 0 | F21: =C21*E21 -> 0 | H21: 0 | I21: =G21*H21 -> 0 | K21: =F21+I21+J21 -> 0
D22: LS | E22: 0 | F22: =C22*E22 -> 0 | H22: 0 | I22: =G22*H22 -> 0 | K22: =F22+I22+J22 -> 0
D23: LS | E23: 0 | F23: =C23*E23 -> 0 | H23: 0 | I23: =G23*H23 -> 0 | K23: =F23+I23+J23 -> 0
D24: LS | E24: 0 | F24: =C24*E24 -> 0 | H24: 0 | I24: =G24*H24 -> 0 | K24: =F24+I24+J24 -> 0
J26: Sub Total | K26: =SUM(K13:K25) -> 0
A27: CODE | B27: DESCRIPTION | C27: Materials & Equipment | G27: Labor
A28: 02 82 00 | B28: Asbestos Remediation | C28: Qty | D28: Unit | E28: U. Price | F28: Sub Total | G28: MHrs | H28: U. Price | I28: Sub Total | J28: Quote | K28: Total
D29: LS | E29: 0 | F29: =C29*E29 -> 0 | H29: 0 | I29: =G29*H29 -> 0 | K29: =F29+I29+J29 -> 0
D30: LS | E30: 0 | F30: =C30*E30 -> 0 | H30: 0 | I30: =G30*H30 -> 0 | K30: =F30+I30+J30 -> 0
D31: LS | E31: 0 | F31: =C31*E31 -> 0 | H31: 0 | I31: =G31*H31 -> 0 | K31: =F31+I31+J31 -> 0
D32: LS | E32: 0 | F32: =C32*E32 -> 0 | H32: 0 | I32: =G32*H32 -> 0 | K32: =F32+I32+J32 -> 0
D33: LS | E33: 0 | F33: =C33*E33 -> 0 | H33: 0 | I33: =G33*H33 -> 0 | K33: =F33+I33+J33 -> 0
D34: LS | E34: 0 | F34: =C34*E34 -> 0 | H34: 0 | I34: =G34*H34 -> 0 | K34: =F34+I34+J34 -> 0
D35: LS | E35: 0 | F35: =C35*E35 -> 0 | H35: 0 | I35: =G35*H35 -> 0 | K35: =F35+I35+J35 -> 0
J37: Sub Total | K37: =SUM(K29:K36) -> 0
A38: CODE | B38: DESCRIPTION | C38: Materials & Equipment | G38: Labor
A39: 02 83 00 | B39: Trenching | C39: Qty | D39: Unit | E39: U. Price | F39: Sub Total | G39: MHrs | H39: U. Price | I39: Sub Total | J39: Quote | K39: Total
D40: LS | E40: 0 | F40: =C40*E40 -> 0 | H40: 0 | I40: =G40*H40 -> 0 | K40: =F40+I40+J40 -> 0
B41: Sanitary Trenching | D41: ft | E41: 65 | F41: =C41*E41 -> 0 | H41: 0 | I41: =G41*H41 -> 0 | K41: =F41+I41+J41 -> 0
D42: LS | E42: 0 | F42: =C42*E42 -> 0 | H42: 0 | I42: =G42*H42 -> 0 | K42: =F42+I42+J42 -> 0
B43: Conduit Trenching | D43: ft | E43: 35 | F43: =C43*E43 -> 0 | H43: 0 | I43: =G43*H43 -> 0 | K43: =F43+I43+J43 -> 0
D44: LS | E44: 0 | F44: =C44*E44 -> 0 | H44: 0 | I44: =G44*H44 -> 0 | K44: =F44+I44+J44 -> 0
D45: LS | E45: 0 | F45: =C45*E45 -> 0 | H45: 0 | I45: =G45*H45 -> 0 | K45: =F45+I45+J45 -> 0
D46: LS | E46: 0 | F46: =C46*E46 -> 0 | H46: 0 | I46: =G46*H46 -> 0 | K46: =F46+I46+J46 -> 0
J48: Sub Total | K48: =SUM(K40:K47) -> 0
F49: Material Total | G49: Total Hours | I49: Labor Total | J49: Contractor Total | K49: TOTAL
A50: $ / Sq.Ft | B50: TOTAL DIVISION 2
...

Sheet 3
C1: ='Estimate Summary'!C1:H1 -> 0
G5: Concrete | J5: Schedule
D6: ='Estimate Summary'!C11 -> Area: | E6: ='Estimate Summary'!D11 -> 65592 | F6: ='Estimate Summary'!E11 -> Sq. Ft. | J6: ='1'!J6 -> 60 | K6: Weeks
A11: CODE | B11: DESCRIPTION | C11: Materials & Equipment | G11: Labor | L11: Sub Contractor | M11: Quote Total | N11: Additional Quote Info
A12: 03 11 00 | B12: Concrete Forming | C12: Qty | D12: Unit | E12: U. Price | F12: Sub Total | G12: MHrs | H12: U. Price | I12: Sub Total | J12: Quote | K12: Total
A13: 03 11 01 | B13: Contractor Quote | K13: =F13+I13+J13 -> 0 | L13: Spent incl Rebar | M13: 561600
A14: 03 11 02.1 | B14: Footings | D14: ft | E14: 25 | F14: =C14*E14 -> 0 | H14: 0 | I14: =G14*H14 -> 0 | J14: =M14-M13 -> 302400 | K14: =F14+I14+J14 -> 302400 | L14: Optimal | M14: 864000 | N14: Can start within 2 weeks. Says 6 to 8 weeks of work left to do
A15: 03 11 02.2 | B15: Walls | D15: ft | E15: 45 | F15: =C15*E15 -> 0 | H15: 0 | I15: =G15*H15 -> 0 | K15: =F15+I15+J15 -> 0
A16: 03 11 02.3 | B16: Piers | D16: ea | E16: 150 | F16: =C16*E16 -> 0 | H16: 0 | I16: =G16*H16 -> 0 | K16: =F16+I16+J16 -> 0
D17: LS | E17: 0 | F17: =C17*E17 -> 0 | H17: 0 | I17: =G17*H17 -> 0 | K17: =F17+I17+J17 -> 0
D18: LS | E18: 0 | F18: =C18*E18 -> 0 | H18: 0 | I18: =G18*H18 -> 0 | K18: =F18+I18+J18 -> 0
D19: LS | E19: 0 | F19: =C19*E19 -> 0 | H19: 0 | I19: =G19*H19 -> 0 | K19: =F19+I19+J19 -> 0
D20: LS | E20: 0 | F20: =C20*E20 -> 0 | H20: 0 | I20: =G20*H20 -> 0 | K20: =F20+I20+J20 -> 0
J26: Sub Total | K26: =SUM(K13:K25) -> 302400
A27: CODE | B27: DESCRIPTION | C27: Materials & Equipment | G27: Labor
A28: 03 20 00 | B28: Concrete Reinforcing | C28: Qty | D28: Unit | E28: U. Price | F28: Sub Total | G28: MHrs | H28: U. Price | I28: Sub Total | J28: Quote | K28: Total
A29: 03 20 01 | B29: Contractor Quote | K29: =F29+I29+J29 -> 0 | T29: Type | U29: Width | W29: Height
A30: 03 20 02 | B30: Rebar | D30: LS | E30: 0 | F30: =C30*E30 -> 0 | H30: 0 | I30: =G30*H30 -> 0 | K30: =F30+I30+J30 -> 0 | U30: A | V30: B | W30: D | X30: Quantity | Y30: Volume m3
A31: 03 20 03 | B31: Mesh | D31: LS | E31: 0 | F31: =C31*E31 -> 0 | H31: 0 | I31: =G31*H31 -> 0 | K31: =F31+I31+J31 -> 0 | S31: Footings | T31: 1 | Y31: =U31*V31*W31*0.0000163871*X31 -> 0
D32: LS | E32: 0 | F32: =C32*E32 -> 0 | H32: 0 | I32: =G32*H32 -> 0 | K32: =F32+I32+J32 -> 0 | T32: 2 | Y32: =U32*V32*W32*0.0000163871*X32 -> 0
D33: LS | E33: 0 | F33: =C33*E33 -> 0 | H33: 0 | I33: =G33*H33 -> 0 | K33: =F33+I33+J33 -> 0 | U33: Length (FT) | V33: Width (ft) | W33: Height (ft)
D34: LS | E34: 0 | F34: =C34*E34 -> 0 | H34: 0 | I34: =G34*H34 -> 0 | K34: =F34+I34+J34 -> 0 | S34: Strip Footing | Y34: =U34*V34*W34*0.028 -> 0
D35: LS | E35: 0 | F35: =C35*E35 -> 0 | H35: 0 | I35: =G35*H35 -> 0 | K35: =F35+I35+J35 -> 0 | S35: Walls | Y35: =U35*V35*W35*0.028 -> 0
S36: Piers | Y36: =U36*V36*W36*0.028*X36 -> 0
J37: Sub Total | K37: =SUM(K29:K36) -> 0 | U37: Area (SF) | W37: Thickness (ft)
A38: CODE | B38: DESCRIPTION | C38: Materials & Equipment | G38: Labor | S38: Slab - ground floor | Y38: =U38*W38*0.028 -> 0
A39: 03 30 00 | B39: Cast-in-Place Concrete | C39: Qty | D39: Unit | E39: U. Price | F39: Sub Total | G39: MHrs | H39: U. Price | I39: Sub Total | J39: Quote | K39: Total | S39: Slab - 2nd floor | Y39: =U39*W39*0.028 -> 0
A40: 03 30 01 | B40: SOG Volume | C40: =Q86*1.1 -> 264.51333 | D40: m3 | E40: =161.42+20 -> 181.42 | F40: =C40*E40 -> 47988.008 | H40: 0 | I40: =G40*H40 -> 0 | K40: =F40+I40+J40 -> 47988.008 | L40: Spent | M40: 100052.75 | O40: 25MPA | P40: =C40+C42 -> 281.33353
B41: Structural Slab | C41: =Q87*1.1 -> 493.95341 | D41: m3 | E41: =190.58+20 -> 210.58 | F41: =C41*E41 -> 104016.71 | H41: 0 | I41: =G41*H41 -> 0 | K41: =F41+I41+J41 -> 104016.71 | L41: 2024 Prices | O41: 30MPA | P41: =C43 -> 22.956468
A42: 03 30 02 | B42: Footing Volume | C42: =(Q82+Q84)*1.1 -> 16.820207 | D42: m3 | E42: =E40 -> 181.42 | F42: =C42*E42 -> 3051.5219 | H42: 0 | I42: =G42*H42 -> 0 | K42: =F42+I42+J42 -> 3051.5219 | O42: 35MPA | P42: =C41+C44 -> 495.44854 | S42: Exterior Pads | Y42: =U42*W42*0.028 -> 0
A43: 03 30 03 | B43: Foundation Wall Volume | C43: =Q83*1.1 -> 22.956468 | D43: m3 | E43: =177.6+20 -> 197.6 | F43: =C43*E43 -> 4536.198 | H43: 0 | I43: =G43*H43 -> 0 | K43: =F43+I43+J43 -> 4536.198
A44: 03 30 04 | B44: Columns | C44: =Q85*1.1 -> 1.4951295 | D44: m3 | E44: =E41 -> 210.58 | F44: =C44*E44 -> 314.84437 | H44: 0 | I44: =G44*H44 -> 0 | K44: =F44+I44+J44 -> 314.84437
B45: Retaining Walls | C45: =Q88 -> 35.849128 | D45: m3 | E45: =E43 -> 197.6 | F45: =C45*E45 -> 7083.7877 | H45: 0 | I45: =G45*H45 -> 0 | K45: =F45+I45+J45 -> 7083.7877
B46: Retaining Footings | C46: =Q89 -> 4.0209922 | D46: m3 | E46: =E40 -> 181.42 | F46: =C46*E46 -> 729.48841 | H46: 0 | I46: =G46*H46 -> 0 | K46: =F46+I46+J46 -> 729.48841
B47: Already Spent | K47: =F47+I47+J47 -> 0
B48: Pump Hrs | C48: =SUM(C40:C46)/35 -> 23.988819 | D48: Hrs | E48: 280 | F48: =C48*E48 -> 6716.8693 | H48: 0 | I48: =G48*H48 -> 0 | K48: =F48+I48+J48 -> 6716.8693 | L48: 38M Pump | W48: Total Volume - Slab | Y48: =Y38+Y39 -> 0
A49: 03 30 04 | B49: Pump | C49: =SUM(C40:C46) -> 839.60866 | D49: m3 | E49: 4 | F49: =C49*E49 -> 3358.4346 | H49: 0 | I49: =G49*H49 -> 0 | K49: =F49+I49+J49 -> 3358.4346 | W49: Total Volume - Footing | Y49: =Y31+Y32+Y34 -> 0
J50: Sub Total | K50: =SUM(K40:K49) -> 177795.86 | W50: Total Volume - Walls | Y50: =Y35+Y36 -> 0
A51: CODE | B51: DESCRIPTION | C51: Materials & Equipment | G51: Labor | W51: Total Volume - Exterior | Y51: =Y42 -> 0
A52: 03 35 00 | B52: Concrete Finishing | C52: Qty | D52: Unit | E52: U. Price | F52: Sub Total | G52: MHrs | H52: U. Price | I52: Sub Total | J52: Quote | K52: Total
...

Sheet 4
C1: ='Estimate Summary'!C1:H1 -> 0
G5: Masonry | J5: Schedule
D6: ='Estimate Summary'!C11 -> Area: | E6: ='Estimate Summary'!D11 -> 65592 | F6: ='Estimate Summary'!E11 -> Sq. Ft. | J6: ='1'!J6 -> 60 | K6: Weeks
A11: CODE | B11: DESCRIPTION | C11: Materials & Equipment | G11: Labor | L11: Sub Contractor | M11: Quote Total | N11: Additional Quote Info | O11: Previous Quotes
A12: 04 20 00 | B12: Unit Masonry | C12: Qty | D12: Unit | E12: U. Price | F12: Sub Total | G12: MHrs | H12: U. Price | I12: Sub Total | J12: Quote | K12: Total
D13: LS | E13: 0 | F13: =C13*E13 -> 0 | H13: 0 | I13: =G13*H13 -> 0 | K13: =F13+I13+J13 -> 0 | M13: Veneer | N13: Interior Blocks | O13: Ston Masonry | P13: =94000+37400 -> 131400 | Q13: Labour only for exterior. Labour + Mat for interior block walls
B14: Culture Stone | C14: =2745+545 -> 3290 | D14: SF | E14: 50 | H14: 0 | I14: =G14*H14 -> 0 | J14: =M14 -> 104000 | K14: =F14+I14+J14 -> 104000 | L14: JP Masonry | M14: 104000 | N14: 36360
D15: LS | E15: 0 | F15: =C15*E15 -> 0 | H15: 0 | I15: =G15*H15 -> 0 | K15: =F15+I15+J15 -> 0 | L15: Vintage (Late) | M15: 219495
B16: Block Walls | C16: 1600 | D16: SF | E16: 40 | H16: 0 | I16: =G16*H16 -> 0 | J16: =N14 -> 36360 | K16: =F16+I16+J16 -> 36360
D17: LS | E17: 0 | F17: =C17*E17 -> 0 | H17: 0 | I17: =G17*H17 -> 0 | K17: =F17+I17+J17 -> 0
D18: LS | E18: 0 | F18: =C18*E18 -> 0 | H18: 0 | I18: =G18*H18 -> 0 | K18: =F18+I18+J18 -> 0
D19: LS | E19: 0 | F19: =C19*E19 -> 0 | H19: 0 | I19: =G19*H19 -> 0 | K19: =F19+I19+J19 -> 0 | L19: Shaw Stone supply | M19: 51352 | N19: Screwed Vena Stone
D20: LS | E20: 0 | F20: =C20*E20 -> 0 | H20: 0 | I20: =G20*H20 -> 0 | K20: =F20+I20+J20 -> 0 | L20: AVT Install | M20: 55000
D21: LS | E21: 0 | F21: =C21*E21 -> 0 | H21: 0 | I21: =G21*H21 -> 0 | K21: =F21+I21+J21 -> 0
D22: LS | E22: 0 | F22: =C22*E22 -> 0 | H22: 0 | I22: =G22*H22 -> 0 | K22: =F22+I22+J22 -> 0
D23: LS | E23: 0 | F23: =C23*E23 -> 0 | H23: 0 | I23: =G23*H23 -> 0 | K23: =F23+I23+J23 -> 0
D24: LS | E24: 0 | F24: =C24*E24 -> 0 | H24: 0 | I24: =G24*H24 -> 0 | K24: =F24+I24+J24 -> 0
J26: Sub Total | K26: =SUM(K13:K25) -> 140360
A27: CODE | B27: DESCRIPTION | C27: Materials & Equipment | G27: Labor
A28: 04 43 00 | B28: Stone Masonry | C28: Qty | D28: Unit | E28: U. Price | F28: Sub Total | G28: MHrs | H28: U. Price | I28: Sub Total | J28: Quote | K28: Total
D29: LS | E29: 0 | F29: =C29*E29 -> 0 | H29: 0 | I29: =G29*H29 -> 0 | K29: =F29+I29+J29 -> 0
D30: LS | E30: 0 | F30: =C30*E30 -> 0 | H30: 0 | I30: =G30*H30 -> 0 | K30: =F30+I30+J30 -> 0
D31: LS | E31: 0 | F31: =C31*E31 -> 0 | H31: 0 | I31: =G31*H31 -> 0 | K31: =F31+I31+J31 -> 0
D32: LS | E32: 0 | F32: =C32*E32 -> 0 | H32: 0 | I32: =G32*H32 -> 0 | K32: =F32+I32+J32 -> 0
D33: LS | E33: 0 | F33: =C33*E33 -> 0 | H33: 0 | I33: =G33*H33 -> 0 | K33: =F33+I33+J33 -> 0
D34: LS | E34: 0 | F34: =C34*E34 -> 0 | H34: 0 | I34: =G34*H34 -> 0 | K34: =F34+I34+J34 -> 0
D35: LS | E35: 0 | F35: =C35*E35 -> 0 | H35: 0 | I35: =G35*H35 -> 0 | K35: =F35+I35+J35 -> 0
J37: Sub Total | K37: =SUM(K29:K36) -> 0
A38: CODE | B38: DESCRIPTION | C38: Materials & Equipment | G38: Labor
C39: Qty | D39: Unit | E39: U. Price | F39: Sub Total | G39: MHrs | H39: U. Price | I39: Sub Total | J39: Quote | K39: Total
D40: LS | E40: 0 | F40: =C40*E40 -> 0 | H40: 0 | I40: =G40*H40 -> 0 | K40: =F40+I40+J40 -> 0
D41: LS | E41: 0 | F41: =C41*E41 -> 0 | H41: 0 | I41: =G41*H41 -> 0 | K41: =F41+I41+J41 -> 0
D42: LS | E42: 0 | F42: =C42*E42 -> 0 | H42: 0 | I42: =G42*H42 -> 0 | K42: =F42+I42+J42 -> 0
J45: Sub Total | K45: =SUM(K40:K44) -> 0
A46: CODE | B46: DESCRIPTION | C46: Materials & Equipment | G46: Labor
C47: Qty | D47: Unit | E47: U. Price | F47: Sub Total | G47: MHrs | H47: U. Price | I47: Sub Total | J47: Quote | K47: Total
D48: LS | E48: 0 | F48: =C48*E48 -> 0 | H48: 0 | I48: =G48*H48 -> 0 | K48: =F48+I48+J48 -> 0
D49: LS | E49: 0 | F49: =C49*E49 -> 0 | H49: 0 | I49: =G49*H49 -> 0 | K49: =F49+I49+J49 -> 0
D50: LS | E50: 0 | F50: =C50*E50 -> 0 | H50: 0 | I50: =G50*H50 -> 0 | K50: =F50+I50+J50 -> 0
D51: LS | E51: 0 | F51: =C51*E51 -> 0 | H51: 0 | I51: =G51*H51 -> 0 | K51: =F51+I51+J51 -> 0
...

Sheet 5
C1: ='Estimate Summary'!C1:H1 -> 0
G5: Metals | J5: Schedule
D6: ='Estimate Summary'!C11 -> Area: | E6: ='Estimate Summary'!D11 -> 65592 | F6: ='Estimate Summary'!E11 -> Sq. Ft. | J6: ='1'!J6 -> 60 | K6: Weeks
A11: CODE | B11: DESCRIPTION | C11: Materials & Equipment | G11: Labor | L11: Sub Contractor | M11: Quote Total | N11: Additional Quote Info
A12: 05 12 00 | B12: Structural Steel Framing | C12: Qty | D12: Unit | E12: U. Price | F12: Sub Total | G12: MHrs | H12: U. Price | I12: Sub Total | J12: Quote | K12: Total
D13: LS | E13: 0 | F13: =C13*E13 -> 0 | H13: 0 | I13: =G13*H13 -> 0 | K13: =F13+I13+J13 -> 0
D14: LS | E14: 0 | F14: =C14*E14 -> 0 | H14: 0 | I14: =G14*H14 -> 0 | J14: =M14 -> 136100 | K14: =F14+I14+J14 -> 136100 | L14: Summit | M14: 136100 | N14: $4500 extra for brick lintels
D15: LS | E15: 0 | F15: =C15*E15 -> 0 | H15: 0 | I15: =G15*H15 -> 0 | K15: =F15+I15+J15 -> 0
B16: Brick Lintels | D16: LS | E16: 0 | F16: =C16*E16 -> 0 | H16: 0 | I16: =G16*H16 -> 0 | J16: 4500 | K16: =F16+I16+J16 -> 4500
D17: LS | E17: 0 | F17: =C17*E17 -> 0 | H17: 0 | I17: =G17*H17 -> 0 | K17: =F17+I17+J17 -> 0
B18: Metal clips for handrails | C18: 8 | D18: LS | E18: 100 | F18: =C18*E18 -> 800 | H18: 0 | I18: =G18*H18 -> 0 | K18: =F18+I18+J18 -> 800
D19: LS | E19: 0 | F19: =C19*E19 -> 0 | H19: 0 | I19: =G19*H19 -> 0 | K19: =F19+I19+J19 -> 0
D20: LS | E20: 0 | F20: =C20*E20 -> 0 | H20: 0 | I20: =G20*H20 -> 0 | K20: =F20+I20+J20 -> 0
D21: LS | E21: 0 | F21: =C21*E21 -> 0 | H21: 0 | I21: =G21*H21 -> 0 | K21: =F21+I21+J21 -> 0
D22: LS | E22: 0 | F22: =C22*E22 -> 0 | H22: 0 | I22: =G22*H22 -> 0 | K22: =F22+I22+J22 -> 0
D23: LS | E23: 0 | F23: =C23*E23 -> 0 | H23: 0 | I23: =G23*H23 -> 0 | K23: =F23+I23+J23 -> 0
D24: LS | E24: 0 | F24: =C24*E24 -> 0 | H24: 0 | I24: =G24*H24 -> 0 | K24: =F24+I24+J24 -> 0
J26: Sub Total | K26: =SUM(K13:K25) -> 141400
A27: CODE | B27: DESCRIPTION | C27: Materials & Equipment | G27: Labor
A28: 05 20 00 | B28: Metal Joists | C28: Qty | D28: Unit | E28: U. Price | F28: Sub Total | G28: MHrs | H28: U. Price | I28: Sub Total | J28: Quote | K28: Total
D29: LS | E29: 0 | F29: =C29*E29 -> 0 | H29: 0 | I29: =G29*H29 -> 0 | K29: =F29+I29+J29 -> 0
D30: LS | E30: 0 | F30: =C30*E30 -> 0 | H30: 0 | I30: =G30*H30 -> 0 | K30: =F30+I30+J30 -> 0
D31: LS | E31: 0 | F31: =C31*E31 -> 0 | H31: 0 | I31: =G31*H31 -> 0 | K31: =F31+I31+J31 -> 0
D32: LS | E32: 0 | F32: =C32*E32 -> 0 | H32: 0 | I32: =G32*H32 -> 0 | K32: =F32+I32+J32 -> 0
D33: LS | E33: 0 | F33: =C33*E33 -> 0 | H33: 0 | I33: =G33*H33 -> 0 | K33: =F33+I33+J33 -> 0
D34: LS | E34: 0 | F34: =C34*E34 -> 0 | H34: 0 | I34: =G34*H34 -> 0 | K34: =F34+I34+J34 -> 0
D35: LS | E35: 0 | F35: =C35*E35 -> 0 | H35: 0 | I35: =G35*H35 -> 0 | K35: =F35+I35+J35 -> 0
J37: Sub Total | K37: =SUM(K29:K36) -> 0
A38: CODE | B38: DESCRIPTION | C38: Materials & Equipment | G38: Labor
A39: 05 30 00 | B39: Metal Decking | C39: Qty | D39: Unit | E39: U. Price | F39: Sub Total | G39: MHrs | H39: U. Price | I39: Sub Total | J39: Quote | K39: Total
D40: LS | E40: 0 | F40: =C40*E40 -> 0 | H40: 0 | I40: =G40*H40 -> 0 | K40: =F40+I40+J40 -> 0
D41: LS | E41: 0 | F41: =C41*E41 -> 0 | H41: 0 | I41: =G41*H41 -> 0 | K41: =F41+I41+J41 -> 0
D42: LS | E42: 0 | F42: =C42*E42 -> 0 | H42: 0 | I42: =G42*H42 -> 0 | K42: =F42+I42+J42 -> 0
J45: Sub Total | K45: =SUM(K40:K44) -> 0
A46: CODE | B46: DESCRIPTION | C46: Materials & Equipment | G46: Labor
A47: 05 51 00 | B47: Metal Stairs | C47: Qty | D47: Unit | E47: U. Price | F47: Sub Total | G47: MHrs | H47: U. Price | I47: Sub Total | J47: Quote | K47: Total
D48: LS | E48: 0 | F48: =C48*E48 -> 0 | H48: 0 | I48: =G48*H48 -> 0 | K48: =F48+I48+J48 -> 0
D49: LS | E49: 0 | F49: =C49*E49 -> 0 | H49: 0 | I49: =G49*H49 -> 0 | K49: =F49+I49+J49 -> 0
D50: LS | E50: 0 | F50: =C50*E50 -> 0 | H50: 0 | I50: =G50*H50 -> 0 | K50: =F50+I50+J50 -> 0
D51: LS | E51: 0 | F51: =C51*E51 -> 0 | H51: 0 | I51: =G51*H51 -> 0 | K51: =F51+I51+J51 -> 0
...

Sheet 6
C1: ='Estimate Summary'!C1:H1 -> 0
G5: Wood & Plastics | J5: Schedule
D6: ='Estimate Summary'!C11 -> Area: | E6: ='Estimate Summary'!D11 -> 65592 | F6: ='Estimate Summary'!E11 -> Sq. Ft. | J6: ='1'!J6 -> 60 | K6: Weeks
A9: CODE | B9: DESCRIPTION | C9: Materials & Equipment | G9: Labor | L9: Sub Contractor | M9: Quote Total | N9: Additional Quote Info
A10: 06 11 00 | B10: Framing Labour | C10: Qty | D10: Unit | E10: U. Price | F10: Sub Total | G10: MHrs | H10: U. Price | I10: Sub Total | J10: Quote | K10: Total
H11: 0 | I11: =G11*H11 -> 0 | J11: =M13 -> 459330 | K11: =F11+I11+J11 -> 459330 | L11: AVT | M11: 445000 | N11: Framing Only. They supply manlift, we supply crane and zoom boom
B12: Allowance for corner columns install | C12: 6 | D12: LS | E12: 500 | F12: =E12*C12 -> 3000 | H12: 0 | I12: =G12*H12 -> 0 | K12: =F12+I12+J12 -> 3000 | L12: Big Bang | M12: 545000 | N12: Framing, strapping and tyvek install
H13: 0 | I13: =G13*H13 -> 0 | K13: =F13+I13+J13 -> 0 | L13: CMS | M13: =459330 -> 459330 | N13: Includes deck install and Windows install & Solar Panel Reinforcements
B14: Crane | C14: 15 | D14: wks | E14: 7000 | F14: =E14*C14 -> 105000 | H14: 0 | I14: =G14*H14 -> 0 | K14: =F14+I14+J14 -> 105000 | L14: Gbro | M14: 569550 | N14: Includes deck install and Windows install
B15: Crane Setup/Dismantle | C15: 2 | D15: LS | E15: 2000 | F15: =E15*C15 -> 4000 | H15: 0 | I15: =G15*H15 -> 0 | K15: =F15+I15+J15 -> 4000 | L15: East Coast | M15: =350000+45000 -> 395000 | N15: Framing and concrete deck install. Additional $45k for window install
H16: 0 | I16: =G16*H16 -> 0 | K16: =F16+I16+J16 -> 0 | L16: S&J | M16: 389956.2 | N16: Includes deck install and Windows install
H17: 0 | I17: =G17*H17 -> 0 | K17: =F17+I17+J17 -> 0 | L17: Branco | M17: =469227.2+8400 -> 477627.2 | N17: Includes deck install and Windows install & Solar Panel Reinforcements
J19: Sub Total | K19: =SUM(K11:K18) -> 571330
A20: 06 20 00 | B20: Framing Materials | C20: Qty | D20: Unit | E20: U. Price | F20: Sub Total | J20: Quote | K20: Total
B22: Lumber & Fasterners Allowance | C22: 59 | D22: Unit | E22: 3250 | F22: =C22*E22 -> 191750 | K22: =F22+I22+J22 -> 191750 | L22: Belle Foret per unit | M22: =175845.44/63 -> 2791.1975 | N22: Added $ for truss bracing
B23: 2x6 Stud | D23: ft | E23: 0.81 | F23: =C23*E23 -> 0 | K23: =F23+I23+J23 -> 0
B24: 2x8 | D24: ft | E24: 1.24 | F24: =C24*E24 -> 0 | K24: =F24+I24+J24 -> 0
B25: 2x10 | D25: ft | E25: 1.61 | F25: =C25*E25 -> 0 | K25: =F25+I25+J25 -> 0
B26: 1x3 | D26: ft | E26: 0.25 | F26: =C26*E26 -> 0 | K26: =F26+I26+J26 -> 0
B27: 1x4 | D27: ft | E27: 0.37 | F27: =C27*E27 -> 0 | K27: =F27+I27+J27 -> 0 | M27: Per Unit
B28: PLYWOOD | K28: =F28+I28+J28 -> 0 | L28: Belle Foret Atlas | M28: =1362134/63 -> 21621.175
B29: 1/2" Standard | D29: EA | E29: 30.65 | F29: =C29*E29 -> 0 | K29: =F29+I29+J29 -> 0 | L29: Joyce Atlas | M29: =1361600/59 -> 23077.966
B30: 5/8" Standard | D30: EA | E30: 43.69 | F30: =C30*E30 -> 0 | K30: =F30+I30+J30 -> 0
B31: 3/4" Standard | D31: EA | E31: 47.47 | F31: =C31*E31 -> 0 | K31: =F31+I31+J31 -> 0 | M31: Walls | N31: Floors | O31: Trusses | P31: Stairs | Q31: Total | S31: Additional with solar bracing
L32: Atlas | M32: 466300 | N32: =263000+218650+43200 -> 524850 | O32: 104900 | P32: 32400 | Q32: =SUM(M32:P32) -> 1128450 | R32: Total with Trusses | S32: 19500
B33: Panel Allowance | C33: 59 | D33: EA | E33: 23077.97 | J33: =R33 -> 1070073.7 | K33: =F33+I33+J33 -> 1070073.7 | L33: T&M | M33: 1003550 | N33: Incl | O33: Not Incl | P33: Incl | Q33: 930650 | R33: =Q33+O35 -> 1070073.7
L34: Truss Peninsule
L35: Gable | M35: Not Incl | N35: 266240.78 | O35: 139423.66 | P35: Not Incl | Q35: Floor does not have boarding
J36: Sub Total | K36: =SUM(K21:K35) -> 1261823.7
A37: CODE | B37: DESCRIPTION | C37: Materials & Equipment | G37: Labor
A38: 06 22 00 | B38: Millwork | C38: Qty | D38: Unit | E38: U. Price | F38: Sub Total | G38: MHrs | H38: U. Price | I38: Sub Total | J38: Quote | K38: Total
D39: LS | E39: 0 | F39: =C39*E39 -> 0 | H39: 0 | I39: =G39*H39 -> 0 | K39: =F39+I39+J39 -> 0 | L39: Extreme Kitchen
C40: 59 | D40: Unit | E40: 6000 | H40: 0 | I40: =G40*H40 -> 0 | J40: =M40 -> 425900 | K40: =F40+I40+J40 -> 425900 | L40: Foxwood | M40: 425900 | N40: Melamine Counter top and doors
D41: LS | E41: 0 | F41: =C41*E41 -> 0 | H41: 0 | I41: =G41*H41 -> 0 | K41: =F41+I41+J41 -> 0 | L41: Royalty | M41: 633000
D42: LS | E42: 0 | F42: =C42*E42 -> 0 | H42: 0 | I42: =G42*H42 -> 0 | K42: =F42+I42+J42 -> 0 | L42: Shaw
D43: LS | E43: 0 | F43: =C43*E43 -> 0 | H43: 0 | I43: =G43*H43 -> 0 | K43: =F43+I43+J43 -> 0 | L43: Triangle | M43: 446883.98 | N43: Pricing quartz top with melamine doors
D44: LS | E44: 0 | F44: =C44*E44 -> 0 | H44: 0 | I44: =G44*H44 -> 0 | K44: =F44+I44+J44 -> 0 | L44: Laforest | M44: 604750 | N44: Soft Close +$44,250. Quartz +$372,000
D45: LS | E45: 0 | F45: =C45*E45 -> 0 | H45: 0 | I45: =G45*H45 -> 0 | K45: =F45+I45+J45 -> 0 | L45: Master Interior (Late) | M45: =194016.19+96052+83585.89+30680 -> 404334.08
J47: Sub Total | K47: =SUM(K39:K46) -> 425900
A48: CODE | B48: DESCRIPTION | C48: Materials & Equipment | G48: Labor
...

Sheet 7
C1: ='Estimate Summary'!C1:H1 -> 0
G5: Thermal & Moisture Protection | J5: Schedule
D6: ='Estimate Summary'!C11 -> Area: | E6: ='Estimate Summary'!D11 -> 65592 | F6: ='Estimate Summary'!E11 -> Sq. Ft. | J6: ='1'!J6 -> 60 | K6: Weeks
A9: CODE | B9: DESCRIPTION | C9: Materials & Equipment | G9: Labor | L9: Sub Contractor | M9: Quote Total | N9: Additional Quote Info
A10: 07 21 00 | B10: Thermal Insulation | C10: Qty | D10: Unit | E10: U. Price | F10: Sub Total | G10: MHrs | H10: U. Price | I10: Sub Total | J10: Quote | K10: Total
A11: 07 21 16 | B11: Blanket Insulation | C11: 59 | D11: Unit | E11: =M15 -> 3880.4407 | H11: 0 | I11: =G11*H11 -> 0 | J11: =M11 -> 237835 | K11: =F11+I11+J11 -> 237835 | L11: Mike's | M11: 237835 | N11: Alternative in floor insulation
A12: 07 21 26 | B12: Blown Insulation | D12: LS | E12: 0 | F12: =C12*E12 -> 0 | H12: 0 | I12: =G12*H12 -> 0 | K12: =F12+I12+J12 -> 0 | L12: Ghiro / BenJo | M12: 193676 | N12: Missing spray foam in underground garage
A13: 07 21 29 | B13: Sprayed Insulation | D13: LS | E13: 0 | F13: =C13*E13 -> 0 | H13: 0 | I13: =G13*H13 -> 0 | K13: =F13+I13+J13 -> 0 | L13: Trinity | M13: =191830+30179 -> 222009 | N13: Blown insulation only
D14: LS | E14: 0 | F14: =C14*E14 -> 0 | H14: 0 | I14: =G14*H14 -> 0 | K14: =F14+I14+J14 -> 0
L15: Joyce per unit | M15: =228946/59 -> 3880.4407
J16: Sub Total | K16: =SUM(K11:K15) -> 237835
A17: CODE | B17: DESCRIPTION | C17: Materials & Equipment | G17: Labor
A18: 07 24 00 | B18: Sound Proofing | C18: Qty | D18: Unit | E18: U. Price | F18: Sub Total | G18: SF | H18: U. Price | I18: Sub Total | J18: Quote | K18: Total
B19: Acoustiboard | C19: =E6/4*3*1.2 -> 59032.8 | D19: SF | E19: 2.88 | F19: =C19*E19 -> 170014.46 | G19: =C19 -> 59032.8 | H19: 1.5 | I19: =G19*H19 -> 88549.2 | K19: =F19+I19+J19 -> 258563.66
B20: Sealant | C20: 45 | D20: Unit | E20: 51.43 | F20: =C20*E20 -> 2314.35 | G20: =C20 -> 45 | H20: =60*4 -> 240 | I20: =G20*H20 -> 10800 | K20: =F20+I20+J20 -> 13114.35 | L20: Assuming 1 tube can do 10'
D21: LS | E21: 0 | F21: =C21*E21 -> 0 | H21: 0 | I21: =G21*H21 -> 0 | K21: =F21+I21+J21 -> 0
J22: Sub Total | K22: =SUM(K19:K21) -> 271678.01
A23: CODE | B23: DESCRIPTION | C23: Materials & Equipment | G23: Labor | O23: Previous Quote
A24: 07 31 00 | B24: Shingles | C24: Qty | D24: Unit | E24: U. Price | F24: Sub Total | G24: MHrs | H24: U. Price | I24: Sub Total | J24: Quote | K24: Total | O24: All Angles Covered | P24: 87550
C25: =E6/4 -> 16398 | D25: SF | E25: =P27 -> 5.30309 | F25: =M25 -> 81750 | H25: 0 | I25: =G25*H25 -> 0 | K25: =F25+I25+J25 -> 81750 | L25: All Angles | M25: 81750
D26: LS | E26: 0 | F26: =C26*E26 -> 0 | H26: 0 | I26: =G26*H26 -> 0 | K26: =F26+I26+J26 -> 0 | L26: Belvue | M26: 101990.13
J27: Sub Total | K27: =SUM(K25:K26) -> 81750 | L27: Eastbound | M27: 102450 | O27: Joyce per sf/floor | P27: =67275/12686 -> 5.30309
A28: CODE | B28: DESCRIPTION | C28: Materials & Equipment | G28: Labor | L28: Maximum | M28: 57500 | N28: Install only
A29: 07 42 00 | B29: Wall Panels | C29: Qty | D29: Unit | E29: U. Price | F29: Sub Total | G29: MHrs | H29: U. Price | I29: Sub Total | J29: Quote | K29: Total
D30: LS | E30: 0 | F30: =C30*E30 -> 0 | H30: 0 | I30: =G30*H30 -> 0 | K30: =F30+I30+J30 -> 0
D31: LS | E31: 0 | F31: =C31*E31 -> 0 | H31: 0 | I31: =G31*H31 -> 0 | K31: =F31+I31+J31 -> 0
D32: LS | E32: 0 | F32: =C32*E32 -> 0 | H32: 0 | I32: =G32*H32 -> 0 | K32: =F32+I32+J32 -> 0
J33: Sub Total | K33: =SUM(K30:K32) -> 0
A34: CODE | B34: DESCRIPTION | C34: Materials & Equipment | G34: Labor
A35: 07 46 00 | B35: Siding | C35: Qty | D35: Unit | E35: U. Price | F35: Sub Total | G35: MHrs | H35: U. Price | I35: Sub Total | J35: Quote | K35: Total | L35: Century
B36: Metal Siding | C36: =20027+4282 -> 24309 | D36: SF | E36: 12 | F36: =C36*E36 -> 291708 | H36: 0 | I36: =G36*H36 -> 0 | K36: =F36+I36+J36 -> 291708 | L36: Shaw Materials | M36: 192414.29
D37: LS | E37: 0 | F37: =C37*E37 -> 0 | H37: 0 | I37: =G37*H37 -> 0 | J37: =M37-55000 -> 270000 | K37: =F37+I37+J37 -> 270000 | L37: AVT Install | M37: 325000 | N37: $55k credit if no need to install brick veneer. Includes strapping install
D38: LS | E38: 0 | F38: =C38*E38 -> 0 | H38: 0 | I38: =G38*H38 -> 0 | K38: =F38+I38+J38 -> 0 | L38: Century | M38: 715000 | N38: =M38/C36 -> 29.412975 | O38: Price per sf
J39: Sub Total | K39: =SUM(K36:K38) -> 561708 | L39: Riztcor Install | M39: $550 Per square | N39: $5.50 per SF | O39: =C36*5.5 -> 133699.5
A40: CODE | B40: DESCRIPTION | C40: Materials & Equipment | G40: Labor
A41: 07 52 00 | B41: Modified Bituminous Membrane Roofing | C41: Qty | D41: Unit | E41: U. Price | F41: Sub Total | G41: MHrs | H41: U. Price | I41: Sub Total | J41: Quote | K41: Total
D42: LS | E42: 0 | F42: =C42*E42 -> 0 | H42: 0 | I42: =G42*H42 -> 0 | K42: =F42+I42+J42 -> 0
D43: LS | E43: 0 | F43: =C43*E43 -> 0 | H43: 0 | I43: =G43*H43 -> 0 | K43: =F43+I43+J43 -> 0
D44: LS | E44: 0 | F44: =C44*E44 -> 0 | H44: 0 | I44: =G44*H44 -> 0 | K44: =F44+I44+J44 -> 0
J45: Sub Total | K45: =SUM(K42:K44) -> 0
...

Sheet 8
C1: ='Estimate Summary'!C1:H1 -> 0
G5: Openings | J5: Schedule
D6: ='Estimate Summary'!C11 -> Area: | E6: ='Estimate Summary'!D11 -> 65592 | F6: ='Estimate Summary'!E11 -> Sq. Ft. | J6: ='1'!J6 -> 60 | K6: Weeks
A11: CODE | B11: DESCRIPTION | C11: Materials & Equipment | G11: Labor | L11: Sub Contractor | M11: Quote Total | N11: Additional Quote Info
A12: 08 11 00 | B12: Metal Doors and Frames | C12: Qty | D12: Unit | E12: U. Price | F12: Sub Total | G12: MHrs | H12: U. Price | I12: Sub Total | J12: Quote | K12: Total
A13: 08 11 13 | B13: Hollow Metal Doors and Frames | C13: 59 | D13: Unit | E13: =M17 -> 2040.8644 | H13: 0 | I13: =G13*H13 -> 0 | J13: =M13 -> 89875 | K13: =F13+I13+J13 -> 89875 | L13: Sevy | M13: =88350+1525 -> 89875
A14: 08 11 16 | B14: Aluminum Doors and Frames | D14: LS | E14: 0 | F14: =C14*E14 -> 0 | H14: 0 | I14: =G14*H14 -> 0 | K14: =F14+I14+J14 -> 0
D15: LS | E15: 0 | F15: =C15*E15 -> 0 | H15: 0 | I15: =G15*H15 -> 0 | K15: =F15+I15+J15 -> 0
D16: LS | E16: 0 | F16: =C16*E16 -> 0 | H16: 0 | I16: =G16*H16 -> 0 | K16: =F16+I16+J16 -> 0
L17: Joyce | M17: =120411/59 -> 2040.8644
J18: Sub Total | K18: =SUM(K13:K17) -> 89875
A19: CODE | B19: DESCRIPTION | C19: Materials & Equipment | G19: Labor
A20: 08 14 00 | B20: Wood Doors | C20: Qty | D20: Unit | E20: U. Price | F20: Sub Total | G20: MHrs | H20: U. Price | I20: Sub Total | J20: Quote | K20: Total
D21: LS | E21: 0 | F21: =C21*E21 -> 0 | H21: 0 | I21: =G21*H21 -> 0 | K21: =F21+I21+J21 -> 0
D22: LS | E22: 0 | F22: =C22*E22 -> 0 | H22: 0 | I22: =G22*H22 -> 0 | K22: =F22+I22+J22 -> 0
D23: LS | E23: 0 | F23: =C23*E23 -> 0 | H23: 0 | I23: =G23*H23 -> 0 | K23: =F23+I23+J23 -> 0
J24: Sub Total | K24: =SUM(K21:K23) -> 0
A25: CODE | B25: DESCRIPTION | C25: Materials & Equipment | G25: Labor
A26: 08 31 00 | B26: Access Doors and Panels | C26: Qty | D26: Unit | E26: U. Price | F26: Sub Total | G26: MHrs | H26: U. Price | I26: Sub Total | J26: Quote | K26: Total
B27: Attict Hatches | C27: 1 | D27: LS | E27: 8000 | F27: =C27*E27 -> 8000 | H27: 0 | I27: =G27*H27 -> 0 | K27: =F27+I27+J27 -> 8000
D28: LS | E28: 0 | F28: =C28*E28 -> 0 | H28: 0 | I28: =G28*H28 -> 0 | K28: =F28+I28+J28 -> 0
J29: Sub Total | K29: =SUM(K27:K28) -> 8000
A30: CODE | B30: DESCRIPTION | C30: Materials & Equipment | G30: Labor
A31: 08 32 00 | B31: Sliding Gates | C31: Qty | D31: Unit | E31: U. Price | F31: Sub Total | G31: MHrs | H31: U. Price | I31: Sub Total | J31: Quote | K31: Total
D32: LS | E32: 0 | F32: =C32*E32 -> 0 | H32: 0 | I32: =G32*H32 -> 0 | K32: =F32+I32+J32 -> 0
D33: LS | E33: 0 | F33: =C33*E33 -> 0 | H33: 0 | I33: =G33*H33 -> 0 | K33: =F33+I33+J33 -> 0
D34: LS | E34: 0 | F34: =C34*E34 -> 0 | H34: 0 | I34: =G34*H34 -> 0 | K34: =F34+I34+J34 -> 0
J35: Sub Total | K35: =SUM(K32:K34) -> 0
A36: CODE | B36: DESCRIPTION | C36: Materials & Equipment | G36: Labor
A37: 08 33 00 | B37: Coiling Doors and Drilles | C37: Qty | D37: Unit | E37: U. Price | F37: Sub Total | G37: MHrs | H37: U. Price | I37: Sub Total | J37: Quote | K37: Total
D38: LS | E38: 0 | F38: =C38*E38 -> 0 | H38: 0 | I38: =G38*H38 -> 0 | J38: =M38 -> 10984.51 | K38: =F38+I38+J38 -> 10984.51 | L38: Gagnon | M38: 10984.51
D39: LS | E39: 0 | F39: =C39*E39 -> 0 | H39: 0 | I39: =G39*H39 -> 0 | K39: =F39+I39+J39 -> 0 | L39: Iller | M39: 7273
D40: LS | E40: 0 | F40: =C40*E40 -> 0 | H40: 0 | I40: =G40*H40 -> 0 | K40: =F40+I40+J40 -> 0
J41: Sub Total | K41: =SUM(K38:K40) -> 10984.51
A42: CODE | B42: DESCRIPTION | C42: Materials & Equipment | G42: Labor
A43: 08 34 00 | B43: Special Function Doors | C43: Qty | D43: Unit | E43: U. Price | F43: Sub Total | G43: MHrs | H43: U. Price | I43: Sub Total | J43: Quote | K43: Total
D44: LS | E44: 0 | F44: =C44*E44 -> 0 | H44: 0 | I44: =G44*H44 -> 0 | K44: =F44+I44+J44 -> 0
D45: LS | E45: 0 | F45: =C45*E45 -> 0 | H45: 0 | I45: =G45*H45 -> 0 | K45: =F45+I45+J45 -> 0
D46: LS | E46: 0 | F46: =C46*E46 -> 0 | H46: 0 | I46: =G46*H46 -> 0 | K46: =F46+I46+J46 -> 0
J47: Sub Total | K47: =SUM(K44:K46) -> 0
...

Sheet 9
C1: ='Estimate Summary'!C1:H1 -> 0
G5: Finishes | J5: Schedule
D6: ='Estimate Summary'!C11 -> Area: | E6: ='Estimate Summary'!D11 -> 65592 | F6: ='Estimate Summary'!E11 -> Sq. Ft. | J6: ='1'!J6 -> 60 | K6: Weeks
A9: CODE | B9: DESCRIPTION | C9: Materials & Equipment | G9: Labor | L9: Sub Contractor | M9: Quote Total | N9: Additional Quote Info | O9: Previous Quotes
A10: 09 20 00 | B10: Plaster and Gypsum Board | C10: Qty | D10: Unit | E10: U. Price | F10: Sub Total | G10: MHrs | H10: U. Price | I10: Sub Total | J10: Quote | K10: Total
D11: SF | E11: 0 | F11: =C11*E11 -> 0 | H11: 0 | I11: =G11*H11 -> 0 | J11: =M13 -> 1139222 | K11: =F11+I11+J11 -> 1139222 | L11: A1 | M11: 1209800 | N11: Price no longer valid - Merge with Arsenault | O11: A1 | P11: 1298700
