Workbook
Name Discount: #REF!
Name Discount: #REF!
Name Discount: #REF!
Name Discount: #REF!
Name Discount: #REF!
Name Discount: #REF!
Name Discount: #REF!
Name Discount: #REF!
Name Discount: #REF!
Name Discount: #REF!
Name Discount: #REF!
Name Discount: #REF!
Name Discount: #REF!
Name Discount: #REF!
Name Discount: #REF!

Sheet Cost Data
A1: Division | B1: 2
B2: 01 00 00 | C2: General Requirements
B3: 01 11 00 | C3: Preconstruction Costs | D3: ='1'!K24 -> 52700
B4: 01 31 00 | C4: Project Management and Coordination | D4: ='1'!K35 -> 57200
B5: 01 41 00 | C5: Permits | D5: ='1'!K67 -> 2816.89
B6: 01 45 00 | C6: Quality Control | D6: ='1'!K76 -> 0
B7: 01 51 00 | C7: Temporary Utilities | D7: ='1'!K87 -> 0
B8: 01 52 00 | C8: Construction Facilities | D8: ='1'!K97 -> 2154.4402
B9: 01 54 00 | C9: Construction Aids | D9: ='1'!K105 -> 1395.6286
B10: 01 56 00 | C10: Temporary Barriers & Enclosures | D10: ='1'!K128 -> 3000
B11: 01 74 00 | C11: Cleaning & Waste Management | D11: ='1'!K136 -> 5347
A13: Division | B13: 2
B15: 02 00 00 | C15: Existing Conditions
B16: 02 41 00 | C16: Demolition | D16: ='2'!K26 -> 15786
B17: 02 82 00 | C17: Asbestos Remediation | D17: ='2'!K37 -> 0
B18: 02 83 00 | C18: Trenching | D18: ='2'!K48 -> 1500
A21: Division | B21: 3
B22: 03 00 00 | C22: Concrete
B23: 03 11 00 | C23: Concrete Forming | D23: ='3'!K26 -> 0
B24: 03 20 00 | C24: Concrete Reinforcing | D24: ='3'!K37 -> 0
B25: 03 30 00 | C25: Cast-in-Place Concrete | D25: ='3'!K46 -> 0
B26: 03 35 00 | C26: Concrete Finishing | D26: ='3'!K55 -> 0
B27: 03 40 00 | C27: Precast Concrete | D27: ='3'!K66 -> 0
B28: 03 60 00 | C28: Grouting | D28: ='3'!K75 -> 0
A31: Division | B31: 4
B32: 04 00 00 | C32: Masonry
B33: 04 20 00 | C33: Unit Masonry | D33: ='4'!K26 -> 0
B34: 04 43 00 | C34: Stone Masonry | D34: ='4'!K37 -> 0
A36: Division | B36: 5
B37: 05 00 00 | C37: Metals
B38: 05 12 00 | C38: Structural Steel Framing | D38: ='5'!K26 -> 0
B39: 05 20 00 | C39: Metal Joists | D39: ='5'!K37 -> 0
B40: 05 30 00 | C40: Metal Decking | D40: ='5'!K45 -> 0
B41: 05 51 00 | C41: Metal Stairs | D41: ='5'!K54 -> 0
B42: 05 52 00 | C42: Metal Railings | D42: ='5'!K65 -> 0
B43: 05 59 00 | C43: Metal Specialties | D43: ='5'!K74 -> 0
A46: Division | B46: 6
B47: 06 00 00 | C47: Wood, Plastics, and Composites
B48: 06 11 00 | C48: Framing | D48: ='6'!K19 -> 1300
B49: 06 20 00 | C49: Finish Carpentry | D49: ='6'!K36 -> 1995.8
...

Sheet Cost Report
B1: Division | C1: Sub - Division | D1: Discription | E1: Cost
B2: 01 00 00 | D2: General Requirements | E2: ='Estimate Summary'!H15 -> 125764
B3: 01 11 00 | D3: Preconstruction Costs | E3: ='1'!K24 -> 52700
B4: 01 31 00 | D4: Project Management and Coordination | E4: ='1'!K35 -> 57200
B5: 01 31 00 | C5: 01 31 01 | D5: Senior Construction Manager | E5: ='1'!K27 -> 0
B6: 01 31 00 | C6: 01 31 02 | D6: Senior Estimator | E6: ='1'!K28 -> 0
B7: 01 31 00 | C7: 01 31 03 | D7: Senior Project Manager | E7: ='1'!K29 -> 13000
B8: 01 31 00 | C8: 01 31 04 | D8: Project Coordinator | E8: ='1'!K30 -> 0
B9: 01 31 00 | C9: 01 31 05 | D9: Project Superintendent | E9: ='1'!K31 -> 44200
B10: 01 31 00 | C10: 01 31 06 | D10: Project Foreman | E10: ='1'!K32 -> 0
B11: 01 32 00 | C11: 01 32 00 | D11: Travel
B12: 01 41 00 | D12: Permits | E12: ='1'!K67 -> 2816.89
B13: 01 45 00 | D13: Quality Control | E13: ='1'!K76 -> 0
B14: 01 51 00 | D14: Temporary Utilities | E14: ='1'!K87 -> 0
B15: 01 52 00 | D15: Construction Facilities | E15: ='1'!K97 -> 2154.4402
B16: 01 52 00 | C16: 01 52 01 | D16: Construction Field Office | E16: ='1'!K90 -> 0
B17: 01 52 00 | C17: 01 52 02 | D17: Sanitary Facilities | E17: ='1'!K92 -> 0
B18: 01 52 00 | C18: 01 52 03 | D18: Drawing Reprographics | E18: ='1'!K93 -> 329.44023
B19: 01 52 00 | C19: 01 52 04 | D19: First-Aid / Safety | E19: ='1'!K94 -> 1625
B20: 01 52 00 | C20: 01 52 05 | D20: Job Sign | E20: ='1'!K95 -> 200
B21: 01 54 00 | D21: Construction Aids | E21: ='1'!K105 -> 1395.6286
B22: 01 55 00 | C22: 01 55 00 | D22: Winter Conditions
B23: 01 56 00 | D23: Temporary Barriers & Enclosures | E23: ='1'!K128 -> 3000
B24: 01 74 00 | D24: Cleaning & Waste Management | E24: ='1'!K136 -> 5347
B25: 01 74 00 | C25: 01 74 01 | D25: Progress Cleaning | E25: ='1'!K131 -> 0
B26: 01 74 00 | C26: 01 74 02 | D26: Site Maintenance | E26: ='1'!K132 -> 0
B27: 01 74 00 | C27: 01 74 03 | D27: Construction Waste Mgmt & Disposal | E27: ='1'!K133 -> 3600
B28: 01 74 00 | C28: 01 74 04 | D28: Final Cleaning | E28: ='1'!K134 -> 1747
B29: 02 00 00 | D29: Existing Conditions | E29: ='Estimate Summary'!H17 -> 17286
B30: 02 41 00 | D30: Demolition | E30: ='2'!K26 -> 15786
B31: 02 82 00 | D31: Asbestos Remediation | E31: ='2'!K37 -> 0
B32: 02 83 00 | D32: Trenching | E32: ='2'!K48 -> 1500
B33: 03 00 00 | D33: Concrete | E33: ='Estimate Summary'!H19 -> 0
B34: 03 11 00 | D34: Concrete Forming | E34: ='3'!K26 -> 0
B35: 03 20 00 | D35: Concrete Reinforcing | E35: ='3'!K37 -> 0
B36: 03 30 00 | D36: Cast-in-Place Concrete | E36: ='3'!K46 -> 0
B37: 03 35 00 | D37: Concrete Finishing | E37: ='3'!K55 -> 0
B38: 03 40 00 | D38: Precast Concrete | E38: ='3'!K66 -> 0
B39: 03 60 00 | D39: Foundation Materials | E39: ='3'!K75 -> 0
B40: 03 60 00 | C40: 03 60 01 | D40: Insulation | E40: ='3'!K69 -> 0
...

Sheet DATA
B2: Quarter | C2: Column1 | D2: Province | H2: Project Definition | J2: Contract Type | K2: Payment Method | M2: A | N2: >5M
B3: Q1 | D3: NB | H3: Multi Residential | J3: CCDC 2 | K3: Stipulated Price | M3: B | N3: 2-5M
B4: Q2 | D4: PEI | H4: Office | J4: CCDC 5B | K4: Fixed Fee | M4: C | N4: 500K - 2M | R4: Status | T4: Result
B5: Q3 | D5: NS | H5: Retail | J5: CCDC 5A | M5: D | N5: 100K - 500K | R5: Awarded | T5: Successful
B6: Q4 | D6: Other | H6: Food | J6: Design Build | M6: E | N6: less than 100K | R6: Not Awarded | T6: Unsuccessful
R7: Pending
A10: Closing Date | B10: Budget Year | C10: Quarter | D10: Province | E10: City/Town | F10: Estimate Number | G10: Estimate Name | H10: Type of Construction | I10: Area | J10: Contract Type | K10: Payment Method | L10: Estimate Price | M10: Price Category | N10: Schedule | O10: Soft Cost | P10: Cost per Week | Q10: Margin | R10: Status | S10: Bid Docs | T10: Successful / Unsuccessful
A11: =+'Estimate Summary'!B3 -> 46030 | B11: =+'Estimate Summary'!B7 -> 2026 | C11: =+'Estimate Summary'!B8 -> Q1 | D11: =+'Estimate Summary'!B5 -> NB | E11: ='Estimate Summary'!B6 -> Moncton | F11: ='Estimate Summary'!B4 -> 3041 | G11: ='Estimate Summary'!D5 -> Dr. Goel Dental Office | H11: =+'Estimate Summary'!F8 -> 0 | I11: =+'Estimate Summary'!D11 -> 1747 | J11: ='Estimate Summary'!D7 -> CCDC 5B | K11: =+'Estimate Summary'!D8 -> Fixed Fee | L11: =+'Estimate Summary'!D75 -> 760983.56 | M11: =IF(L11<100000,"E",IF(L11<500000,"D",IF(L11<2000000,"C",IF(L11<5000000,"B",IF(L11>=5000000,"A"))))) -> C | N11: ='Estimate Summary'!D81 -> 13 | O11: ='Estimate Summary'!D82 -> 95539.74 | P11: ='Estimate Summary'!E82 -> 7349.2108 | Q11: ='Estimate Summary'!D84 -> 0.12554771 | R11: ='Estimate Summary'!F6 -> 0 | S11: ='Estimate Summary'!F5 -> 0 | T11: ='Estimate Summary'!F7 -> 0

Sheet Estimate Version Comparison
B2: ='Estimate Summary'!D5 -> Dr. Goel Dental Office | I2: CLIENT SUMMARY
B3: ='Estimate Summary'!D6 -> Dr. Goel
B4: Date: | C4: ='Estimate Summary'!B3 -> 46030
D7: 45839 | G7: 46023 | H7: ='Estimate Summary'!G8 -> 0
B8: 01 00 00 | C8: General Requirements | E8: =SUM(D9:D17) -> 126486.21 | H8: =SUM(G9:G17) -> 125764 | J8: =IF(H8>E8,"Increase","Decrease or No Change") -> Decrease or No Change | K8: =H8-E8 -> -722.20365
B9: 01 11 00 | C9: Preconstruction Costs | D9: 56200 | G9: ='1'!K24 -> 52700
B10: 01 31 00 | C10: Project Management and Coordination | D10: 57200 | G10: ='1'!K35 -> 57200
B11: 01 41 00 | C11: Permits | D11: 2914.7553 | G11: ='1'!K67 -> 2816.89
B12: 01 45 00 | C12: Insurance | D12: 699.54126 | G12: ='1'!K45 -> 1150.0459
B13: 01 51 00 | C13: Temporary Utilities | D13: 0 | G13: ='1'!K87 -> 0
B14: 01 52 00 | C14: Construction Facilities | D14: 2025.3894 | G14: ='1'!K97 -> 2154.4402
B15: 01 54 00 | C15: Construction Aids | D15: 848.92247 | G15: ='1'!K105 -> 1395.6286
B16: 01 56 00 | C16: Temporary Barriers & Enclosures | D16: 3000 | G16: ='1'!K128 -> 3000
B17: 01 74 00 | C17: Cleaning & Waste Management | D17: 3597.6 | G17: ='1'!K136 -> 5347
B19: 02 00 00 | C19: Existing Conditions | E19: =SUM(D20:D22) -> 16615 | H19: =SUM(G20:G22) -> 11586 | J19: =IF(H19>E19,"Increase","Decrease or No Change") -> Decrease or No Change | K19: =H19-E19 -> -5029
B20: 02 41 00 | C20: Demolition | D20: 8735 | G20: ='2'!K13 -> 10086
B21: 02 82 00 | C21: Asbestos Remediation | D21: 0 | G21: ='2'!K37 -> 0
B22: 02 83 00 | C22: Trenching | D22: 7880 | G22: ='2'!K48 -> 1500
B24: 03 00 00 | C24: Concrete | E24: =SUM(D25:D29) -> 0 | H24: =SUM(G25:G29) -> 0 | J24: =IF(H24>E24,"Increase","Decrease or No Change") -> Decrease or No Change | K24: =H24-E24 -> 0
B25: 03 11 00 | C25: Concrete Forming | D25: 0 | G25: ='3'!K26 -> 0
B26: 03 20 00 | C26: Concrete Reinforcing | D26: 0 | G26: ='3'!K37 -> 0
B27: 03 30 00 | C27: Cast-in-Place Concrete | D27: 0 | G27: ='3'!K46+'3'!K55 -> 0
B28: 03 40 00 | C28: Precast Concrete | D28: 0 | G28: ='3'!K66 -> 0
B29: 03 60 00 | C29: Grouting | D29: 0 | G29: ='3'!K75 -> 0
B31: 04 00 00 | C31: Masonry | E31: =SUM(D32:D33) -> 0 | H31: =SUM(G32:G33) -> 0 | J31: =IF(H31>E31,"Increase","Decrease or No Change") -> Decrease or No Change | K31: =H31-E31 -> 0
B32: 04 20 00 | C32: Unit Masonry | D32: 0 | G32: ='4'!K26 -> 0
B33: 04 40 00 | C33: Stone Assemblies | D33: 0 | G33: ='4'!K37 -> 0
B35: 05 00 00 | C35: Metals | E35: =SUM(D36:D39) -> 0 | H35: =SUM(G36:G39) -> 0 | J35: =IF(H35>E35,"Increase","Decrease or No Change") -> Decrease or No Change | K35: =H35-E35 -> 0
B36: 05 12 00 | C36: Structural Steel Framing | D36: 0 | G36: ='5'!K26 -> 0
B37: 05 20 00 | C37: Metal Joists | D37: 0 | G37: ='5'!K37 -> 0
B38: 05 30 00 | C38: Metal Decking | D38: 0 | G38: ='5'!K45 -> 0
B39: 05 50 00 | C39: Metal Fabrications | D39: 0 | G39: ='5'!K54+'5'!K65+'5'!K74 -> 0
B41: 06 00 00 | C41: Wood, Plastics, and Composites | E41: =SUM(D42:D45) -> 57936.36 | H41: =SUM(G42:G45) -> 184170.8 | J41: =IF(H41>E41,"Increase","Decrease or No Change") -> Increase | K41: =H41-E41 -> 126234.44
B42: 06 11 00 | C42: Framing Labour | D42: 0 | G42: ='6'!K19 -> 1300
B43: 06 11 00 | C43: Framing Material | D43: 2836.36 | G43: ='6'!K36 -> 1995.8
B44: 06 22 00 | C44: Millwork | D44: 55100 | G44: ='6'!K51 -> 180875 | J44: All Laminates
B45: 06 40 00 | C45: Architectural Woodwork | D45: 0 | G45: ='6'!K59+'6'!K68+'6'!K79+'6'!K88+'6'!K95 -> 0
B47: 07 00 00 | C47: Thermal and Moisture Protection | E47: =SUM(D48:D57) -> 0 | H47: =SUM(G48:G57) -> 8446 | J47: =IF(H47>E47,"Increase","Decrease or No Change") -> Increase | K47: =H47-E47 -> 8446
B48: 07 21 00 | C48: Thermal Insulation | D48: 0 | G48: ='7'!K16 -> 0
B49: 07 24 00 | C49: EIFS | D49: 0 | G49: ='7'!K22 -> 0
...

Sheet Client  Detailed Summary 
B3: ='Estimate Summary'!D5 -> Dr. Goel Dental Office | F3: CLIENT SUMMARY
B4: 585 Mapleton Drive
B5: Date: | C5: ='Estimate Summary'!B3 -> 46030
B7: 01 00 00 | C7: General Requirements | H7: =SUM(G8:G17) -> 125764
B8: 01 11 00 | C8: Preconstruction Costs - Design | G8: ='1'!K24 -> 52700
B9: 01 31 00 | C9: Project Management and Coordination | G9: ='1'!K35 -> 57200
B10: 01 32 00 | C10: Insurance | G10: ='1'!K45+'1'!K56 -> 1150.0459
B11: 01 41 00 | C11: Permits | G11: ='1'!K67 -> 2816.89
B12: 01 45 00 | C12: Quality Control | G12: ='1'!K76 -> 0
B13: 01 51 00 | C13: Temporary Utilities | G13: ='1'!K87 -> 0
B14: 01 52 00 | C14: Construction Facilities | G14: ='1'!K97 -> 2154.4402
B15: 01 54 00 | C15: Construction Aids & Winter Conditions | G15: ='1'!K105+'1'!K120 -> 1395.6286
B16: 01 56 00 | C16: Temporary Barriers & Enclosures | G16: ='1'!K128 -> 3000
B17: 01 74 00 | C17: Cleaning & Waste Management | G17: ='1'!K136 -> 5347
B19: 02 00 00 | C19: Existing Conditions | H19: =SUM(G20:G22) -> 17286
B20: 02 41 00 | C20: Demolition and Core Drilling | G20: ='2'!K26 -> 15786
B21: 02 82 00 | C21: Asbestos Remediation | G21: ='2'!K37 -> 0
B22: 02 83 00 | C22: Core Drilling | G22: ='2'!K48 -> 1500
B24: 03 00 00 | C24: Concrete | H24: =SUM(G25:G29) -> 0
B25: 03 11 00 | C25: Concrete Forming | G25: ='3'!K26 -> 0
B26: 03 20 00 | C26: Concrete Reinforcing | G26: ='3'!K37 -> 0
B27: 03 30 00 | C27: Cast-in-Place Concrete | G27: ='3'!K46+'3'!K55 -> 0
B28: 03 40 00 | C28: Precast Concrete | G28: ='3'!K66 -> 0
B29: 03 60 00 | C29: Grouting | G29: ='3'!K75 -> 0
B31: 04 00 00 | C31: Masonry | H31: =SUM(G32:G33) -> 0
B32: 04 20 00 | C32: Unit Masonry | G32: ='4'!K26 -> 0
B33: 04 40 00 | C33: Stone Assemblies | G33: ='4'!K37 -> 0
B35: 05 00 00 | C35: Metals | H35: =SUM(G36:G39) -> 0
B36: 05 12 00 | C36: Structural Steel Framing | G36: ='5'!K26 -> 0
B37: 05 20 00 | C37: Metal Joists | G37: ='5'!K37 -> 0
B38: 05 30 00 | C38: Metal Decking | G38: ='5'!K45 -> 0
B39: 05 50 00 | C39: Metal Fabrications | G39: ='5'!K54+'5'!K65+'5'!K74 -> 0
B41: 06 00 00 | C41: Wood, Plastics, and Composites | H41: =SUM(G42:G45) -> 184170.8
B42: 06 11 00 | C42: Wood Labour | G42: ='6'!K19 -> 1300
B43: 06 11 00 | C43: Wood materials | G43: ='6'!K36 -> 1995.8
B44: 06 22 00 | C44: Millwork | G44: ='6'!K51 -> 180875
B45: 06 40 00 | C45: Architectural Woodwork | G45: ='6'!K59+'6'!K68+'6'!K79+'6'!K88+'6'!K95 -> 0
B47: 07 00 00 | C47: Thermal and Moisture Protection | H47: =SUM(G48:G57) -> 8446
B48: 07 21 00 | C48: Thermal Insulation | G48: ='7'!K16 -> 0
B49: 07 24 00 | C49: EIFS | G49: ='7'!K22 -> 0
...

Sheet Estimate Summary
A2: Project Information
A3: Closing Date : | B3: 46030
A4: Estimate # E- | B4: 3041 | C4: Area: | D4: 1747
A5: Province : | B5: NB | C5: Estimate Name : | D5: Dr. Goel Dental Office | E5: Bid Documents :
A6: City/Town : | B6: Moncton | C6: Client : | D6: Dr. Goel | E6: Status :
A7: Budget Year : | B7: 2026 | C7: Contract Type : | D7: CCDC 5B | E7: Result:
A8: Quarter: | B8: Q1 | C8: Payment Method : | D8: Fixed Fee
C11: Area: | D11: =D4 -> 1747 | E11: Sq. Ft.
A13: CODE | B13: DESCRIPTION | D13: M&E $$ | E13: M-HRS | F13: LAB $$ | G13: SUB CONT. | H13: Total | K13: Sackville Smiles | L13: Prisma Dental | M13: Mountain View Dental
C14: % | I14: $/SF
A15: 01 00 00 | B15: General Requirements | C15: =H15/D$66 -> 0.17352833 | D15: =SUM('1'!F139:F140) -> 17547.115 | E15: =SUM('1'!G139:G140) -> 50 | F15: =SUM('1'!I139:I140) -> 57200 | G15: =SUM('1'!J139:J140) -> 51016.89 | H15: =D15+F15+G15 -> 125764 | I15: =ROUNDUP(H15/D$11,1)&"$/SF" -> 72$/SF | K15: 75.6$/SF | L15: 22.8$/SF | M15: 53.3$/SF
A17: 02 00 00 | B17: Existing Conditions | C17: =H17/D$66 -> 0.023851107 | D17: =SUM('2'!F51:F52) -> 1500 | E17: =SUM('2'!G51:G52) -> 0 | F17: =SUM('2'!I51:I52) -> 0 | G17: =SUM('2'!J51:J52) -> 15786 | H17: =D17+F17+G17 -> 17286 | I17: =ROUNDUP(H17/D$11,1)&"$/SF" -> 9.9$/SF | K17: 0$/SF | L17: 0$/SF | M17: 8.7$/SF
A19: 03 00 00 | B19: Concrete | C19: =H19/D$66 -> 0 | D19: =SUM('3'!F78:F79) -> 0 | E19: =SUM('3'!G78:G79) -> 0 | F19: =SUM('3'!I78:I79) -> 0 | G19: =SUM('3'!J78:J79) -> 0 | H19: =D19+F19+G19 -> 0 | I19: =ROUNDUP(H19/D$11,1)&"$/SF" -> 0$/SF | K19: 21.7$/SF | L19: 25.9$/SF | M19: 0.6$/SF
A21: 04 00 00 | B21: Masonry | C21: =H21/D$66 -> 0 | D21: =SUM('4'!F68:F69) -> 0 | E21: =SUM('4'!G68:G69) -> 0 | F21: =SUM('4'!I68:I69) -> 0 | G21: =SUM('4'!J68:J69) -> 0 | H21: =D21+F21+G21 -> 0 | I21: =ROUNDUP(H21/D$11,1)&"$/SF" -> 0$/SF | K21: 9.5$/SF | L21: 0$/SF | M21: 0$/SF
A23: 05 00 00 | B23: Metals | C23: =H23/D$66 -> 0 | D23: =SUM('5'!F77:F78) -> 0 | E23: =SUM('5'!G77:G78) -> 0 | F23: =SUM('5'!I77:I78) -> 0 | G23: =SUM('5'!J77:J78) -> 0 | H23: =D23+F23+G23 -> 0 | I23: =ROUNDUP(H23/D$11,1)&"$/SF" -> 0$/SF | K23: 0$/SF | L23: 25.3$/SF | M23: 10.4$/SF
A25: 06 00 00 | B25: Wood, Plastics, and Composites | C25: =H25/D$66 -> 0.25411763 | D25: =SUM('6'!F98:F99) -> 1995.8 | E25: =SUM('6'!G98:G99) -> 20 | F25: =SUM('6'!I98:I99) -> 1300 | G25: =SUM('6'!J98:J99) -> 180875 | H25: =D25+F25+G25 -> 184170.8 | I25: =ROUNDUP(H25/D$11,1)&"$/SF" -> 105.5$/SF | K25: 40$/SF | L25: 41.2$/SF | M25: 57.5$/SF
A27: 07 00 00 | B27: Thermal and Moisture Protection | C27: =H27/D$66 -> 0.011653734 | D27: =SUM('7'!F93:F94) -> 0 | E27: =SUM('7'!G93:G94) -> 0 | F27: =SUM('7'!I93:I94) -> 0 | G27: =SUM('7'!J93:J94) -> 8446 | H27: =D27+F27+G27 -> 8446 | I27: =ROUNDUP(H27/D$11,1)&"$/SF" -> 4.9$/SF | K27: 29.1$/SF | L27: 48.1$/SF | M27: 0$/SF
A29: 08 00 00 | B29: Openings | C29: =H29/D$66 -> 0.031335105 | D29: =SUM('8'!F108:F109) -> 480 | E29: =SUM('8'!G108:G109) -> 28 | F29: =SUM('8'!I108:I109) -> 1820 | G29: =SUM('8'!J108:J109) -> 20410 | H29: =D29+F29+G29 -> 22710 | I29: =ROUNDUP(H29/D$11,1)&"$/SF" -> 13$/SF | K29: 22.4$/SF | L29: 22.2$/SF | M29: 6.6$/SF
A31: 09 00 00 | B31: Finishes | C31: =H31/D$66 -> 0.13813309 | D31: =SUM('9'!F65:F66) -> 3494 | E31: =SUM('9'!G65:G66) -> 0 | F31: =SUM('9'!I65:I66) -> 0 | G31: =SUM('9'!J65:J66) -> 96617.44 | H31: =D31+F31+G31 -> 100111.44 | I31: =ROUNDUP(H31/D$11,1)&"$/SF" -> 57.4$/SF | K31: 42.2$/SF | L31: 58.2$/SF | M31: 43.4$/SF
A33: 10 00 00 | B33: Specialties | C33: =H33/D$66 -> 0.016129783 | D33: =SUM('10'!F74:F75) -> 0 | E33: =SUM('10'!G74:G75) -> 46 | F33: =SUM('10'!I74:I75) -> 1690 | G33: =SUM('10'!J74:J75) -> 10000 | H33: =D33+F33+G33 -> 11690 | I33: =ROUNDUP(H33/D$11,1)&"$/SF" -> 6.7$/SF | K33: 2.3$/SF | L33: 0.9$/SF | M33: 0.7$/SF
A35: 11 00 00 | B35: Equipment | C35: =H35/D$66 -> 0 | D35: =SUM('11'!F99:F100) -> 0 | E35: =SUM('11'!G99:G100) -> 0 | F35: =SUM('11'!I99:I100) -> 0 | G35: =SUM('11'!J99:J100) -> 0 | H35: =D35+F35+G35 -> 0 | I35: =ROUNDUP(H35/D$11,1)&"$/SF" -> 0$/SF | K35: 0$/SF | L35: 0$/SF | M35: 0$/SF
A37: 12 00 00 | B37: Furnishings | C37: =H37/D$66 -> 0 | D37: =SUM('12'!F99:F100) -> 0 | E37: =SUM('12'!G99:G100) -> 0 | F37: =SUM('12'!I99:I100) -> 0 | G37: =SUM('12'!J99:J100) -> 0 | H37: =D37+F37+G37 -> 0 | I37: =ROUNDUP(H37/D$11,1)&"$/SF" -> 0$/SF | K37: 0.8$/SF | L37: 0$/SF | M37: 0$/SF
A39: 13 00 00 | B39: Special Construction | C39: =H39/D$66 -> 0 | D39: =+SUM('13'!F99:F100) -> 0 | E39: =SUM('13'!G99:G100) -> 0 | F39: =SUM('13'!I99:I100) -> 0 | G39: =SUM('13'!J99:J100) -> 0 | H39: =D39+F39+G39 -> 0 | I39: =ROUNDUP(H39/D$11,1)&"$/SF" -> 0$/SF | K39: 0$/SF | L39: 0$/SF | M39: 0$/SF
A41: 14 00 00 | B41: Conveying Equipment | C41: =H41/D$66 -> 0 | D41: =SUM('14'!F99:F100) -> 0 | E41: =SUM('14'!G99:G100) -> 0 | F41: =SUM('14'!I99:I100) -> 0 | G41: =SUM('14'!J99:J100) -> 0 | H41: =D41+F41+G41 -> 0 | I41: =ROUNDUP(H41/D$11,1)&"$/SF" -> 0$/SF | K41: 0$/SF | L41: 0$/SF | M41: 0$/SF
A43: 21 00 00 | B43: Fire Suppression | C43: =H43/D$66 -> 0.0095730058 | D43: =SUM('21'!F99:F100) -> 0 | E43: =SUM('21'!G99:G100) -> 0 | F43: =SUM('21'!I99:I100) -> 0 | G43: =SUM('21'!J99:J100) -> 6938 | H43: =D43+F43+G43 -> 6938 | I43: =ROUNDUP(H43/D$11,1)&"$/SF" -> 4$/SF | K43: 0$/SF | L43: 6.3$/SF | M43: 2.8$/SF
A45: 22 00 00 | B45: Plumbing | C45: =H45/D$66 -> 0.17909717 | D45: =SUM('22'!F94:F95) -> 0 | E45: =SUM('22'!G94:G95) -> 0 | F45: =SUM('22'!I94:I95) -> 0 | G45: =SUM('22'!J94:J95) -> 129800 | H45: =D45+F45+G45 -> 129800 | I45: =ROUNDUP(H45/D$11,1)&"$/SF" -> 74.3$/SF | K45: 33.3$/SF | L45: 27.3$/SF | M45: 16.1$/SF
A47: 23 00 00 | B47: HVAC | C47: =H47/D$66 -> 0.051093745 | D47: =SUM('23'!F102:F103) -> 0 | E47: =SUM('23'!G102:G103) -> 0 | F47: =SUM('23'!I102:I103) -> 0 | G47: =SUM('23'!J102:J103) -> 37030 | H47: =D47+F47+G47 -> 37030 | I47: =ROUNDUP(H47/D$11,1)&"$/SF" -> 21.2$/SF | K47: 43.7$/SF | L47: 30.9$/SF | M47: 14.7$/SF
A49: 25 00 00 | B49: Integrated Automation | C49: =H49/D$66 -> 0 | D49: =SUM('25'!F54:F55) -> 0 | E49: =SUM('25'!G54:G55) -> 0 | F49: =SUM('25'!I54:I55) -> 0 | G49: =SUM('25'!J54:J55) -> 0 | H49: =D49+F49+G49 -> 0 | I49: =ROUNDUP(H49/D$11,1)&"$/SF" -> 0$/SF | K49: 0$/SF | L49: 0$/SF | M49: 0$/SF
A51: 26 00 00 | B51: Electrical | C51: =H51/D$66 -> 0.1114873 | D51: =SUM('26'!F57:F58) -> 0 | E51: =SUM('26'!G57:G58) -> 0 | F51: =SUM('26'!I57:I58) -> 0 | G51: =SUM('26'!J57:J58) -> 80800 | H51: =D51+F51+G51 -> 80800 | I51: =ROUNDUP(H51/D$11,1)&"$/SF" -> 46.3$/SF | K51: 64.9$/SF | L51: 34.6$/SF | M51: 37.6$/SF
A53: 27 00 00 | B53: Communications | C53: =H53/D$66 -> 0 | D53: =SUM('27'!F99:F100) -> 0 | E53: =SUM('27'!G99:G100) -> 0 | F53: =SUM('27'!I99:I100) -> 0 | G53: =SUM('27'!J99:J100) -> 0 | H53: =D53+F53+G53 -> 0 | I53: =ROUNDUP(H53/D$11,1)&"$/SF" -> 0$/SF | K53: 0$/SF | L53: 0$/SF | M53: 4.9$/SF
A55: 28 00 00 | B55: Electronic Safety and Security | C55: =H55/D$66 -> 0 | D55: =SUM('28'!F55:F56) -> 0 | E55: =SUM('28'!G55:G56) -> 0 | F55: =SUM('28'!I55:I56) -> 0 | G55: =SUM('28'!J55:J56) -> 0 | H55: =D55+F55+G55 -> 0 | I55: =ROUNDUP(H55/D$11,1)&"$/SF" -> 0$/SF | K55: 0$/SF | L55: 0$/SF | M55: 0$/SF
A57: 31 00 00 | B57: Earthwork | C57: =H57/D$66 -> 0 | D57: =SUM('31'!F69:F70) -> 0 | E57: =SUM('31'!G69:G70) -> 0 | F57: =SUM('31'!I69:I70) -> 0 | G57: =SUM('31'!J69:J70) -> 0 | H57: =D57+F57+G57 -> 0 | I57: =ROUNDUP(H57/D$11,1)&"$/SF" -> 0$/SF | K57: 102.9$/SF | L57: 49.6$/SF | M57: 0$/SF
A59: 32 00 00 | B59: Exterior Improvements | C59: =H59/D$66 -> 0 | D59: =SUM('32'!F97:F98) -> 0 | E59: =SUM('32'!G97:G98) -> 0 | F59: =SUM('32'!I97:I98) -> 0 | G59: =SUM('32'!J97:J98) -> 0 | H59: =D59+F59+G59 -> 0 | I59: =ROUNDUP(H59/D$11,1)&"$/SF" -> 0$/SF | K59: 59.3$/SF | L59: 16.2$/SF | M59: 0$/SF
A61: 33 00 00 | B61: Utilities | C61: =H61/D$66 -> 0 | D61: =SUM('33'!F57:F58) -> 0 | E61: =SUM('33'!G57:G58) -> 0 | F61: =SUM('33'!I57:I58) -> 0 | G61: =SUM('33'!J57:J58) -> 0 | H61: =D61+F61+G61 -> 0 | I61: =ROUNDUP(H61/D$11,1)&"$/SF" -> 0$/SF | K61: 0$/SF | L61: 0$/SF | M61: 0$/SF
B64: Sub Totals>>>>>> | C64: =SUM(C15:C63) -> 1 | D64: =SUM(D15:D63) -> 25016.915 | E64: =SUM(E15:E63) -> 144 | F64: =SUM(F15:F63) -> 62010 | G64: =SUM(G15:G63) -> 637719.33 | H64: =SUM(H15:H63) -> 724746.24 | I64: =ROUNDUP(H64/D$11,1)&"$/SF" -> 414.9$/SF | K64: 546.9$/SF | L64: 408.7$/SF | M64: 256.7$/SF
B66: Total Construction Cost>>>>>> | D66: =D64+F64+G64 -> 724746.24
B68: OH&P>>>>>> | D68: =(D66*E68) -> 36237.312 | E68: 0.05
F69: HST | G69: TOTAL
F70: 0.15
B71: Estimated Price | D71: =D68+D66 -> 760983.56 | F71: =D71*F70 -> 114147.53 | G71: =D71+F71 -> 875131.09
...

Sheet 1
C1: ='Estimate Summary'!C1:H1 -> 0
G5: General Requirements | J5: Schedule
D6: ='Estimate Summary'!C11 -> Area: | E6: ='Estimate Summary'!D11 -> 1747 | F6: ='Estimate Summary'!E11 -> Sq. Ft. | J6: ='Estimate Summary'!D81 -> 13 | K6: Weeks
A9: CODE | B9: DESCRIPTION | C9: Materials & Equipment | G9: Labor | L9: Sub Contractor | M9: Quote Total | N9: Additional Quote Info
A10: 01 11 00 | B10: Preconstruction Costs | C10: Qty | D10: Unit | E10: U. Price | F10: Sub Total | G10: MHrs | H10: U. Price | I10: Sub Total | J10: Quote | K10: Total
A11: 01 11 13 | B11: Senior Construction Manager | D11: LS | E11: 0 | F11: =C11*E11 -> 0 | H11: 0 | I11: =G11*H11 -> 0 | K11: =F11+I11+J11 -> 0
A12: 01 11 16 | B12: Senior Estimator | C12: 1 | D12: LS | E12: 4500 | F12: =C12*E12 -> 4500 | H12: 0 | I12: =G12*H12 -> 0 | K12: =F12+I12+J12 -> 4500
A13: 01 11 19 | B13: Junior Estimator | D13: LS | E13: 0 | F13: =C13*E13 -> 0 | H13: 0 | I13: =G13*H13 -> 0 | K13: =F13+I13+J13 -> 0
A14: 01 11 23 | B14: Reprographics | D14: LS | E14: 0 | F14: =C14*E14 -> 0 | H14: 0 | I14: =G14*H14 -> 0 | K14: =F14+I14+J14 -> 0
A15: 01 11 26 | B15: Design Costs | D15: LS | E15: 0 | F15: =C15*E15 -> 0 | H15: 0 | I15: =G15*H15 -> 0 | K15: =F15+I15+J15 -> 0
A16: 01 11 26.13 | B16: Architectural | D16: LS | E16: 0 | F16: =C16*E16 -> 0 | H16: 0 | I16: =G16*H16 -> 0 | J16: =M16 -> 35000 | K16: =F16+I16+J16 -> 35000 | L16: KUB | M16: 35000 | N16: KUB
A17: 01 11 26.16 | B17: Civil | D17: LS | E17: 0 | F17: =C17*E17 -> 0 | H17: 0 | I17: =G17*H17 -> 0 | K17: =F17+I17+J17 -> 0
A18: 01 11 26.19 | B18: Structural | D18: LS | E18: 0 | F18: =C18*E18 -> 0 | H18: 0 | I18: =G18*H18 -> 0 | K18: =F18+I18+J18 -> 0 | L18: Mountain View | M18: 3500 | N18: Giffin
A19: 01 11 26.23 | B19: HVAC | D19: LS | E19: 0 | F19: =C19*E19 -> 0 | H19: 0 | I19: =G19*H19 -> 0 | J19: =M19 -> 13200 | K19: =F19+I19+J19 -> 13200 | L19: MCW | M19: =12450+750 -> 13200
A20: 01 11 26.26 | B20: Plumbing | D20: LS | E20: 0 | F20: =C20*E20 -> 0 | H20: 0 | I20: =G20*H20 -> 0 | K20: =F20+I20+J20 -> 0
A21: 01 11 26.29 | B21: Electrical | D21: LS | E21: 0 | F21: =C21*E21 -> 0 | H21: 0 | I21: =G21*H21 -> 0 | K21: =F21+I21+J21 -> 0
A22: 01 11 26.33 | B22: Geotechnical | D22: LS | E22: 0 | F22: =C22*E22 -> 0 | H22: 0 | I22: =G22*H22 -> 0 | K22: =F22+I22+J22 -> 0
J24: Sub Total | K24: =SUM(K11:K23) -> 52700
A25: CODE | B25: DESCRIPTION | C25: Materials & Equipment | G25: Labor
A26: 01 31 00 | B26: Project Management and Coordination | C26: Qty | D26: Unit | E26: U. Price | F26: Sub Total | G26: MHrs | H26: U. Price | I26: Sub Total | J26: Quote | K26: Total
A27: 01 31 01 | B27: Senior Construction Manager | D27: LS | E27: 0 | F27: =C27*E27 -> 0 | H27: 0 | I27: =G27*H27 -> 0 | K27: =F27+I27+J27 -> 0
A28: 01 31 02 | B28: Senior Estimator | D28: LS | E28: 0 | F28: =C28*E28 -> 0 | H28: 0 | I28: =G28*H28 -> 0 | K28: =F28+I28+J28 -> 0
A29: 01 31 03 | B29: Senior Project Manager | C29: =J6 -> 13 | D29: LS | E29: 0 | F29: =C29*E29 -> 0 | G29: 10 | H29: 100 | I29: =H29*G29*C29 -> 13000 | K29: =F29+I29+J29 -> 13000
A30: 01 31 04 | B30: Project Coordinator | C30: =J6 -> 13 | D30: LS | E30: 0 | F30: =C30*E30 -> 0 | H30: 75 | I30: =H30*G30*C30 -> 0 | K30: =F30+I30+J30 -> 0
A31: 01 31 05 | B31: Project Superintendent | C31: =J6 -> 13 | D31: LS | E31: 0 | F31: =C31*E31 -> 0 | G31: 40 | H31: 85 | I31: =H31*G31*C31 -> 44200 | K31: =F31+I31+J31 -> 44200
A32: 01 31 06 | B32: Project Foreman | D32: LS | E32: 0 | F32: =C32*E32 -> 0 | H32: 0 | I32: =G32*H32 -> 0 | K32: =F32+I32+J32 -> 0
D33: LS | E33: 0 | F33: =C33*E33 -> 0 | H33: 0 | I33: =G33*H33 -> 0 | K33: =F33+I33+J33 -> 0
K34: =F34+I34+J34 -> 0
J35: Sub Total | K35: =SUM(K27:K34) -> 57200
A36: CODE | B36: DESCRIPTION
A37: 01 32 00 | B37: Insurance | D37: /$1000 | E37: Cost | F37: Rate | G37: Toll Cost | H37: Frequency | J37: Sub Total | K37: Total
A38: 01 32 01 | B38: General Liability & Contractor's Pollution Liability | C38: =SUM('Estimate Summary'!H17:H61)/1000 -> 598.98224 | D38: /$1000 | E38: 0.63 | F38: =C38*E38 -> 377.35881 | K38: =F38 -> 377.35881
B39: Contractor's Pollution Liability | C39: =SUM('Estimate Summary'!H17:H61)/1000 -> 598.98224 | D39: /$1000 | E39: 1.29 | F39: =C39*E39 -> 772.68709 | K39: =F39 -> 772.68709
B40: Builders Risk | C40: =+J6/4.5 -> 2.8888889 | D40: $1000/month | E40: 0.75 | K40: =F40 -> 0
B41: Wrap-up Liability | C41: =SUM('Estimate Summary'!H17:H61)/1000 -> 598.98224 | D41: /$1000 | E41: 1.88 | K41: =F41 -> 0
A45: 01 32 00 | J45: Sub Total | K45: =SUM(K38:K44) -> 1150.0459
A46: CODE | B46: DESCRIPTION | C46: Materials & Equipment | G46: Labor
A47: CODE | B47: DESCRIPTION
A48: 01 32 00 | B48: Travel | C48: Frequency | D48: Weeks | E48: Distance (Round Trip) | F48: Rate | G48: Toll Cost | H48: Frequency | J48: Sub Total | K48: Total
B49: PM KM | D49: =J6 -> 13 | E49: 0 | F49: 0.45 | H49: =C49*D49 -> 0 | J49: =C49*D49*E49*F49+G49*H49 -> 0 | K49: =J49+(G49*H49) -> 0
...

Sheet 2
C1: ='Estimate Summary'!C1:H1 -> 0
G5: Existing Conditions | J5: Schedule
D6: ='Estimate Summary'!C11 -> Area: | E6: ='Estimate Summary'!D11 -> 1747 | F6: ='Estimate Summary'!E11 -> Sq. Ft. | J6: ='1'!J6 -> 13 | K6: Weeks
A11: CODE | B11: DESCRIPTION | C11: Materials & Equipment | G11: Labor | L11: Sub Contractor | M11: Quote Total | N11: Additional Quote Info
A12: 02 00 00 | B12: Existing Conditions | C12: Qty | D12: Unit | E12: U. Price | F12: Sub Total | G12: MHrs | H12: U. Price | I12: Sub Total | J12: Quote | K12: Total
A13: 02 41 00 | B13: Demolition | C13: =E6 -> 1747 | D13: SF | E13: 5 | F13: 0 | H13: 0 | I13: =G13*H13 -> 0 | J13: =M13 -> 10086 | K13: =F13+I13+J13 -> 10086 | L13: Branco | M13: 10086 | N13: Duct demo has been removed
D14: LS | E14: 0 | F14: =C14*E14 -> 0 | H14: 0 | I14: =G14*H14 -> 0 | K14: =F14+I14+J14 -> 0 | L14: Branco | M14: 150 | N14: per hole
B15: Additional 18 holes | D15: LS | E15: 0 | F15: =C15*E15 -> 0 | H15: 0 | I15: =G15*H15 -> 0 | J15: =M14*38 -> 5700 | K15: =F15+I15+J15 -> 5700 | L15: Branco | M15: =M14*38 -> 5700
D16: LS | E16: 0 | F16: =C16*E16 -> 0 | H16: 0 | I16: =G16*H16 -> 0 | K16: =F16+I16+J16 -> 0 | L16: Enviro | M16: 15900
D17: LS | E17: 0 | F17: =C17*E17 -> 0 | H17: 0 | I17: =G17*H17 -> 0 | K17: =F17+I17+J17 -> 0 | L17: Enviro | M17: 100 | N17: per hole
D18: LS | E18: 0 | F18: =C18*E18 -> 0 | H18: 0 | I18: =G18*H18 -> 0 | K18: =F18+I18+J18 -> 0 | L18: Inflector | M18: 15230
D19: LS | E19: 0 | F19: =C19*E19 -> 0 | H19: 0 | I19: =G19*H19 -> 0 | K19: =F19+I19+J19 -> 0
D20: LS | E20: 0 | F20: =C20*E20 -> 0 | H20: 0 | I20: =G20*H20 -> 0 | K20: =F20+I20+J20 -> 0 | L20: Mountain View Dental | M20: 11.94
D21: LS | E21: 0 | F21: =C21*E21 -> 0 | H21: 0 | I21: =G21*H21 -> 0 | K21: =F21+I21+J21 -> 0
D22: LS | E22: 0 | F22: =C22*E22 -> 0 | H22: 0 | I22: =G22*H22 -> 0 | K22: =F22+I22+J22 -> 0
D23: LS | E23: 0 | F23: =C23*E23 -> 0 | H23: 0 | I23: =G23*H23 -> 0 | K23: =F23+I23+J23 -> 0 | M23: =17286-K26 -> 1500
D24: LS | E24: 0 | F24: =C24*E24 -> 0 | H24: 0 | I24: =G24*H24 -> 0 | K24: =F24+I24+J24 -> 0
J26: Sub Total | K26: =SUM(K13:K25) -> 15786
A27: CODE | B27: DESCRIPTION | C27: Materials & Equipment | G27: Labor
A28: 02 82 00 | B28: Asbestos Remediation | C28: Qty | D28: Unit | E28: U. Price | F28: Sub Total | G28: MHrs | H28: U. Price | I28: Sub Total | J28: Quote | K28: Total
D29: LS | E29: 0 | F29: =C29*E29 -> 0 | H29: 0 | I29: =G29*H29 -> 0 | K29: =F29+I29+J29 -> 0
D30: LS | E30: 0 | F30: =C30*E30 -> 0 | H30: 0 | I30: =G30*H30 -> 0 | K30: =F30+I30+J30 -> 0
D31: LS | E31: 0 | F31: =C31*E31 -> 0 | H31: 0 | I31: =G31*H31 -> 0 | K31: =F31+I31+J31 -> 0
D32: LS | E32: 0 | F32: =C32*E32 -> 0 | H32: 0 | I32: =G32*H32 -> 0 | K32: =F32+I32+J32 -> 0
D33: LS | E33: 0 | F33: =C33*E33 -> 0 | H33: 0 | I33: =G33*H33 -> 0 | K33: =F33+I33+J33 -> 0
D34: LS | E34: 0 | F34: =C34*E34 -> 0 | H34: 0 | I34: =G34*H34 -> 0 | K34: =F34+I34+J34 -> 0
D35: LS | E35: 0 | F35: =C35*E35 -> 0 | H35: 0 | I35: =G35*H35 -> 0 | K35: =F35+I35+J35 -> 0
J37: Sub Total | K37: =SUM(K29:K36) -> 0
A38: CODE | B38: DESCRIPTION | C38: Materials & Equipment | G38: Labor
A39: 02 83 00 | B39: Trenching | C39: Qty | D39: Unit | E39: U. Price | F39: Sub Total | G39: MHrs | H39: U. Price | I39: Sub Total | J39: Quote | K39: Total
D40: LS | E40: 0 | F40: =C40*E40 -> 0 | H40: 0 | I40: =G40*H40 -> 0 | K40: =F40+I40+J40 -> 0
B41: Sanitary Trenching | D41: ft | E41: 95 | F41: =C41*E41 -> 0 | H41: 0 | I41: =G41*H41 -> 0 | K41: =F41+I41+J41 -> 0
D42: LS | E42: 0 | F42: =C42*E42 -> 0 | H42: 0 | I42: =G42*H42 -> 0 | K42: =F42+I42+J42 -> 0
B43: Core Drilling | C43: 24 | D43: EA | E43: 120 | F43: 0 | H43: 0 | I43: =G43*H43 -> 0 | K43: =F43+I43+J43 -> 0
B44: X Ray Allowance | C44: 1 | D44: LS | E44: 1500 | F44: =C44*E44 -> 1500 | H44: 0 | I44: =G44*H44 -> 0 | K44: =F44+I44+J44 -> 1500
D45: LS | E45: 0 | F45: =C45*E45 -> 0 | H45: 0 | I45: =G45*H45 -> 0 | K45: =F45+I45+J45 -> 0
D46: LS | E46: 0 | F46: =C46*E46 -> 0 | H46: 0 | I46: =G46*H46 -> 0 | K46: =F46+I46+J46 -> 0
J48: Sub Total | K48: =SUM(K40:K47) -> 1500
F49: Material Total | G49: Total Hours | I49: Labor Total | J49: Contractor Total | K49: TOTAL
A50: $ / Sq.Ft | B50: TOTAL DIVISION 2
...

Sheet 3
C1: ='Estimate Summary'!C1:H1 -> 0
G5: Concrete | J5: Schedule
D6: ='Estimate Summary'!C11 -> Area: | E6: ='Estimate Summary'!D11 -> 1747 | F6: ='Estimate Summary'!E11 -> Sq. Ft. | J6: ='1'!J6 -> 13 | K6: Weeks
A11: CODE | B11: DESCRIPTION | C11: Materials & Equipment | G11: Labor | L11: Sub Contractor | M11: Quote Total | N11: Additional Quote Info
A12: 03 11 00 | B12: Concrete Forming | C12: Qty | D12: Unit | E12: U. Price | F12: Sub Total | G12: MHrs | H12: U. Price | I12: Sub Total | J12: Quote | K12: Total
A13: 03 11 01 | B13: Contractor Quote | K13: =F13+I13+J13 -> 0
A14: 03 11 02.1 | B14: Footings | D14: ft | E14: 25 | F14: =C14*E14 -> 0 | H14: 0 | I14: =G14*H14 -> 0 | K14: =F14+I14+J14 -> 0
A15: 03 11 02.2 | B15: Walls | D15: ft | E15: 45 | F15: =C15*E15 -> 0 | H15: 0 | I15: =G15*H15 -> 0 | K15: =F15+I15+J15 -> 0
A16: 03 11 02.3 | B16: Piers | D16: ea | E16: 150 | F16: =C16*E16 -> 0 | H16: 0 | I16: =G16*H16 -> 0 | K16: =F16+I16+J16 -> 0
D17: LS | E17: 0 | F17: =C17*E17 -> 0 | H17: 0 | I17: =G17*H17 -> 0 | K17: =F17+I17+J17 -> 0
D18: LS | E18: 0 | F18: =C18*E18 -> 0 | H18: 0 | I18: =G18*H18 -> 0 | K18: =F18+I18+J18 -> 0
D19: LS | E19: 0 | F19: =C19*E19 -> 0 | H19: 0 | I19: =G19*H19 -> 0 | K19: =F19+I19+J19 -> 0
D20: LS | E20: 0 | F20: =C20*E20 -> 0 | H20: 0 | I20: =G20*H20 -> 0 | K20: =F20+I20+J20 -> 0
J26: Sub Total | K26: =SUM(K13:K25) -> 0
A27: CODE | B27: DESCRIPTION | C27: Materials & Equipment | G27: Labor
A28: 03 20 00 | B28: Concrete Reinforcing | C28: Qty | D28: Unit | E28: U. Price | F28: Sub Total | G28: MHrs | H28: U. Price | I28: Sub Total | J28: Quote | K28: Total
A29: 03 20 01 | B29: Contractor Quote | K29: =F29+I29+J29 -> 0 | T29: Type | U29: Width | W29: Height
A30: 03 20 02 | B30: Rebar | D30: LS | E30: 0 | F30: =C30*E30 -> 0 | H30: 0 | I30: =G30*H30 -> 0 | K30: =F30+I30+J30 -> 0 | U30: A | V30: B | W30: D | X30: Quantity | Y30: Volume m3
A31: 03 20 03 | B31: Mesh | D31: LS | E31: 0 | F31: =C31*E31 -> 0 | H31: 0 | I31: =G31*H31 -> 0 | K31: =F31+I31+J31 -> 0 | S31: Footings | T31: 1 | Y31: =U31*V31*W31*0.0000163871*X31 -> 0
D32: LS | E32: 0 | F32: =C32*E32 -> 0 | H32: 0 | I32: =G32*H32 -> 0 | K32: =F32+I32+J32 -> 0 | T32: 2 | Y32: =U32*V32*W32*0.0000163871*X32 -> 0
D33: LS | E33: 0 | F33: =C33*E33 -> 0 | H33: 0 | I33: =G33*H33 -> 0 | K33: =F33+I33+J33 -> 0 | U33: Length (FT) | V33: Width (ft) | W33: Height (ft)
D34: LS | E34: 0 | F34: =C34*E34 -> 0 | H34: 0 | I34: =G34*H34 -> 0 | K34: =F34+I34+J34 -> 0 | S34: Strip Footing | Y34: =U34*V34*W34*0.028 -> 0
D35: LS | E35: 0 | F35: =C35*E35 -> 0 | H35: 0 | I35: =G35*H35 -> 0 | K35: =F35+I35+J35 -> 0 | S35: Walls | Y35: =U35*V35*W35*0.028 -> 0
S36: Piers | Y36: =U36*V36*W36*0.028*X36 -> 0
J37: Sub Total | K37: =SUM(K29:K36) -> 0 | U37: Area (SF) | W37: Thickness (ft)
A38: CODE | B38: DESCRIPTION | C38: Materials & Equipment | G38: Labor | S38: Slab - ground floor | Y38: =U38*W38*0.028 -> 0
A39: 03 30 00 | B39: Cast-in-Place Concrete | C39: Qty | D39: Unit | E39: U. Price | F39: Sub Total | G39: MHrs | H39: U. Price | I39: Sub Total | J39: Quote | K39: Total | S39: Slab - 2nd floor | Y39: =U39*W39*0.028 -> 0
A40: 03 30 01 | B40: Slab Volume | C40: =Y44 -> 0 | D40: m3 | E40: 0 | F40: =C40*E40 -> 0 | H40: 0 | I40: =G40*H40 -> 0 | K40: =F40+I40+J40 -> 0
A41: 03 30 02 | B41: Footing Volume | C41: =Y45 -> 0 | D41: m3 | E41: 0 | F41: =C41*E41 -> 0 | H41: 0 | I41: =G41*H41 -> 0 | K41: =F41+I41+J41 -> 0 | S41: Exterior Pads | Y41: =U41*W41*0.028 -> 0
A42: 03 30 03 | B42: Foundation Wall Volume | C42: =Y46 -> 0 | D42: m3 | E42: 0 | F42: =C42*E42 -> 0 | H42: 0 | I42: =G42*H42 -> 0 | K42: =F42+I42+J42 -> 0
A43: 03 30 04 | B43: Exterior Concrete Volume | C43: =Y47 -> 0 | D43: m3 | E43: 0 | F43: =C43*E43 -> 0 | H43: 0 | I43: =G43*H43 -> 0 | K43: =F43+I43+J43 -> 0
D44: LS | E44: 0 | F44: =C44*E44 -> 0 | H44: 0 | I44: =G44*H44 -> 0 | K44: =F44+I44+J44 -> 0 | W44: Total Volume - Slab | Y44: =Y38+Y39 -> 0
A45: 03 30 04 | B45: Pump | C45: =SUM(C40:C43) -> 0 | D45: m3 | E45: 3 | F45: =C45*E45 -> 0 | H45: 0 | I45: =G45*H45 -> 0 | K45: =F45+I45+J45 -> 0 | W45: Total Volume - Footing | Y45: =Y31+Y32+Y34 -> 0
J46: Sub Total | K46: =SUM(K40:K45) -> 0 | W46: Total Volume - Walls | Y46: =Y35+Y36 -> 0
A47: CODE | B47: DESCRIPTION | C47: Materials & Equipment | G47: Labor | W47: Total Volume - Exterior | Y47: =Y41 -> 0
A48: 03 35 00 | B48: Concrete Finishing | C48: Qty | D48: Unit | E48: U. Price | F48: Sub Total | G48: MHrs | H48: U. Price | I48: Sub Total | J48: Quote | K48: Total
D49: LS | E49: 0 | F49: =C49*E49 -> 0 | H49: 0 | I49: =G49*H49 -> 0 | K49: =F49+I49+J49 -> 0
B50: Slab Finishing - Ground Floor | C50: =U38 -> 0 | D50: sf | E50: 1 | F50: =C50*E50 -> 0 | H50: 0 | I50: =G50*H50 -> 0 | K50: =F50+I50+J50 -> 0
B51: Slab Finishing - 2nd Floor | C51: =U39 -> 0 | D51: sf | E51: 1 | F51: =C51*E51 -> 0 | H51: 0 | I51: =G51*H51 -> 0 | K51: =F51+I51+J51 -> 0
D52: LS | E52: 0 | F52: =C52*E52 -> 0 | H52: 0 | I52: =G52*H52 -> 0 | K52: =F52+I52+J52 -> 0
...

Sheet 4
C1: ='Estimate Summary'!C1:H1 -> 0
G5: Masonry | J5: Schedule
D6: ='Estimate Summary'!C11 -> Area: | E6: ='Estimate Summary'!D11 -> 1747 | F6: ='Estimate Summary'!E11 -> Sq. Ft. | J6: ='1'!J6 -> 13 | K6: Weeks
A11: CODE | B11: DESCRIPTION | C11: Materials & Equipment | G11: Labor | L11: Sub Contractor | M11: Quote Total | N11: Additional Quote Info
A12: 04 20 00 | B12: Unit Masonry | C12: Qty | D12: Unit | E12: U. Price | F12: Sub Total | G12: MHrs | H12: U. Price | I12: Sub Total | J12: Quote | K12: Total
D13: LS | E13: 0 | F13: =C13*E13 -> 0 | H13: 0 | I13: =G13*H13 -> 0 | K13: =F13+I13+J13 -> 0
D14: LS | E14: 0 | F14: =C14*E14 -> 0 | H14: 0 | I14: =G14*H14 -> 0 | K14: =F14+I14+J14 -> 0
D15: LS | E15: 0 | F15: =C15*E15 -> 0 | H15: 0 | I15: =G15*H15 -> 0 | K15: =F15+I15+J15 -> 0
D16: LS | E16: 0 | F16: =C16*E16 -> 0 | H16: 0 | I16: =G16*H16 -> 0 | K16: =F16+I16+J16 -> 0
D17: LS | E17: 0 | F17: =C17*E17 -> 0 | H17: 0 | I17: =G17*H17 -> 0 | K17: =F17+I17+J17 -> 0
D18: LS | E18: 0 | F18: =C18*E18 -> 0 | H18: 0 | I18: =G18*H18 -> 0 | K18: =F18+I18+J18 -> 0
D19: LS | E19: 0 | F19: =C19*E19 -> 0 | H19: 0 | I19: =G19*H19 -> 0 | K19: =F19+I19+J19 -> 0
D20: LS | E20: 0 | F20: =C20*E20 -> 0 | H20: 0 | I20: =G20*H20 -> 0 | K20: =F20+I20+J20 -> 0
D21: LS | E21: 0 | F21: =C21*E21 -> 0 | H21: 0 | I21: =G21*H21 -> 0 | K21: =F21+I21+J21 -> 0
D22: LS | E22: 0 | F22: =C22*E22 -> 0 | H22: 0 | I22: =G22*H22 -> 0 | K22: =F22+I22+J22 -> 0
D23: LS | E23: 0 | F23: =C23*E23 -> 0 | H23: 0 | I23: =G23*H23 -> 0 | K23: =F23+I23+J23 -> 0
D24: LS | E24: 0 | F24: =C24*E24 -> 0 | H24: 0 | I24: =G24*H24 -> 0 | K24: =F24+I24+J24 -> 0
J26: Sub Total | K26: =SUM(K13:K25) -> 0
A27: CODE | B27: DESCRIPTION | C27: Materials & Equipment | G27: Labor
A28: 04 43 00 | B28: Stone Masonry | C28: Qty | D28: Unit | E28: U. Price | F28: Sub Total | G28: MHrs | H28: U. Price | I28: Sub Total | J28: Quote | K28: Total
D29: LS | E29: 0 | F29: =C29*E29 -> 0 | H29: 0 | I29: =G29*H29 -> 0 | K29: =F29+I29+J29 -> 0
D30: LS | E30: 0 | F30: =C30*E30 -> 0 | H30: 0 | I30: =G30*H30 -> 0 | K30: =F30+I30+J30 -> 0
D31: LS | E31: 0 | F31: =C31*E31 -> 0 | H31: 0 | I31: =G31*H31 -> 0 | K31: =F31+I31+J31 -> 0
D32: LS | E32: 0 | F32: =C32*E32 -> 0 | H32: 0 | I32: =G32*H32 -> 0 | K32: =F32+I32+J32 -> 0
D33: LS | E33: 0 | F33: =C33*E33 -> 0 | H33: 0 | I33: =G33*H33 -> 0 | K33: =F33+I33+J33 -> 0
D34: LS | E34: 0 | F34: =C34*E34 -> 0 | H34: 0 | I34: =G34*H34 -> 0 | K34: =F34+I34+J34 -> 0
D35: LS | E35: 0 | F35: =C35*E35 -> 0 | H35: 0 | I35: =G35*H35 -> 0 | K35: =F35+I35+J35 -> 0
J37: Sub Total | K37: =SUM(K29:K36) -> 0
A38: CODE | B38: DESCRIPTION | C38: Materials & Equipment | G38: Labor
C39: Qty | D39: Unit | E39: U. Price | F39: Sub Total | G39: MHrs | H39: U. Price | I39: Sub Total | J39: Quote | K39: Total
D40: LS | E40: 0 | F40: =C40*E40 -> 0 | H40: 0 | I40: =G40*H40 -> 0 | K40: =F40+I40+J40 -> 0
D41: LS | E41: 0 | F41: =C41*E41 -> 0 | H41: 0 | I41: =G41*H41 -> 0 | K41: =F41+I41+J41 -> 0
D42: LS | E42: 0 | F42: =C42*E42 -> 0 | H42: 0 | I42: =G42*H42 -> 0 | K42: =F42+I42+J42 -> 0
J45: Sub Total | K45: =SUM(K40:K44) -> 0
A46: CODE | B46: DESCRIPTION | C46: Materials & Equipment | G46: Labor
C47: Qty | D47: Unit | E47: U. Price | F47: Sub Total | G47: MHrs | H47: U. Price | I47: Sub Total | J47: Quote | K47: Total
D48: LS | E48: 0 | F48: =C48*E48 -> 0 | H48: 0 | I48: =G48*H48 -> 0 | K48: =F48+I48+J48 -> 0
D49: LS | E49: 0 | F49: =C49*E49 -> 0 | H49: 0 | I49: =G49*H49 -> 0 | K49: =F49+I49+J49 -> 0
D50: LS | E50: 0 | F50: =C50*E50 -> 0 | H50: 0 | I50: =G50*H50 -> 0 | K50: =F50+I50+J50 -> 0
D51: LS | E51: 0 | F51: =C51*E51 -> 0 | H51: 0 | I51: =G51*H51 -> 0 | K51: =F51+I51+J51 -> 0
...

Sheet 5
C1: ='Estimate Summary'!C1:H1 -> 0
G5: Metals | J5: Schedule
D6: ='Estimate Summary'!C11 -> Area: | E6: ='Estimate Summary'!D11 -> 1747 | F6: ='Estimate Summary'!E11 -> Sq. Ft. | J6: ='1'!J6 -> 13 | K6: Weeks
A11: CODE | B11: DESCRIPTION | C11: Materials & Equipment | G11: Labor | L11: Sub Contractor | M11: Quote Total | N11: Additional Quote Info
A12: 05 12 00 | B12: Structural Steel Framing | C12: Qty | D12: Unit | E12: U. Price | F12: Sub Total | G12: MHrs | H12: U. Price | I12: Sub Total | J12: Quote | K12: Total
D13: LS | E13: 0 | F13: =C13*E13 -> 0 | H13: 0 | I13: =G13*H13 -> 0 | K13: =F13+I13+J13 -> 0
D14: LS | E14: 0 | F14: =C14*E14 -> 0 | H14: 0 | I14: =G14*H14 -> 0 | K14: =F14+I14+J14 -> 0
D15: LS | E15: 0 | F15: =C15*E15 -> 0 | H15: 0 | I15: =G15*H15 -> 0 | K15: =F15+I15+J15 -> 0
D16: LS | E16: 0 | F16: =C16*E16 -> 0 | H16: 0 | I16: =G16*H16 -> 0 | K16: =F16+I16+J16 -> 0
D17: LS | E17: 0 | F17: =C17*E17 -> 0 | H17: 0 | I17: =G17*H17 -> 0 | K17: =F17+I17+J17 -> 0
D18: LS | E18: 0 | F18: =C18*E18 -> 0 | H18: 0 | I18: =G18*H18 -> 0 | K18: =F18+I18+J18 -> 0
D19: LS | E19: 0 | F19: =C19*E19 -> 0 | H19: 0 | I19: =G19*H19 -> 0 | K19: =F19+I19+J19 -> 0
D20: LS | E20: 0 | F20: =C20*E20 -> 0 | H20: 0 | I20: =G20*H20 -> 0 | K20: =F20+I20+J20 -> 0
D21: LS | E21: 0 | F21: =C21*E21 -> 0 | H21: 0 | I21: =G21*H21 -> 0 | K21: =F21+I21+J21 -> 0
D22: LS | E22: 0 | F22: =C22*E22 -> 0 | H22: 0 | I22: =G22*H22 -> 0 | K22: =F22+I22+J22 -> 0
D23: LS | E23: 0 | F23: =C23*E23 -> 0 | H23: 0 | I23: =G23*H23 -> 0 | K23: =F23+I23+J23 -> 0
D24: LS | E24: 0 | F24: =C24*E24 -> 0 | H24: 0 | I24: =G24*H24 -> 0 | K24: =F24+I24+J24 -> 0
J26: Sub Total | K26: =SUM(K13:K25) -> 0
A27: CODE | B27: DESCRIPTION | C27: Materials & Equipment | G27: Labor
A28: 05 20 00 | B28: Metal Joists | C28: Qty | D28: Unit | E28: U. Price | F28: Sub Total | G28: MHrs | H28: U. Price | I28: Sub Total | J28: Quote | K28: Total
D29: LS | E29: 0 | F29: =C29*E29 -> 0 | H29: 0 | I29: =G29*H29 -> 0 | K29: =F29+I29+J29 -> 0
D30: LS | E30: 0 | F30: =C30*E30 -> 0 | H30: 0 | I30: =G30*H30 -> 0 | K30: =F30+I30+J30 -> 0
D31: LS | E31: 0 | F31: =C31*E31 -> 0 | H31: 0 | I31: =G31*H31 -> 0 | K31: =F31+I31+J31 -> 0
D32: LS | E32: 0 | F32: =C32*E32 -> 0 | H32: 0 | I32: =G32*H32 -> 0 | K32: =F32+I32+J32 -> 0
D33: LS | E33: 0 | F33: =C33*E33 -> 0 | H33: 0 | I33: =G33*H33 -> 0 | K33: =F33+I33+J33 -> 0
D34: LS | E34: 0 | F34: =C34*E34 -> 0 | H34: 0 | I34: =G34*H34 -> 0 | K34: =F34+I34+J34 -> 0
D35: LS | E35: 0 | F35: =C35*E35 -> 0 | H35: 0 | I35: =G35*H35 -> 0 | K35: =F35+I35+J35 -> 0
J37: Sub Total | K37: =SUM(K29:K36) -> 0
A38: CODE | B38: DESCRIPTION | C38: Materials & Equipment | G38: Labor
A39: 05 30 00 | B39: Metal Decking | C39: Qty | D39: Unit | E39: U. Price | F39: Sub Total | G39: MHrs | H39: U. Price | I39: Sub Total | J39: Quote | K39: Total
D40: LS | E40: 0 | F40: =C40*E40 -> 0 | H40: 0 | I40: =G40*H40 -> 0 | K40: =F40+I40+J40 -> 0
D41: LS | E41: 0 | F41: =C41*E41 -> 0 | H41: 0 | I41: =G41*H41 -> 0 | K41: =F41+I41+J41 -> 0
D42: LS | E42: 0 | F42: =C42*E42 -> 0 | H42: 0 | I42: =G42*H42 -> 0 | K42: =F42+I42+J42 -> 0
J45: Sub Total | K45: =SUM(K40:K44) -> 0
A46: CODE | B46: DESCRIPTION | C46: Materials & Equipment | G46: Labor
A47: 05 51 00 | B47: Metal Stairs | C47: Qty | D47: Unit | E47: U. Price | F47: Sub Total | G47: MHrs | H47: U. Price | I47: Sub Total | J47: Quote | K47: Total
D48: LS | E48: 0 | F48: =C48*E48 -> 0 | H48: 0 | I48: =G48*H48 -> 0 | K48: =F48+I48+J48 -> 0
D49: LS | E49: 0 | F49: =C49*E49 -> 0 | H49: 0 | I49: =G49*H49 -> 0 | K49: =F49+I49+J49 -> 0
D50: LS | E50: 0 | F50: =C50*E50 -> 0 | H50: 0 | I50: =G50*H50 -> 0 | K50: =F50+I50+J50 -> 0
D51: LS | E51: 0 | F51: =C51*E51 -> 0 | H51: 0 | I51: =G51*H51 -> 0 | K51: =F51+I51+J51 -> 0
...

Sheet 6
C1: ='Estimate Summary'!C1:H1 -> 0
G5: Wood & Plastics | J5: Schedule
D6: ='Estimate Summary'!C11 -> Area: | E6: ='Estimate Summary'!D11 -> 1747 | F6: ='Estimate Summary'!E11 -> Sq. Ft. | J6: ='1'!J6 -> 13 | K6: Weeks
A9: CODE | B9: DESCRIPTION | C9: Materials & Equipment | G9: Labor | L9: Sub Contractor | M9: Quote Total | N9: Additional Quote Info
A10: 06 11 00 | B10: Framing Labour | C10: Qty | D10: Unit | E10: U. Price | F10: Sub Total | G10: MHrs | H10: U. Price | I10: Sub Total | J10: Quote | K10: Total
H11: 0 | I11: =G11*H11 -> 0 | K11: =F11+I11+J11 -> 0
G12: 20 | H12: 65 | I12: =G12*H12 -> 1300 | K12: =F12+I12+J12 -> 1300
H13: 0 | I13: =G13*H13 -> 0 | K13: =F13+I13+J13 -> 0
H14: 0 | I14: =G14*H14 -> 0 | K14: =F14+I14+J14 -> 0
H15: 0 | I15: =G15*H15 -> 0 | K15: =F15+I15+J15 -> 0
H16: 0 | I16: =G16*H16 -> 0 | K16: =F16+I16+J16 -> 0
H17: 0 | I17: =G17*H17 -> 0 | K17: =F17+I17+J17 -> 0
J19: Sub Total | K19: =SUM(K11:K18) -> 1300
A20: 06 20 00 | B20: Framing Materials | C20: Qty | D20: Unit | E20: U. Price | F20: Sub Total | J20: Quote | K20: Total
B22: 2x4 Stud (utility room stacked equipment) | C22: 32 | D22: ft | E22: 0.61 | F22: =C22*E22 -> 19.52 | K22: =F22+I22+J22 -> 19.52
B23: 2x6 Stud | D23: ft | E23: 0.81 | F23: =C23*E23 -> 0 | K23: =F23+I23+J23 -> 0
B24: 4x4 (utility room stacked equipment) | C24: 15 | D24: ft | E24: 1.24 | F24: =C24*E24 -> 18.6 | K24: =F24+I24+J24 -> 18.6
B25: 2x10 | D25: ft | E25: 1.61 | F25: =C25*E25 -> 0 | K25: =F25+I25+J25 -> 0
B26: 1x3 | D26: ft | E26: 0.25 | F26: =C26*E26 -> 0 | K26: =F26+I26+J26 -> 0
B27: 1x4 | D27: ft | E27: 0.37 | F27: =C27*E27 -> 0 | K27: =F27+I27+J27 -> 0
B28: PLYWOOD | K28: =F28+I28+J28 -> 0
B29: 1/2" Standard | D29: EA | E29: 66.98 | F29: =C29*E29 -> 0 | K29: =F29+I29+J29 -> 0
B30: 5/8" Standard | D30: EA | E30: 43.69 | F30: =C30*E30 -> 0 | K30: =F30+I30+J30 -> 0
B31: 3/4" Standard | C31: 16 | D31: EA | E31: 87.98 | F31: =C31*E31 -> 1407.68 | K31: =F31+I31+J31 -> 1407.68
B32: Fasteners and consumables | C32: 1 | D32: LS | E32: 550 | F32: =C32*E32 -> 550 | K32: =F32+I32+J32 -> 550
B33: 5/8" OSB T&G | D33: EA | E33: 22.74 | F33: =C33*E33 -> 0 | K33: =F33+I33+J33 -> 0
J36: Sub Total | K36: =SUM(K21:K35) -> 1995.8
A37: CODE | B37: DESCRIPTION | C37: Materials & Equipment | G37: Labor
A38: 06 22 00 | B38: Millwork | C38: Qty | D38: Unit | E38: U. Price | F38: Sub Total | G38: MHrs | H38: U. Price | I38: Sub Total | J38: Quote | K38: Total
B39: Reception Desk | C39: 23 | D39: LF | E39: 400 | F39: 0 | H39: 0 | I39: =G39*H39 -> 0 | J39: =M39 -> 180875 | K39: =F39+I39+J39 -> 180875 | L39: Foxwoods | M39: 180875 | N39: Stainless steel counter included
B40: Hygene Rooms | C40: =15+14+14 -> 43 | D40: LF | E40: 400 | F40: 0 | H40: 0 | I40: =G40*H40 -> 0 | K40: =F40+I40+J40 -> 0 | L40: Foxwoods | M40: 164700 | N40: Alternate spec
B41: Lab & Storage | C41: 20 | D41: LF | E41: 400 | F41: 0 | H41: 0 | I41: =G41*H41 -> 0 | K41: =F41+I41+J41 -> 0 | L41: Lux KBS | M41: 315000
B42: Staff Room | C42: 8 | D42: LF | E42: 400 | F42: 0 | H42: 0 | I42: =G42*H42 -> 0 | K42: =F42+I42+J42 -> 0 | L42: Lux KBS | M42: 254000 | N42: Revised
B43: Workstations | C43: 17 | D43: LF | E43: 400 | F43: 0 | H43: 0 | I43: =G43*H43 -> 0 | K43: =F43+I43+J43 -> 0 | L43: Procase | N43: To send quote this week
B44: Sterilization | C44: 14 | D44: LF | E44: 400 | F44: 0 | H44: 0 | I44: =G44*H44 -> 0 | K44: =F44+I44+J44 -> 0
B45: OP Rooms | C45: =13+15+13+12 -> 53 | D45: LF | E45: 400 | F45: 0 | H45: 0 | I45: =G45*H45 -> 0 | K45: =F45+I45+J45 -> 0
B46: Washrooms | C46: 9 | D46: LF | E46: 400 | F46: 0 | H46: 0 | I46: =G46*H46 -> 0 | K46: =F46+I46+J46 -> 0
B47: Imaging | C47: 3 | D47: LF | E47: 400 | F47: 0 | H47: 0 | I47: =G47*H47 -> 0 | K47: =F47+I47+J47 -> 0
B48: Sterilization | D48: LF | E48: 0 | F48: =C48*E48 -> 0 | H48: 0 | I48: =G48*H48 -> 0 | K48: =F48+I48+J48 -> 0
D49: LS | E49: 0 | F49: =C49*E49 -> 0 | H49: 0 | I49: =G49*H49 -> 0 | K49: =F49+I49+J49 -> 0 | L49: Mountain view Dental | M49: 128488.12 | N49: 2052sf
...

Sheet 7
C1: ='Estimate Summary'!C1:H1 -> 0
G5: Thermal & Moisture Protection | J5: Schedule
D6: ='Estimate Summary'!C11 -> Area: | E6: ='Estimate Summary'!D11 -> 1747 | F6: ='Estimate Summary'!E11 -> Sq. Ft. | J6: ='1'!J6 -> 13 | K6: Weeks
A9: CODE | B9: DESCRIPTION | C9: Materials & Equipment | G9: Labor | L9: Sub Contractor | M9: Quote Total | N9: Additional Quote Info
A10: 07 21 00 | B10: Thermal Insulation | C10: Qty | D10: Unit | E10: U. Price | F10: Sub Total | G10: MHrs | H10: U. Price | I10: Sub Total | J10: Quote | K10: Total
A11: 07 21 16 | B11: Blanket Insulation | D11: LS | E11: 0 | F11: =C11*E11 -> 0 | H11: 0 | I11: =G11*H11 -> 0 | K11: =F11+I11+J11 -> 0
A12: 07 21 26 | B12: Blown Insulation | D12: LS | E12: 0 | F12: =C12*E12 -> 0 | H12: 0 | I12: =G12*H12 -> 0 | K12: =F12+I12+J12 -> 0
A13: 07 21 29 | B13: Sprayed Insulation | D13: LS | E13: 0 | F13: =C13*E13 -> 0 | H13: 0 | I13: =G13*H13 -> 0 | K13: =F13+I13+J13 -> 0
D14: LS | E14: 0 | F14: =C14*E14 -> 0 | H14: 0 | I14: =G14*H14 -> 0 | K14: =F14+I14+J14 -> 0
J16: Sub Total | K16: =SUM(K11:K15) -> 0
A17: CODE | B17: DESCRIPTION | C17: Materials & Equipment | G17: Labor
A18: 07 24 00 | B18: EIFS | C18: Qty | D18: Unit | E18: U. Price | F18: Sub Total | G18: MHrs | H18: U. Price | I18: Sub Total | J18: Quote | K18: Total
D19: LS | E19: 0 | F19: =C19*E19 -> 0 | H19: 0 | I19: =G19*H19 -> 0 | K19: =F19+I19+J19 -> 0
D20: LS | E20: 0 | F20: =C20*E20 -> 0 | H20: 0 | I20: =G20*H20 -> 0 | K20: =F20+I20+J20 -> 0
D21: LS | E21: 0 | F21: =C21*E21 -> 0 | H21: 0 | I21: =G21*H21 -> 0 | K21: =F21+I21+J21 -> 0
J22: Sub Total | K22: =SUM(K19:K21) -> 0
A23: CODE | B23: DESCRIPTION | C23: Materials & Equipment | G23: Labor
A24: 07 31 00 | B24: Shingles | C24: Qty | D24: Unit | E24: U. Price | F24: Sub Total | G24: MHrs | H24: U. Price | I24: Sub Total | J24: Quote | K24: Total
D25: LS | E25: 0 | F25: =C25*E25 -> 0 | H25: 0 | I25: =G25*H25 -> 0 | K25: =F25+I25+J25 -> 0
D26: LS | E26: 0 | F26: =C26*E26 -> 0 | H26: 0 | I26: =G26*H26 -> 0 | K26: =F26+I26+J26 -> 0
J27: Sub Total | K27: =SUM(K25:K26) -> 0
A28: CODE | B28: DESCRIPTION | C28: Materials & Equipment | G28: Labor
A29: 07 42 00 | B29: Wall Panels | C29: Qty | D29: Unit | E29: U. Price | F29: Sub Total | G29: MHrs | H29: U. Price | I29: Sub Total | J29: Quote | K29: Total
D30: LS | E30: 0 | F30: =C30*E30 -> 0 | H30: 0 | I30: =G30*H30 -> 0 | K30: =F30+I30+J30 -> 0
D31: LS | E31: 0 | F31: =C31*E31 -> 0 | H31: 0 | I31: =G31*H31 -> 0 | K31: =F31+I31+J31 -> 0
D32: LS | E32: 0 | F32: =C32*E32 -> 0 | H32: 0 | I32: =G32*H32 -> 0 | K32: =F32+I32+J32 -> 0
J33: Sub Total | K33: =SUM(K30:K32) -> 0
A34: CODE | B34: DESCRIPTION | C34: Materials & Equipment | G34: Labor
A35: 07 46 00 | B35: Siding | C35: Qty | D35: Unit | E35: U. Price | F35: Sub Total | G35: MHrs | H35: U. Price | I35: Sub Total | J35: Quote | K35: Total
D36: LS | E36: 0 | F36: =C36*E36 -> 0 | H36: 0 | I36: =G36*H36 -> 0 | K36: =F36+I36+J36 -> 0
D37: LS | E37: 0 | F37: =C37*E37 -> 0 | H37: 0 | I37: =G37*H37 -> 0 | K37: =F37+I37+J37 -> 0
D38: LS | E38: 0 | F38: =C38*E38 -> 0 | H38: 0 | I38: =G38*H38 -> 0 | K38: =F38+I38+J38 -> 0
J39: Sub Total | K39: =SUM(K36:K38) -> 0
A40: CODE | B40: DESCRIPTION | C40: Materials & Equipment | G40: Labor
A41: 07 52 00 | B41: Modified Bituminous Membrane Roofing | C41: Qty | D41: Unit | E41: U. Price | F41: Sub Total | G41: MHrs | H41: U. Price | I41: Sub Total | J41: Quote | K41: Total
D42: LS | E42: 0 | F42: =C42*E42 -> 0 | H42: 0 | I42: =G42*H42 -> 0 | K42: =F42+I42+J42 -> 0
D43: LS | E43: 0 | F43: =C43*E43 -> 0 | H43: 0 | I43: =G43*H43 -> 0 | K43: =F43+I43+J43 -> 0
D44: LS | E44: 0 | F44: =C44*E44 -> 0 | H44: 0 | I44: =G44*H44 -> 0 | K44: =F44+I44+J44 -> 0
J45: Sub Total | K45: =SUM(K42:K44) -> 0
A46: CODE | B46: DESCRIPTION | C46: Materials & Equipment | G46: Labor
...

Sheet 8
C1: ='Estimate Summary'!C1:H1 -> 0
G5: Openings | J5: Schedule
D6: ='Estimate Summary'!C11 -> Area: | E6: ='Estimate Summary'!D11 -> 1747 | F6: ='Estimate Summary'!E11 -> Sq. Ft. | J6: ='1'!J6 -> 13 | K6: Weeks
A11: CODE | B11: DESCRIPTION | C11: Materials & Equipment | G11: Labor | L11: Sub Contractor | M11: Quote Total | N11: Additional Quote Info
A12: 08 11 00 | B12: Metal Doors and Frames | C12: Qty | D12: Unit | E12: U. Price | F12: Sub Total | G12: MHrs | H12: U. Price | I12: Sub Total | J12: Quote | K12: Total
A13: 08 11 13 | B13: Hollow Metal Frames and Solid Core Wood Door Swing | C13: 5 | D13: EA | E13: 1500 | F13: 0 | G13: =7*4 -> 28 | H13: 65 | I13: =G13*H13 -> 1820 | J13: =M15 -> 18665 | K13: =F13+I13+J13 -> 20485 | L13: Advantage | M13: 21000
A14: 08 11 16 | B14: Hollow Metal Frames and Solid Core Wood Pocket Door | C14: 1 | D14: EA | E14: 1000 | F14: 0 | H14: 0 | I14: =G14*H14 -> 0 | K14: =F14+I14+J14 -> 0 | L14: DCP
B15: Hollow Metal Frames and Solid Core Wood slide Door | C15: 1 | D15: EA | E15: 1200 | F15: 0 | H15: 0 | I15: =G15*H15 -> 0 | K15: =F15+I15+J15 -> 0 | L15: Coastal | M15: 18665
D16: LS | E16: 0 | F16: =C16*E16 -> 0 | H16: 0 | I16: =G16*H16 -> 0 | K16: =F16+I16+J16 -> 0
J18: Sub Total | K18: =SUM(K13:K17) -> 20485
A19: CODE | B19: DESCRIPTION | C19: Materials & Equipment | G19: Labor
A20: 08 14 00 | B20: Wood Doors | C20: Qty | D20: Unit | E20: U. Price | F20: Sub Total | G20: MHrs | H20: U. Price | I20: Sub Total | J20: Quote | K20: Total
D21: LS | E21: 0 | F21: =C21*E21 -> 0 | H21: 0 | I21: =G21*H21 -> 0 | K21: =F21+I21+J21 -> 0
D22: LS | E22: 0 | F22: =C22*E22 -> 0 | H22: 0 | I22: =G22*H22 -> 0 | K22: =F22+I22+J22 -> 0
D23: LS | E23: 0 | F23: =C23*E23 -> 0 | H23: 0 | I23: =G23*H23 -> 0 | K23: =F23+I23+J23 -> 0
J24: Sub Total | K24: =SUM(K21:K23) -> 0
A25: CODE | B25: DESCRIPTION | C25: Materials & Equipment | G25: Labor
A26: 08 31 00 | B26: Access Doors and Panels | C26: Qty | D26: Unit | E26: U. Price | F26: Sub Total | G26: MHrs | H26: U. Price | I26: Sub Total | J26: Quote | K26: Total
D27: LS | E27: 0 | F27: =C27*E27 -> 0 | H27: 0 | I27: =G27*H27 -> 0 | K27: =F27+I27+J27 -> 0
D28: LS | E28: 0 | F28: =C28*E28 -> 0 | H28: 0 | I28: =G28*H28 -> 0 | K28: =F28+I28+J28 -> 0
J29: Sub Total | K29: =SUM(K27:K28) -> 0
A30: CODE | B30: DESCRIPTION | C30: Materials & Equipment | G30: Labor
A31: 08 32 00 | B31: Sliding Gates | C31: Qty | D31: Unit | E31: U. Price | F31: Sub Total | G31: MHrs | H31: U. Price | I31: Sub Total | J31: Quote | K31: Total
D32: LS | E32: 0 | F32: =C32*E32 -> 0 | H32: 0 | I32: =G32*H32 -> 0 | K32: =F32+I32+J32 -> 0
D33: LS | E33: 0 | F33: =C33*E33 -> 0 | H33: 0 | I33: =G33*H33 -> 0 | K33: =F33+I33+J33 -> 0
D34: LS | E34: 0 | F34: =C34*E34 -> 0 | H34: 0 | I34: =G34*H34 -> 0 | K34: =F34+I34+J34 -> 0
J35: Sub Total | K35: =SUM(K32:K34) -> 0
A36: CODE | B36: DESCRIPTION | C36: Materials & Equipment | G36: Labor
A37: 08 33 00 | B37: Coiling Doors and Drilles | C37: Qty | D37: Unit | E37: U. Price | F37: Sub Total | G37: MHrs | H37: U. Price | I37: Sub Total | J37: Quote | K37: Total
D38: LS | E38: 0 | F38: =C38*E38 -> 0 | H38: 0 | I38: =G38*H38 -> 0 | K38: =F38+I38+J38 -> 0
D39: LS | E39: 0 | F39: =C39*E39 -> 0 | H39: 0 | I39: =G39*H39 -> 0 | K39: =F39+I39+J39 -> 0
D40: LS | E40: 0 | F40: =C40*E40 -> 0 | H40: 0 | I40: =G40*H40 -> 0 | K40: =F40+I40+J40 -> 0
J41: Sub Total | K41: =SUM(K38:K40) -> 0
A42: CODE | B42: DESCRIPTION | C42: Materials & Equipment | G42: Labor
A43: 08 34 00 | B43: Special Function Doors | C43: Qty | D43: Unit | E43: U. Price | F43: Sub Total | G43: MHrs | H43: U. Price | I43: Sub Total | J43: Quote | K43: Total
B44: Closet door | C44: 1 | D44: EA | E44: 900 | F44: 0 | H44: 0 | I44: =G44*H44 -> 0 | K44: =F44+I44+J44 -> 0
D45: LS | E45: 0 | F45: =C45*E45 -> 0 | H45: 0 | I45: =G45*H45 -> 0 | K45: =F45+I45+J45 -> 0
D46: LS | E46: 0 | F46: =C46*E46 -> 0 | H46: 0 | I46: =G46*H46 -> 0 | K46: =F46+I46+J46 -> 0
J47: Sub Total | K47: =SUM(K44:K46) -> 0
A48: CODE | B48: DESCRIPTION | C48: Materials & Equipment | G48: Labor
...

Sheet 9
C1: ='Estimate Summary'!C1:H1 -> 0
G5: Finishes | J5: Schedule
D6: ='Estimate Summary'!C11 -> Area: | E6: ='Estimate Summary'!D11 -> 1747 | F6: ='Estimate Summary'!E11 -> Sq. Ft. | J6: ='1'!J6 -> 13 | K6: Weeks
A9: CODE | B9: DESCRIPTION | C9: Materials & Equipment | G9: Labor | L9: Sub Contractor | M9: Quote Total | N9: Additional Quote Info
A10: 09 20 00 | B10: Plaster and Gypsum Board | C10: Qty | D10: Unit | E10: U. Price | F10: Sub Total | G10: MHrs | H10: U. Price | I10: Sub Total | J10: Quote | K10: Total
B11: Interior Drywall | C11: 5097 | D11: SF | E11: 7 | F11: 0 | H11: 0 | I11: =G11*H11 -> 0 | J11: =M15 -> 61750 | K11: =F11+I11+J11 -> 61750 | L11: Arsenault | M11: 82720 | N11: Includes plywood for millwork and washroom accessories
B12: Demising Wall - 1hr - 1 layer of gypsum board over existing wall | C12: 1748 | D12: SF | E12: 10 | F12: 0 | H12: 0 | I12: =G12*H12 -> 0 | K12: =F12+I12+J12 -> 0 | L12: Arsenault | M12: 19160 | N12: All walls to underside of deck
B13: Extra for wall to underside of deck - Office, Staff lounge and equipment room | D13: SF | E13: 0 | F13: =C13*E13 -> 0 | H13: 0 | I13: =G13*H13 -> 0 | K13: =F13+I13+J13 -> 0 | L13: Fundy | M13: 66800 | N13: Backing NIC
C14: =E6 -> 1747 | D14: SF | E14: 0 | F14: =C14*E14 -> 0 | H14: 0 | I14: =G14*H14 -> 0 | K14: =F14+I14+J14 -> 0 | L14: Fundy | M14: 6800 | N14: Credit for walls to be 10'
D15: SF | E15: 0 | F15: =C15*E15 -> 0 | H15: 0 | I15: =G15*H15 -> 0 | K15: =F15+I15+J15 -> 0 | L15: premium | M15: 61750 | N15: Backing included, except for walls not indicated on drawing
D16: SF | E16: 0 | F16: =C16*E16 -> 0 | H16: 0 | I16: =G16*H16 -> 0 | K16: =F16+I16+J16 -> 0 | L16: premium | M16: 8500 | N16: Option price for all walls to underside of deck
J18: Sub Total | K18: =SUM(K11:K17) -> 61750
A19: CODE | B19: DESCRIPTION | C19: Materials & Equipment | G19: Labor
A20: 09 30 00 | B20: Tiling | C20: Qty | D20: Unit | E20: U. Price | F20: Sub Total | G20: MHrs | H20: U. Price | I20: Sub Total | J20: Quote | K20: Total
B21: Washroom tile | C21: 201 | D21: SF | E21: 8 | F21: 0 | H21: 0 | I21: =G21*H21 -> 0 | K21: =F21+I21+J21 -> 0
D22: SF | E22: 0 | F22: =C22*E22 -> 0 | H22: 0 | I22: =G22*H22 -> 0 | K22: =F22+I22+J22 -> 0
D23: SF | E23: 0 | F23: =C23*E23 -> 0 | H23: 0 | I23: =G23*H23 -> 0 | K23: =F23+I23+J23 -> 0
D24: SF | E24: 0 | F24: =C24*E24 -> 0 | H24: 0 | I24: =G24*H24 -> 0 | K24: =F24+I24+J24 -> 0
J26: Sub Total | K26: =SUM(K21:K25) -> 0
A27: CODE | B27: DESCRIPTION | C27: Materials & Equipment | G27: Labor
A28: 09 50 00 | B28: Ceiling | C28: Qty | D28: Unit | E28: U. Price | F28: Sub Total | G28: MHrs | H28: U. Price | I28: Sub Total | J28: Quote | K28: Total
B29: Acoustic ceiling | C29: =E6 -> 1747 | D29: SF | E29: 6 | F29: 0 | H29: 0 | I29: =G29*H29 -> 0 | K29: =F29+I29+J29 -> 0
D30: SF | E30: 0 | F30: =C30*E30 -> 0 | H30: 0 | I30: =G30*H30 -> 0 | K30: =F30+I30+J30 -> 0
J32: Sub Total | K32: =SUM(K29:K31) -> 0
A33: CODE | B33: DESCRIPTION | C33: Materials & Equipment | G33: Labor
A34: 09 60 00 | B34: Flooring | C34: Qty | D34: Unit | E34: U. Price | F34: Sub Total | G34: MHrs | H34: U. Price | I34: Sub Total | J34: Quote | K34: Total
A35: 09 61 00 | B35: Concrete Floor Polishing | D35: SF | E35: 0 | F35: =C35*E35 -> 0 | H35: 0 | I35: =G35*H35 -> 0 | K35: =F35+I35+J35 -> 0 | L35: Coastal/Primo | M35: 28200
D36: SF | E36: 0 | F36: =C36*E36 -> 0 | H36: 0 | I36: =G36*H36 -> 0 | K36: =F36+I36+J36 -> 0 | L36: Ritchie's | M36: 24500
A37: 09 62 00 | B37: Specialty Flooring | D37: SF | E37: 0 | F37: =C37*E37 -> 0 | H37: 0 | I37: =G37*H37 -> 0 | K37: =F37+I37+J37 -> 0 | L37: Domus | M37: 22675
A38: 09 64 00 | B38: Wood Flooring | D38: SF | E38: 0 | F38: =C38*E38 -> 0 | H38: 0 | I38: =G38*H38 -> 0 | K38: =F38+I38+J38 -> 0 | L38: FRS | M38: 27471
A39: 09 65 00 | B39: Flooring | C39: =E6 -> 1747 | D39: SF | E39: 12 | F39: 0 | H39: 0 | I39: =G39*H39 -> 0 | J39: =M37 -> 22675 | K39: =F39+I39+J39 -> 22675
A40: 09 67 00 | B40: Floor Prep | C40: =C39 -> 1747 | D40: SF | E40: 2 | F40: =C40*E40 -> 3494 | H40: 0 | I40: =G40*H40 -> 0 | K40: =F40+I40+J40 -> 3494
A41: 09 68 00 | B41: Carpet Tile | D41: SF | E41: 0 | F41: =C41*E41 -> 0 | H41: 0 | I41: =G41*H41 -> 0 | K41: =F41+I41+J41 -> 0
L45: Sackville smiles | M45: 5.18
