Workbook
Name Discount: #REF!
Name Discount: #REF!
Name Discount: #REF!
Name Discount: #REF!
Name Discount: #REF!
Name Discount: #REF!
Name Discount: #REF!
Name Discount: #REF!
Name Discount: #REF!
Name Discount: #REF!
Name Discount: #REF!
Name Discount: #REF!
Name Discount: #REF!
Name Discount: #REF!
Name Discount: #REF!

Sheet Cost Data
A1: Division | B1: 2
B2: 01 00 00 | C2: General Requirements
B3: 01 11 00 | C3: Preconstruction Costs | D3: ='1'!K25 -> 21450
B4: 01 31 00 | C4: Project Management and Coordination | D4: ='1'!K36 -> 63750
B5: 01 41 00 | C5: Permits | D5: ='1'!K67 -> 5301.1972
B6: 01 45 00 | C6: Quality Control | D6: ='1'!K76 -> 3250
B7: 01 51 00 | C7: Temporary Utilities | D7: ='1'!K87 -> 0
B8: 01 52 00 | C8: Construction Facilities | D8: ='1'!K97 -> 2276.2545
B9: 01 54 00 | C9: Construction Aids | D9: ='1'!K105 -> 3146.9053
B10: 01 56 00 | C10: Temporary Barriers & Enclosures | D10: ='1'!K128 -> 596.7
B11: 01 74 00 | C11: Cleaning & Waste Management | D11: ='1'!K136 -> 3450
A13: Division | B13: 2
B15: 02 00 00 | C15: Existing Conditions
B16: 02 41 00 | C16: Demolition | D16: ='2'!K24 -> 21250
B17: 02 82 00 | C17: Asbestos Remediation | D17: ='2'!K35 -> 0
B18: 02 83 00 | C18: Trenching | D18: ='2'!K46 -> 0
A21: Division | B21: 3
B22: 03 00 00 | C22: Concrete
B23: 03 11 00 | C23: Concrete Forming | D23: ='3'!K18 -> 25200
B24: 03 20 00 | C24: Concrete Reinforcing | D24: ='3'!K26 -> 11950
B25: 03 30 00 | C25: Cast-in-Place Concrete | D25: ='3'!K37 -> 7577.7
B26: 03 35 00 | C26: Concrete Finishing | D26: ='3'!K44 -> 1911
B27: 03 40 00 | C27: Precast Concrete | D27: ='3'!K49 -> 0
B28: 03 60 00 | C28: Grouting | D28: ='3'!K58 -> 3686
A31: Division | B31: 4
B32: 04 00 00 | C32: Masonry
B33: 04 20 00 | C33: Unit Masonry | D33: ='4'!K19 -> 21700
B34: 04 43 00 | C34: Stone Masonry | D34: ='4'!K30 -> 0
A36: Division | B36: 5
B37: 05 00 00 | C37: Metals
B38: 05 12 00 | C38: Structural Steel Framing | D38: ='5'!K19 -> 64100
B39: 05 20 00 | C39: Metal Joists | D39: ='5'!K29 -> 0
B40: 05 30 00 | C40: Metal Decking | D40: ='5'!K37 -> 0
B41: 05 51 00 | C41: Metal Stairs | D41: ='5'!K46 -> 0
B42: 05 52 00 | C42: Metal Railings | D42: ='5'!K57 -> 0
B43: 05 59 00 | C43: Metal Specialties | D43: ='5'!K66 -> 2040
A46: Division | B46: 6
B47: 06 00 00 | C47: Wood, Plastics, and Composites
B48: 06 11 00 | C48: Framing | D48: ='6'!K19 -> 0
B49: 06 20 00 | C49: Finish Carpentry | D49: ='6'!K36 -> 0
...

Sheet Cost Report
B1: Division | C1: Sub - Division | D1: Discription | E1: Cost
B2: 01 00 00 | D2: General Requirements | E2: ='Estimate Summary'!H15 -> 104578.16
B3: 01 11 00 | D3: Preconstruction Costs | E3: ='1'!K25 -> 21450
B4: 01 31 00 | D4: Project Management and Coordination | E4: ='1'!K36 -> 63750
B5: 01 31 00 | C5: 01 31 01 | D5: Senior Construction Manager | E5: ='1'!K28 -> 0
B6: 01 31 00 | C6: 01 31 02 | D6: Senior Estimator | E6: ='1'!K29 -> 0
B7: 01 31 00 | C7: 01 31 03 | D7: Senior Project Manager | E7: ='1'!K30 -> 15000
B8: 01 31 00 | C8: 01 31 04 | D8: Project Coordinator | E8: ='1'!K31 -> 0
B9: 01 31 00 | C9: 01 31 05 | D9: Project Superintendent | E9: ='1'!K32 -> 48750
B10: 01 31 00 | C10: 01 31 06 | D10: Project Foreman | E10: ='1'!K33 -> 0
B11: 01 32 00 | C11: 01 32 00 | D11: Travel
B12: 01 41 00 | D12: Permits | E12: ='1'!K67 -> 5301.1972
B13: 01 45 00 | D13: Quality Control | E13: ='1'!K76 -> 3250
B14: 01 51 00 | D14: Temporary Utilities | E14: ='1'!K87 -> 0
B15: 01 52 00 | D15: Construction Facilities | E15: ='1'!K97 -> 2276.2545
B16: 01 52 00 | C16: 01 52 01 | D16: Construction Field Office | E16: ='1'!K90 -> 0
B17: 01 52 00 | C17: 01 52 02 | D17: Sanitary Facilities | E17: ='1'!K92 -> 750
B18: 01 52 00 | C18: 01 52 03 | D18: Drawing Reprographics | E18: ='1'!K93 -> 388.75446
B19: 01 52 00 | C19: 01 52 04 | D19: First-Aid / Safety | E19: ='1'!K94 -> 937.5
B20: 01 52 00 | C20: 01 52 05 | D20: Job Sign | E20: ='1'!K95 -> 200
B21: 01 54 00 | D21: Construction Aids | E21: ='1'!K105 -> 3146.9053
B22: 01 55 00 | C22: 01 55 00 | D22: Winter Conditions
B23: 01 56 00 | D23: Temporary Barriers & Enclosures | E23: ='1'!K128 -> 596.7
B24: 01 74 00 | D24: Cleaning & Waste Management | E24: ='1'!K136 -> 3450
B25: 01 74 00 | C25: 01 74 01 | D25: Progress Cleaning | E25: ='1'!K131 -> 0
B26: 01 74 00 | C26: 01 74 02 | D26: Site Maintenance | E26: ='1'!K132 -> 0
B27: 01 74 00 | C27: 01 74 03 | D27: Construction Waste Mgmt & Disposal | E27: ='1'!K133 -> 1650
B28: 01 74 00 | C28: 01 74 04 | D28: Final Cleaning | E28: ='1'!K134 -> 1800
B29: 02 00 00 | D29: Existing Conditions | E29: ='Estimate Summary'!H17 -> 21250
B30: 02 41 00 | D30: Demolition | E30: ='2'!K24 -> 21250
B31: 02 82 00 | D31: Asbestos Remediation | E31: ='2'!K35 -> 0
B32: 02 83 00 | D32: Trenching | E32: ='2'!K46 -> 0
B33: 03 00 00 | D33: Concrete | E33: ='Estimate Summary'!H19 -> 50324.7
B34: 03 11 00 | D34: Concrete Forming | E34: ='3'!K18 -> 25200
B35: 03 20 00 | D35: Concrete Reinforcing | E35: ='3'!K26 -> 11950
B36: 03 30 00 | D36: Cast-in-Place Concrete | E36: ='3'!K37 -> 7577.7
B37: 03 35 00 | D37: Concrete Finishing | E37: ='3'!K44 -> 1911
B38: 03 40 00 | D38: Precast Concrete | E38: ='3'!K49 -> 0
B39: 03 60 00 | D39: Foundation Materials | E39: ='3'!K58 -> 3686
B40: 03 60 00 | C40: 03 60 01 | D40: Insulation | E40: ='3'!K52 -> 1148
...

Sheet DATA
B2: Quarter | C2: Column1 | D2: Province | H2: Project Definition | J2: Contract Type | K2: Payment Method | M2: A | N2: >5M
B3: Q1 | D3: NB | H3: Multi Residential | J3: CCDC 2 | K3: Stipulated Price | M3: B | N3: 2-5M
B4: Q2 | D4: PEI | H4: Office | J4: CCDC 5B | K4: Fixed Fee | M4: C | N4: 500K - 2M | R4: Status | T4: Result
B5: Q3 | D5: NS | H5: Retail | J5: CCDC 5A | M5: D | N5: 100K - 500K | R5: Awarded | T5: Successful
B6: Q4 | D6: Other | H6: Food | J6: Design Build | M6: E | N6: less than 100K | R6: Not Awarded | T6: Unsuccessful
R7: Pending
A10: Closing Date | B10: Budget Year | C10: Quarter | D10: Province | E10: City/Town | F10: Estimate Number | G10: Estimate Name | H10: Type of Construction | I10: Area | J10: Contract Type | K10: Payment Method | L10: Estimate Price | M10: Price Category | N10: Schedule | O10: Soft Cost | P10: Cost per Week | Q10: Margin | R10: Status | S10: Bid Docs | T10: Successful / Unsuccessful
A11: =+'Estimate Summary'!B3 -> 46140 | B11: =+'Estimate Summary'!B7 -> 2026 | C11: =+'Estimate Summary'!B8 -> Q2 | D11: =+'Estimate Summary'!B5 -> NB | E11: ='Estimate Summary'!B6 -> Riverview | F11: ='Estimate Summary'!B4 -> 3057 | G11: ='Estimate Summary'!D5 -> 567 Coverdale Renovation and Expansion (Phase 1) | H11: =+'Estimate Summary'!F8 -> 0 | I11: =+'Estimate Summary'!D11 -> 600 | J11: ='Estimate Summary'!D7 -> CCDC 5B | K11: =+'Estimate Summary'!D8 -> Fixed Fee | L11: =+'Estimate Summary'!D75 -> 868202.77 | M11: =IF(L11<100000,"E",IF(L11<500000,"D",IF(L11<2000000,"C",IF(L11<5000000,"B",IF(L11>=5000000,"A"))))) -> C | N11: ='Estimate Summary'!D82 -> 15 | O11: ='Estimate Summary'!D83 -> 123029.27 | P11: ='Estimate Summary'!E83 -> 8201.9515 | Q11: ='Estimate Summary'!D85 -> 0.14170569 | R11: ='Estimate Summary'!F6 -> 0 | S11: ='Estimate Summary'!F5 -> 0 | T11: ='Estimate Summary'!F7 -> 0

Sheet Estimate Version Comparison
B2: ='Estimate Summary'!D5 -> 567 Coverdale Renovation and Expansion (Phase 1) | I2: CLIENT SUMMARY
B3: ='Estimate Summary'!D6 -> GTD Management Inc.
B4: Date: | C4: ='Estimate Summary'!B3 -> 46140
G7: ='Estimate Summary'!B3 -> 46140 | H7: ='Estimate Summary'!G8 -> 0
B8: 01 00 00 | C8: General Requirements | E8: =SUM(D9:D17) -> 0 | H8: =SUM(G9:G17) -> 103221.06 | J8: =IF(H8>E8,"Increase","Decrease or No Change") -> Increase | K8: =H8-E8 -> 103221.06
B9: 01 11 00 | C9: Preconstruction Costs | D9: 0 | G9: ='1'!K25 -> 21450
B10: 01 31 00 | C10: Project Management and Coordination | D10: 0 | G10: ='1'!K36 -> 63750
B11: 01 41 00 | C11: Permits | D11: 0 | G11: ='1'!K67 -> 5301.1972
B12: 01 45 00 | C12: Quality Control | D12: 0 | G12: ='1'!K76 -> 3250
B13: 01 51 00 | C13: Temporary Utilities | D13: 0 | G13: ='1'!K87 -> 0
B14: 01 52 00 | C14: Construction Facilities | D14: 0 | G14: ='1'!K97 -> 2276.2545
B15: 01 54 00 | C15: Construction Aids | D15: 0 | G15: ='1'!K105 -> 3146.9053
B16: 01 56 00 | C16: Temporary Barriers & Enclosures | D16: 0 | G16: ='1'!K128 -> 596.7
B17: 01 74 00 | C17: Cleaning & Waste Management | D17: 0 | G17: ='1'!K136 -> 3450
B19: 02 00 00 | C19: Existing Conditions | E19: =SUM(D20:D22) -> 0 | H19: =SUM(G20:G22) -> 20950 | J19: =IF(H19>E19,"Increase","Decrease or No Change") -> Increase | K19: =H19-E19 -> 20950
B20: 02 41 00 | C20: Demolition | D20: 0 | G20: ='2'!K13 -> 20950
B21: 02 82 00 | C21: Asbestos Remediation | D21: 0 | G21: ='2'!K35 -> 0
B22: 02 83 00 | C22: Trenching | D22: 0 | G22: ='2'!K46 -> 0
B24: 03 00 00 | C24: Concrete | E24: =SUM(D25:D29) -> 0 | H24: =SUM(G25:G29) -> 50324.7 | J24: =IF(H24>E24,"Increase","Decrease or No Change") -> Increase | K24: =H24-E24 -> 50324.7
B25: 03 11 00 | C25: Concrete Forming | D25: 0 | G25: ='3'!K18 -> 25200
B26: 03 20 00 | C26: Concrete Reinforcing | D26: 0 | G26: ='3'!K26 -> 11950
B27: 03 30 00 | C27: Cast-in-Place Concrete | D27: 0 | G27: ='3'!K37+'3'!K44 -> 9488.7
B28: 03 40 00 | C28: Precast Concrete | D28: 0 | G28: ='3'!K49 -> 0
B29: 03 60 00 | C29: Grouting | D29: 0 | G29: ='3'!K58 -> 3686
B31: 04 00 00 | C31: Masonry | E31: =SUM(D32:D33) -> 0 | H31: =SUM(G32:G33) -> 21700 | J31: =IF(H31>E31,"Increase","Decrease or No Change") -> Increase | K31: =H31-E31 -> 21700
B32: 04 20 00 | C32: Unit Masonry | D32: 0 | G32: ='4'!K19 -> 21700
B33: 04 40 00 | C33: Stone Assemblies | D33: 0 | G33: ='4'!K30 -> 0
B35: 05 00 00 | C35: Metals | E35: =SUM(D36:D39) -> 0 | H35: =SUM(G36:G39) -> 66140 | J35: =IF(H35>E35,"Increase","Decrease or No Change") -> Increase | K35: =H35-E35 -> 66140
B36: 05 12 00 | C36: Structural Steel Framing | D36: 0 | G36: ='5'!K19 -> 64100
B37: 05 20 00 | C37: Metal Joists | D37: 0 | G37: ='5'!K29 -> 0
B38: 05 30 00 | C38: Metal Decking | D38: 0 | G38: ='5'!K37 -> 0
B39: 05 50 00 | C39: Metal Fabrications | D39: 0 | G39: ='5'!K46+'5'!K57+'5'!K66 -> 2040
B41: 06 00 00 | C41: Wood, Plastics, and Composites | E41: =SUM(D42:D45) -> 0 | H41: =SUM(G42:G45) -> 0 | J41: =IF(H41>E41,"Increase","Decrease or No Change") -> Decrease or No Change | K41: =H41-E41 -> 0
B42: 06 11 00 | C42: Framing Labour | D42: 0 | G42: ='6'!K19 -> 0
B43: 06 11 00 | C43: Framing Material | D43: 0 | G43: ='6'!K36 -> 0
B44: 06 22 00 | C44: Millwork | D44: 0 | G44: ='6'!K47 -> 0
B45: 06 40 00 | C45: Architectural Woodwork | D45: 0 | G45: ='6'!K55+'6'!K64+'6'!K75+'6'!K84+'6'!K91 -> 0
B47: 07 00 00 | C47: Thermal and Moisture Protection | E47: =SUM(D48:D57) -> 0 | H47: =SUM(G48:G57) -> 124516 | J47: =IF(H47>E47,"Increase","Decrease or No Change") -> Increase | K47: =H47-E47 -> 124516
B48: 07 21 00 | C48: Thermal Insulation | D48: 0 | G48: ='7'!K16 -> 0
B49: 07 24 00 | C49: EIFS | D49: 0 | G49: ='7'!K22 -> 0
...

Sheet Client  Detailed Summary 
B3: ='Estimate Summary'!D5 -> 567 Coverdale Renovation and Expansion (Phase 1) | F3: CLIENT SUMMARY
B4: ='Estimate Summary'!D6 -> GTD Management Inc.
B5: Date: | C5: ='Estimate Summary'!B3 -> 46140 | G5: CLIENT SUMMARY
B7: 01 00 00 | C7: General Requirements | H7: =SUM(G8:G17) -> 104578.16
B8: 01 11 00 | C8: Preconstruction Costs (Design) | G8: ='1'!K25 -> 21450
B9: 01 31 00 | C9: Project Management and Coordination | G9: ='1'!K36 -> 63750
B10: 01 32 00 | C10: Insurance | G10: ='1'!K46+'1'!K56 -> 1357.1065
B11: 01 41 00 | C11: Permits | G11: ='1'!K67 -> 5301.1972
B12: 01 45 00 | C12: Quality Control | G12: ='1'!K76 -> 3250
B13: 01 51 00 | C13: Temporary Utilities | G13: ='1'!K87 -> 0
B14: 01 52 00 | C14: Construction Facilities | G14: ='1'!K97 -> 2276.2545
B15: 01 54 00 | C15: Construction Aids | G15: ='1'!K105+'1'!K120 -> 3146.9053
B16: 01 56 00 | C16: Temporary Barriers & Enclosures | G16: ='1'!K128 -> 596.7
B17: 01 74 00 | C17: Cleaning & Waste Management | G17: ='1'!K136 -> 3450
B19: 02 00 00 | C19: Existing Conditions | H19: =SUM(G20:G22) -> 21250
B20: 02 41 00 | C20: Demolition and Coring | G20: ='2'!K24 -> 21250
B21: 02 82 00 | C21: Asbestos Remediation | G21: ='2'!K35 -> 0
B22: 02 83 00 | C22: Coring | G22: ='2'!K46 -> 0
B24: 03 00 00 | C24: Concrete | H24: =SUM(G25:G29) -> 50324.7
B25: 03 11 00 | C25: Concrete Forming | G25: ='3'!K18 -> 25200
B26: 03 20 00 | C26: Concrete Reinforcing | G26: ='3'!K26 -> 11950
B27: 03 30 00 | C27: Cast-in-Place Concrete | G27: ='3'!K37+'3'!K44 -> 9488.7
B28: 03 40 00 | C28: Precast Concrete | G28: ='3'!K49 -> 0
B29: 03 60 00 | C29: Foundation Materials | G29: ='3'!K58 -> 3686
B31: 04 00 00 | C31: Masonry | H31: =SUM(G32:G33) -> 21700
B32: 04 20 00 | C32: Unit Masonry | G32: ='4'!K19 -> 21700
B33: 04 40 00 | C33: Stone Assemblies | G33: ='4'!K30 -> 0
B35: 05 00 00 | C35: Metals | H35: =SUM(G36:G39) -> 66140
B36: 05 12 00 | C36: Structural Steel Framing | G36: ='5'!K19 -> 64100
B37: 05 20 00 | C37: Metal Joists | G37: ='5'!K29 -> 0
B38: 05 30 00 | C38: Metal Decking | G38: ='5'!K37 -> 0
B39: 05 50 00 | C39: Metal Fabrications | G39: ='5'!K46+'5'!K57+'5'!K66 -> 2040
B41: 06 00 00 | C41: Wood, Plastics, and Composites | H41: =SUM(G42:G45) -> 0
B42: 06 11 00 | C42: Framing Labour | G42: ='6'!K19 -> 0
B43: 06 11 00 | C43: Framing Material | G43: ='6'!K36 -> 0
B44: 06 22 00 | C44: Millwork | G44: ='6'!K47 -> 0
B45: 06 40 00 | C45: Architectural Woodwork | G45: ='6'!K55+'6'!K64+'6'!K75+'6'!K84+'6'!K91 -> 0
B47: 07 00 00 | C47: Thermal and Moisture Protection | H47: =SUM(G48:G57) -> 124516
B48: 07 21 00 | C48: Thermal Insulation | G48: ='7'!K16 -> 0
B49: 07 24 00 | C49: EIFS | G49: ='7'!K22 -> 0
...

Sheet Estimate Summary
A2: Project Information
A3: Closing Date : | B3: 46140
A4: Estimate # E- | B4: 3057 | C4: Area: | D4: 600
A5: Province : | B5: NB | C5: Estimate Name : | D5: 567 Coverdale Renovation and Expansion (Phase 1) | E5: Bid Documents :
A6: City/Town : | B6: Riverview | C6: Client : | D6: GTD Management Inc. | E6: Status :
A7: Budget Year : | B7: 2026 | C7: Contract Type : | D7: CCDC 5B | E7: Result:
A8: Quarter: | B8: Q2 | C8: Payment Method : | D8: Fixed Fee
C11: Area: | D11: =D4 -> 600 | E11: Sq. Ft.
A13: CODE | B13: DESCRIPTION | D13: M&E $$ | E13: M-HRS | F13: LAB $$ | G13: SUB CONT. | H13: Total | K13: Comparable Project
C14: % | I14: $/SF
A15: 01 00 00 | B15: General Requirements | C15: =H15/D$66 -> 0.12888537 | D15: =SUM('1'!F139:F140) -> 40828.163 | E15: =SUM('1'!G139:G140) -> 50 | F15: =SUM('1'!I139:I140) -> 63750 | G15: =SUM('1'!J139:J140) -> 0 | H15: =D15+F15+G15 -> 104578.16 | I15: =ROUNDUP(H15/D$11,1)&"$/SF" -> 174.3$/SF
A17: 02 00 00 | B17: Existing Conditions | C17: =H17/D$66 -> 0.026189159 | D17: =SUM('2'!F49:F50) -> 300 | E17: =SUM('2'!G49:G50) -> 0 | F17: =SUM('2'!I49:I50) -> 0 | G17: =SUM('2'!J49:J50) -> 20950 | H17: =D17+F17+G17 -> 21250 | I17: =ROUNDUP(H17/D$11,1)&"$/SF" -> 35.5$/SF
A19: 03 00 00 | B19: Concrete | C19: =H19/D$66 -> 0.06202172 | D19: =SUM('3'!F61:F62) -> 11302.7 | E19: =SUM('3'!G61:G62) -> 28.8 | F19: =SUM('3'!I61:I62) -> 1872 | G19: =SUM('3'!J61:J62) -> 37150 | H19: =D19+F19+G19 -> 50324.7 | I19: =ROUNDUP(H19/D$11,1)&"$/SF" -> 83.9$/SF
A21: 04 00 00 | B21: Masonry | C21: =H21/D$66 -> 0.026743753 | D21: =SUM('4'!F61:F62) -> 0 | E21: =SUM('4'!G61:G62) -> 0 | F21: =SUM('4'!I61:I62) -> 0 | G21: =SUM('4'!J61:J62) -> 21700 | H21: =D21+F21+G21 -> 21700 | I21: =ROUNDUP(H21/D$11,1)&"$/SF" -> 36.2$/SF
A23: 05 00 00 | B23: Metals | C23: =H23/D$66 -> 0.081512986 | D23: =SUM('5'!F69:F70) -> 1000 | E23: =SUM('5'!G69:G70) -> 16 | F23: =SUM('5'!I69:I70) -> 1040 | G23: =SUM('5'!J69:J70) -> 64100 | H23: =D23+F23+G23 -> 66140 | I23: =ROUNDUP(H23/D$11,1)&"$/SF" -> 110.3$/SF
A25: 06 00 00 | B25: Wood, Plastics, and Composites | C25: =H25/D$66 -> 0 | D25: =SUM('6'!F94:F95) -> 0 | E25: =SUM('6'!G94:G95) -> 0 | F25: =SUM('6'!I94:I95) -> 0 | G25: =SUM('6'!J94:J95) -> 0 | H25: =D25+F25+G25 -> 0 | I25: =ROUNDUP(H25/D$11,1)&"$/SF" -> 0$/SF
A27: 07 00 00 | B27: Thermal and Moisture Protection | C27: =H27/D$66 -> 0.15345738 | D27: =SUM('7'!F101:F102) -> 0 | E27: =SUM('7'!G101:G102) -> 0 | F27: =SUM('7'!I101:I102) -> 0 | G27: =SUM('7'!J101:J102) -> 124516 | H27: =D27+F27+G27 -> 124516 | I27: =ROUNDUP(H27/D$11,1)&"$/SF" -> 207.6$/SF
A29: 08 00 00 | B29: Openings | C29: =H29/D$66 -> 0.088772005 | D29: =SUM('8'!F112:F113) -> 0 | E29: =SUM('8'!G112:G113) -> 8 | F29: =SUM('8'!I112:I113) -> 520 | G29: =SUM('8'!J112:J113) -> 71510 | H29: =D29+F29+G29 -> 72030 | I29: =ROUNDUP(H29/D$11,1)&"$/SF" -> 120.1$/SF
A31: 09 00 00 | B31: Finishes | C31: =H31/D$66 -> 0.075485893 | D31: =SUM('9'!F70:F71) -> 0 | E31: =SUM('9'!G70:G71) -> 0 | F31: =SUM('9'!I70:I71) -> 0 | G31: =SUM('9'!J70:J71) -> 61249.59 | H31: =D31+F31+G31 -> 61249.59 | I31: =ROUNDUP(H31/D$11,1)&"$/SF" -> 102.1$/SF
A33: 10 00 00 | B33: Specialties | C33: =H33/D$66 -> 0 | D33: =SUM('10'!F74:F75) -> 0 | E33: =SUM('10'!G74:G75) -> 0 | F33: =SUM('10'!I74:I75) -> 0 | G33: =SUM('10'!J74:J75) -> 0 | H33: =D33+F33+G33 -> 0 | I33: =ROUNDUP(H33/D$11,1)&"$/SF" -> 0$/SF
A35: 11 00 00 | B35: Equipment | C35: =H35/D$66 -> 0 | D35: =SUM('11'!F99:F100) -> 0 | E35: =SUM('11'!G99:G100) -> 0 | F35: =SUM('11'!I99:I100) -> 0 | G35: =SUM('11'!J99:J100) -> 0 | H35: =D35+F35+G35 -> 0 | I35: =ROUNDUP(H35/D$11,1)&"$/SF" -> 0$/SF
A37: 12 00 00 | B37: Furnishings | C37: =H37/D$66 -> 0 | D37: =SUM('12'!F99:F100) -> 0 | E37: =SUM('12'!G99:G100) -> 0 | F37: =SUM('12'!I99:I100) -> 0 | G37: =SUM('12'!J99:J100) -> 0 | H37: =D37+F37+G37 -> 0 | I37: =ROUNDUP(H37/D$11,1)&"$/SF" -> 0$/SF
A39: 13 00 00 | B39: Special Construction | C39: =H39/D$66 -> 0 | D39: =+SUM('13'!F99:F100) -> 0 | E39: =SUM('13'!G99:G100) -> 0 | F39: =SUM('13'!I99:I100) -> 0 | G39: =SUM('13'!J99:J100) -> 0 | H39: =D39+F39+G39 -> 0 | I39: =ROUNDUP(H39/D$11,1)&"$/SF" -> 0$/SF
A41: 14 00 00 | B41: Conveying Equipment | C41: =H41/D$66 -> 0.16366684 | D41: =SUM('14'!F98:F99) -> 0 | E41: =SUM('14'!G98:G99) -> 0 | F41: =SUM('14'!I98:I99) -> 0 | G41: =SUM('14'!J98:J99) -> 132800 | H41: =D41+F41+G41 -> 132800 | I41: =ROUNDUP(H41/D$11,1)&"$/SF" -> 221.4$/SF
A43: 21 00 00 | B43: Fire Suppression | C43: =H43/D$66 -> 0.024081702 | D43: =SUM('21'!F99:F100) -> 0 | E43: =SUM('21'!G99:G100) -> 0 | F43: =SUM('21'!I99:I100) -> 0 | G43: =SUM('21'!J99:J100) -> 19540 | H43: =D43+F43+G43 -> 19540 | I43: =ROUNDUP(H43/D$11,1)&"$/SF" -> 32.6$/SF
A45: 22 00 00 | B45: Plumbing | C45: =H45/D$66 -> 0.031362904 | D45: =SUM('22'!F94:F95) -> 0 | E45: =SUM('22'!G94:G95) -> 0 | F45: =SUM('22'!I94:I95) -> 0 | G45: =SUM('22'!J94:J95) -> 25448 | H45: =D45+F45+G45 -> 25448 | I45: =ROUNDUP(H45/D$11,1)&"$/SF" -> 42.5$/SF
A47: 23 00 00 | B47: HVAC | C47: =H47/D$66 -> 0.01035242 | D47: =SUM('23'!F102:F103) -> 0 | E47: =SUM('23'!G102:G103) -> 0 | F47: =SUM('23'!I102:I103) -> 0 | G47: =SUM('23'!J102:J103) -> 8400 | H47: =D47+F47+G47 -> 8400 | I47: =ROUNDUP(H47/D$11,1)&"$/SF" -> 14$/SF
A49: 25 00 00 | B49: Integrated Automation | C49: =H49/D$66 -> 0 | D49: =SUM('25'!F54:F55) -> 0 | E49: =SUM('25'!G54:G55) -> 0 | F49: =SUM('25'!I54:I55) -> 0 | G49: =SUM('25'!J54:J55) -> 0 | H49: =D49+F49+G49 -> 0 | I49: =ROUNDUP(H49/D$11,1)&"$/SF" -> 0$/SF
A51: 26 00 00 | B51: Electrical | C51: =H51/D$66 -> 0.065661459 | D51: =SUM('26'!F53:F54) -> 0 | E51: =SUM('26'!G53:G54) -> 0 | F51: =SUM('26'!I53:I54) -> 0 | G51: =SUM('26'!J53:J54) -> 53278 | H51: =D51+F51+G51 -> 53278 | I51: =ROUNDUP(H51/D$11,1)&"$/SF" -> 88.8$/SF
A53: 27 00 00 | B53: Communications | C53: =H53/D$66 -> 0 | D53: =SUM('27'!F99:F100) -> 0 | E53: =SUM('27'!G99:G100) -> 0 | F53: =SUM('27'!I99:I100) -> 0 | G53: =SUM('27'!J99:J100) -> 0 | H53: =D53+F53+G53 -> 0 | I53: =ROUNDUP(H53/D$11,1)&"$/SF" -> 0$/SF
A55: 28 00 00 | B55: Electronic Safety and Security | C55: =H55/D$66 -> 0 | D55: =SUM('28'!F55:F56) -> 0 | E55: =SUM('28'!G55:G56) -> 0 | F55: =SUM('28'!I55:I56) -> 0 | G55: =SUM('28'!J55:J56) -> 0 | H55: =D55+F55+G55 -> 0 | I55: =ROUNDUP(H55/D$11,1)&"$/SF" -> 0$/SF
A57: 31 00 00 | B57: Earthwork | C57: =H57/D$66 -> 0.05207021 | D57: =SUM('31'!F59:F60) -> 0 | E57: =SUM('31'!G59:G60) -> 0 | F57: =SUM('31'!I59:I60) -> 0 | G57: =SUM('31'!J59:J60) -> 42250 | H57: =D57+F57+G57 -> 42250 | I57: =ROUNDUP(H57/D$11,1)&"$/SF" -> 70.5$/SF
A59: 32 00 00 | B59: Exterior Improvements | C59: =H59/D$66 -> 0.0097362049 | D59: =SUM('32'!F97:F98) -> 5900 | E59: =SUM('32'!G97:G98) -> 0 | F59: =SUM('32'!I97:I98) -> 0 | G59: =SUM('32'!J97:J98) -> 2000 | H59: =D59+F59+G59 -> 7900 | I59: =ROUNDUP(H59/D$11,1)&"$/SF" -> 13.2$/SF
A61: 33 00 00 | B61: Utilities | C61: =H61/D$66 -> 0 | D61: =SUM('33'!F57:F58) -> 0 | E61: =SUM('33'!G57:G58) -> 0 | F61: =SUM('33'!I57:I58) -> 0 | G61: =SUM('33'!J57:J58) -> 0 | H61: =D61+F61+G61 -> 0 | I61: =ROUNDUP(H61/D$11,1)&"$/SF" -> 0$/SF
B64: Sub Totals>>>>>> | C64: =SUM(C15:C63) -> 1 | D64: =SUM(D15:D63) -> 59330.863 | E64: =SUM(E15:E63) -> 102.8 | F64: =SUM(F15:F63) -> 67182 | G64: =SUM(G15:G63) -> 684891.59 | H64: =SUM(H15:H63) -> 811404.45 | I64: =ROUNDUP(H64/D$11,1)&"$/SF" -> 1352.4$/SF
B66: Total Construction Cost>>>>>> | D66: =D64+F64+G64 -> 811404.45
B68: OH&P>>>>>> | D68: =(D66*E68) -> 56798.312 | E68: 0.07 | K68: 7% as agreed by Client (Dean Hartman ) via email dated 2026-Feb-05
F69: HST | G69: TOTAL
F70: 0.15
B71: Estimated Price | D71: =D68+D66 -> 868202.77 | F71: =D71*F70 -> 130230.41 | G71: =D71+F71 -> 998433.18
...

Sheet 1
C1: ='Estimate Summary'!C1:H1 -> 0
G5: General Requirements | J5: Schedule
D6: ='Estimate Summary'!C11 -> Area: | E6: ='Estimate Summary'!D11 -> 600 | F6: ='Estimate Summary'!E11 -> Sq. Ft. | J6: ='Estimate Summary'!D82 -> 15 | K6: Weeks
A9: CODE | B9: DESCRIPTION | C9: Materials & Equipment | G9: Labor | L9: Sub Contractor | M9: Quote Total | N9: Additional Quote Info
A10: 01 11 00 | B10: Preconstruction Costs | C10: Qty | D10: Unit | E10: U. Price | F10: Sub Total | G10: MHrs | H10: U. Price | I10: Sub Total | J10: Quote | K10: Total
A11: 01 11 13 | B11: Senior Construction Manager | D11: LS | E11: 0 | F11: =C11*E11 -> 0 | H11: 0 | I11: =G11*H11 -> 0 | K11: =F11+I11+J11 -> 0
A12: 01 11 16 | B12: Senior Estimator - AGCM | C12: 1 | D12: LS | E12: 2500 | F12: =C12*E12 -> 2500 | H12: 0 | I12: =G12*H12 -> 0 | K12: =F12+I12+J12 -> 2500 | L12: as agreed by Client (Dean Hartman ) via email dated 2026-Feb-05
A13: 01 11 19 | B13: Junior Estimator | D13: LS | E13: 0 | F13: =C13*E13 -> 0 | H13: 0 | I13: =G13*H13 -> 0 | K13: =F13+I13+J13 -> 0
A14: 01 11 23 | B14: Reprographics | D14: LS | E14: 0 | F14: =C14*E14 -> 0 | H14: 0 | I14: =G14*H14 -> 0 | K14: =F14+I14+J14 -> 0
A15: 01 11 26 | B15: Design Costs | D15: LS | E15: 0 | F15: =C15*E15 -> 0 | H15: 0 | I15: =G15*H15 -> 0 | K15: =F15+I15+J15 -> 0
A16: 01 11 26.13 | B16: Architect | C16: 1 | D16: LS | E16: 0 | F16: =C16*E16 -> 0 | H16: 0 | I16: =G16*H16 -> 0 | K16: =F16+I16+J16 -> 0 | L16: KUB | M16: TBC
A17: 01 11 26.16 | B17: Civil | D17: LS | E17: 0 | F17: =C17*E17 -> 0 | H17: 0 | I17: =G17*H17 -> 0 | K17: =F17+I17+J17 -> 0
A18: 01 11 26.19 | B18: Structural - Giffin | C18: 1 | D18: LS | E18: =M18 -> 14000 | F18: =C18*E18 -> 14000 | H18: 0 | I18: =G18*H18 -> 0 | K18: =F18+I18+J18 -> 14000 | L18: Giffin | M18: 14000 | N18: as agreed by Client (Dean Hartman ) via email dated 2026-Feb-05
A19: 01 11 26.23 | B19: HVAC | D19: LS | E19: 0 | F19: =C19*E19 -> 0 | H19: 0 | I19: =G19*H19 -> 0 | K19: =F19+I19+J19 -> 0 | L19: Delray | M19: 15800 | N19: $13,000 + construction review @ $1000 + $600x3 | O19: $13,000 + construction review @ $1000 + $600x3
A20: 01 11 26.26 | B20: Plumbing | D20: LS | E20: 0 | F20: =C20*E20 -> 0 | H20: 0 | I20: =G20*H20 -> 0 | K20: =F20+I20+J20 -> 0
A21: 01 11 26.29 | B21: Electrical | D21: LS | E21: 0 | F21: =C21*E21 -> 0 | H21: 0 | I21: =G21*H21 -> 0 | K21: =F21+I21+J21 -> 0
A22: 01 11 26.33 | B22: Geotechnical | D22: LS | E22: 0 | F22: =C22*E22 -> 0 | H22: 0 | I22: =G22*H22 -> 0 | K22: =F22+I22+J22 -> 0
A23: 01 11 26.19 | B23: M&E - LRL | C23: 1 | D23: LS | E23: =M23 -> 4950 | F23: =C23*E23 -> 4950 | H23: 0 | I23: =G23*H23 -> 0 | K23: =F23+I23+J23 -> 4950 | L23: LRL | M23: 4950 | N23: as agreed by Client (Dean Hartman ) via email dated 2026-Feb-05
L24: AEC | M24: 12800
J25: Sub Total | K25: =SUM(K11:K24) -> 21450
A26: CODE | B26: DESCRIPTION | C26: Materials & Equipment | G26: Labor
A27: 01 31 00 | B27: Project Management and Coordination | C27: Qty | D27: Unit | E27: U. Price | F27: Sub Total | G27: MHrs | H27: U. Price | I27: Sub Total | J27: Quote | K27: Total
A28: 01 31 01 | B28: Senior Construction Manager | D28: LS | E28: 0 | F28: =C28*E28 -> 0 | H28: 0 | I28: =G28*H28 -> 0 | K28: =F28+I28+J28 -> 0
A29: 01 31 02 | B29: Senior Estimator | D29: LS | E29: 0 | F29: =C29*E29 -> 0 | H29: 0 | I29: =G29*H29 -> 0 | K29: =F29+I29+J29 -> 0
A30: 01 31 03 | B30: Senior Project Manager | C30: =J6 -> 15 | D30: Week | E30: 0 | F30: =C30*E30 -> 0 | G30: 10 | H30: 100 | I30: =H30*G30*C30 -> 15000 | K30: =F30+I30+J30 -> 15000 | L30: as agreed by Client (Dean Hartman ) via email dated 2026-Feb-05
A31: 01 31 04 | B31: Project Coordinator | C31: =J6 -> 15 | D31: LS | E31: 0 | F31: =C31*E31 -> 0 | H31: 75 | I31: =H31*G31*C31 -> 0 | K31: =F31+I31+J31 -> 0
A32: 01 31 05 | B32: Project Superintendent | C32: =J6 -> 15 | D32: Week | E32: 0 | F32: =C32*E32 -> 0 | G32: 40 | H32: 81.25 | I32: =H32*G32*C32 -> 48750 | K32: =F32+I32+J32 -> 48750 | L32: as agreed by Client (Dean Hartman ) via email dated 2026-Feb-05
A33: 01 31 06 | B33: Project Foreman | D33: LS | E33: 0 | F33: =C33*E33 -> 0 | H33: 0 | I33: =G33*H33 -> 0 | K33: =F33+I33+J33 -> 0
D34: LS | E34: 0 | F34: =C34*E34 -> 0 | H34: 0 | I34: =G34*H34 -> 0 | K34: =F34+I34+J34 -> 0
K35: =F35+I35+J35 -> 0
J36: Sub Total | K36: =SUM(K28:K35) -> 63750
A37: CODE | B37: DESCRIPTION
A38: 01 32 00 | B38: Insurance | D38: /$1000 | E38: Cost | F38: Rate | G38: Toll Cost | H38: Frequency | J38: Sub Total | K38: Total
A39: 01 32 01 | B39: General Liability & Contractor's Pollution Liability | C39: =SUM('Estimate Summary'!H17:H61)/1000 -> 706.82629 | D39: /$1000 | E39: 0.63 | F39: =C39*E39 -> 445.30056 | K39: =F39 -> 445.30056
B40: Contractor's Pollution Liability | C40: =SUM('Estimate Summary'!H17:H61)/1000 -> 706.82629 | D40: /$1000 | E40: 1.29 | F40: =C40*E40 -> 911.80591 | K40: =F40 -> 911.80591
B41: Builders Risk | C41: =+J6/4.5 -> 3.3333333 | D41: $1000/month | E41: 0.75 | K41: =F41 -> 0
B42: Wrap-up Liability | C42: =SUM('Estimate Summary'!H17:H61)/1000 -> 706.82629 | D42: /$1000 | E42: 1.88 | K42: =F42 -> 0
A46: 01 32 00 | J46: Sub Total | K46: =SUM(K39:K45) -> 1357.1065
A47: CODE | B47: DESCRIPTION | C47: Materials & Equipment | G47: Labor
A48: 01 32 00 | B48: Travel | C48: Frequency | D48: Weeks | E48: Distance (Round Trip) | F48: Rate | G48: Toll Cost | H48: Frequency | J48: Sub Total | K48: Total
...

Sheet 2
C1: ='Estimate Summary'!C1:H1 -> 0
G5: Existing Conditions | J5: Schedule
D6: ='Estimate Summary'!C11 -> Area: | E6: ='Estimate Summary'!D11 -> 600 | F6: ='Estimate Summary'!E11 -> Sq. Ft. | J6: ='1'!J6 -> 15 | K6: Weeks
A11: CODE | B11: DESCRIPTION | C11: Materials & Equipment | G11: Labor | L11: Sub Contractor | M11: Quote Total | N11: Additional Quote Info
A12: 02 00 00 | B12: Existing Conditions | C12: Qty | D12: Unit | E12: U. Price | F12: Sub Total | G12: MHrs | H12: U. Price | I12: Sub Total | J12: Quote | K12: Total
A13: 02 41 00 | B13: Demolition | D13: LS | E13: 0 | F13: =C13*E13 -> 0 | H13: 0 | I13: =G13*H13 -> 0 | J13: =M17 -> 20950 | K13: =F13+I13+J13 -> 20950 | L13: Branco
M14: 7250 | N14: Sidewalk removal & disposal
B15: Add Extra coring | C15: 1 | D15: LS | E15: 300 | F15: =C15*E15 -> 300 | H15: 0 | I15: =G15*H15 -> 0 | K15: =F15+I15+J15 -> 300 | M15: 29850 | N15: Main demolition
L16: PLG
L17: Inflector | M17: 20950
L19: Enviro | M19: 19600
M20: =800+200+600 -> 1600 | N20: 3 openings
M21: =SUM(M19:M20) -> 21200
J24: Sub Total | K24: =SUM(K13:K23) -> 21250
A25: CODE | B25: DESCRIPTION | C25: Materials & Equipment | G25: Labor
A26: 02 82 00 | B26: Asbestos Remediation | C26: Qty | D26: Unit | E26: U. Price | F26: Sub Total | G26: MHrs | H26: U. Price | I26: Sub Total | J26: Quote | K26: Total
D27: LS | E27: 0 | F27: =C27*E27 -> 0 | H27: 0 | I27: =G27*H27 -> 0 | K27: =F27+I27+J27 -> 0
D28: LS | E28: 0 | F28: =C28*E28 -> 0 | H28: 0 | I28: =G28*H28 -> 0 | K28: =F28+I28+J28 -> 0
D29: LS | E29: 0 | F29: =C29*E29 -> 0 | H29: 0 | I29: =G29*H29 -> 0 | K29: =F29+I29+J29 -> 0
D30: LS | E30: 0 | F30: =C30*E30 -> 0 | H30: 0 | I30: =G30*H30 -> 0 | K30: =F30+I30+J30 -> 0
D31: LS | E31: 0 | F31: =C31*E31 -> 0 | H31: 0 | I31: =G31*H31 -> 0 | K31: =F31+I31+J31 -> 0
D32: LS | E32: 0 | F32: =C32*E32 -> 0 | H32: 0 | I32: =G32*H32 -> 0 | K32: =F32+I32+J32 -> 0
D33: LS | E33: 0 | F33: =C33*E33 -> 0 | H33: 0 | I33: =G33*H33 -> 0 | K33: =F33+I33+J33 -> 0
J35: Sub Total | K35: =SUM(K27:K34) -> 0
A36: CODE | B36: DESCRIPTION | C36: Materials & Equipment | G36: Labor
A37: 02 83 00 | B37: Trenching | C37: Qty | D37: Unit | E37: U. Price | F37: Sub Total | G37: MHrs | H37: U. Price | I37: Sub Total | J37: Quote | K37: Total
B38: Core Drilling | D38: ea | E38: 300 | F38: =C38*E38 -> 0 | H38: 0 | I38: =G38*H38 -> 0 | K38: =F38+I38+J38 -> 0 | L38: assumed for the basement machine room
B39: Core drilling for plumbing | D39: ft | E39: 65 | F39: =C39*E39 -> 0 | H39: 0 | I39: =G39*H39 -> 0 | K39: =F39+I39+J39 -> 0 | N39: Part of Inflector's quote
B40: Sanitary Trenching | D40: ft | E40: 65 | F40: =C40*E40 -> 0 | H40: 0 | I40: =G40*H40 -> 0 | K40: =F40+I40+J40 -> 0
B41: Conduit Trenching | D41: ft | E41: 35 | F41: =C41*E41 -> 0 | H41: 0 | I41: =G41*H41 -> 0 | K41: =F41+I41+J41 -> 0
D42: LS | E42: 0 | F42: =C42*E42 -> 0 | H42: 0 | I42: =G42*H42 -> 0 | K42: =F42+I42+J42 -> 0
D43: LS | E43: 0 | F43: =C43*E43 -> 0 | H43: 0 | I43: =G43*H43 -> 0 | K43: =F43+I43+J43 -> 0
D44: LS | E44: 0 | F44: =C44*E44 -> 0 | H44: 0 | I44: =G44*H44 -> 0 | K44: =F44+I44+J44 -> 0
J46: Sub Total | K46: =SUM(K38:K45) -> 0
F47: Material Total | G47: Total Hours | I47: Labor Total | J47: Contractor Total | K47: TOTAL
A48: $ / Sq.Ft | B48: TOTAL DIVISION 2
A49: =K49/E6 -> 35.416667 | F49: =SUM(F13:F23,F38:F45,F27:F33) -> 300 | G49: =SUM(G13:G23,G38:G45,G27:G33) -> 0 | I49: =SUM(I13:I23,I38:I45,I27:I33) -> 0 | J49: =SUM(J13:J23,J38:J45,J27:J33) -> 20950 | K49: =SUM(K46,K24,K35) -> 21250

Sheet 3
C1: ='Estimate Summary'!C1:H1 -> 0
G5: Concrete | J5: Schedule
D6: ='Estimate Summary'!C11 -> Area: | E6: ='Estimate Summary'!D11 -> 600 | F6: ='Estimate Summary'!E11 -> Sq. Ft. | J6: ='1'!J6 -> 15 | K6: Weeks
A11: CODE | B11: DESCRIPTION | C11: Materials & Equipment | G11: Labor | L11: Sub Contractor | M11: Quote Total | N11: Additional Quote Info
A12: 03 11 00 | B12: Concrete Forming | C12: Qty | D12: Unit | E12: U. Price | F12: Sub Total | G12: MHrs | H12: U. Price | I12: Sub Total | J12: Quote | K12: Total
A13: 03 11 01 | B13: Contractor Quote | K13: =F13+I13+J13 -> 0
A14: 03 11 02.1 | B14: Footing, Foundation Wall | D14: LS | F14: =C14*E14 -> 0 | H14: 0 | I14: =G14*H14 -> 0 | J14: =M15 -> 25200 | K14: =F14+I14+J14 -> 25200 | L14: Coastal Formwork | N14: confirmed to bid
A15: 03 11 02.2 | B15: Suspended Slab | D15: LS | F15: =C15*E15 -> 0 | H15: 0 | I15: =G15*H15 -> 0 | K15: =F15+I15+J15 -> 0 | L15: L&L Concrete Fdn | M15: 25200
A16: 03 11 02.3 | B16: Piers | D16: ea | E16: 150 | F16: =C16*E16 -> 0 | H16: 0 | I16: =G16*H16 -> 0 | K16: =F16+I16+J16 -> 0
J18: Sub Total | K18: =SUM(K13:K17) -> 25200
A19: CODE | B19: DESCRIPTION | C19: Materials & Equipment | G19: Labor
A20: 03 20 00 | B20: Concrete Reinforcing | C20: Qty | D20: Unit | E20: U. Price | F20: Sub Total | G20: MHrs | H20: U. Price | I20: Sub Total | J20: Quote | K20: Total
A21: 03 20 01 | B21: Contractor Quote | K21: =F21+I21+J21 -> 0
A22: 03 20 02 | B22: Rebar | D22: LS | F22: =C22*E22 -> 0 | H22: 0 | I22: =G22*H22 -> 0 | J22: =M23 -> 11950 | K22: =F22+I22+J22 -> 11950 | L22: OSCO | M22: 13369 | N22: confirmed to bid
A23: 03 20 03 | B23: Mesh | D23: LS | E23: 0 | F23: =C23*E23 -> 0 | H23: 0 | I23: =G23*H23 -> 0 | K23: =F23+I23+J23 -> 0 | L23: AGF Olympic | M23: 11950
D24: LS | E24: 0 | F24: =C24*E24 -> 0 | H24: 0 | I24: =G24*H24 -> 0 | K24: =F24+I24+J24 -> 0
J26: Sub Total | K26: =SUM(K21:K25) -> 11950
A27: CODE | B27: DESCRIPTION | C27: Materials & Equipment | G27: Labor
A28: 03 30 00 | B28: Cast-in-Place Concrete | C28: Qty | D28: Unit | E28: U. Price | F28: Sub Total | G28: MHrs | H28: U. Price | I28: Sub Total | J28: Quote | K28: Total
A29: 03 30 01 | B29: 4" Slab on-grade Volume, 25 MPa | C29: =ROUNDUP(2.71*1.1,0) -> 3 | D29: m3 | E29: =M30 -> 178.74 | F29: =C29*E29 -> 536.22 | H29: 0 | I29: =G29*H29 -> 0 | K29: =F29+I29+J29 -> 536.22 | M29: Mobile Ready Mix (2026)
A30: 03 30 02 | B30: Footing Volume, 20 MPa | C30: =ROUNDUP(4.23*1.1,0) -> 5 | D30: m3 | E30: =M32 -> 171.84 | F30: =C30*E30 -> 859.2 | H30: 0 | I30: =G30*H30 -> 0 | K30: =F30+I30+J30 -> 859.2 | L30: 25 MPa | M30: 178.74
A31: 03 30 03 | B31: Foundation Wall & Pilasters Volume, 25 MPa | C31: =ROUNDUP((14.6+2.48)*1.1,0) -> 19 | D31: m3 | E31: =M30 -> 178.74 | F31: =C31*E31 -> 3396.06 | H31: 0 | I31: =G31*H31 -> 0 | K31: =F31+I31+J31 -> 3396.06 | L31: 35 MPa | M31: 206.5
B32: 4" Concrete topping on Level 2 steel deck Volume, 25 MPa | C32: =ROUNDUP(1.9*1.1,0) -> 3 | D32: m3 | E32: =M30 -> 178.74 | F32: =C32*E32 -> 536.22 | H32: 0 | I32: =G32*H32 -> 0 | K32: =F32+I32+J32 -> 536.22 | L32: 20 MPa | M32: 171.84
A33: 03 30 04 | B33: Exterior Concrete Volume | D33: m3 | E33: 0 | F33: =C33*E33 -> 0 | H33: 0 | I33: =G33*H33 -> 0 | K33: =F33+I33+J33 -> 0 | L33: Pumping per hour | M33: 340 | N33: min. 4 hrs
D34: m3 | E34: 0 | F34: =C34*E34 -> 0 | H34: 0 | I34: =G34*H34 -> 0 | K34: =F34+I34+J34 -> 0 | L34: Pump charge per m3 | M34: 3
A35: 03 30 07 | B35: Pumping per hour | C35: 8 | D35: Hrs | E35: 270 | F35: =C35*E35 -> 2160 | H35: 0 | I35: =G35*H35 -> 0 | K35: =F35+I35+J35 -> 2160
A36: 03 30 04 | B36: Pump charge per m3 | C36: =SUM(C29:C34) -> 30 | D36: m3 | E36: 3 | F36: =C36*E36 -> 90 | H36: 0 | I36: =G36*H36 -> 0 | K36: =F36+I36+J36 -> 90
J37: Sub Total | K37: =SUM(K29:K36) -> 7577.7
A38: CODE | B38: DESCRIPTION | C38: Materials & Equipment | G38: Labor
A39: 03 35 00 | B39: Concrete Finishing | C39: Qty | D39: Unit | E39: U. Price | F39: Sub Total | G39: MHrs | H39: U. Price | I39: Sub Total | J39: Quote | K39: Total
B40: To place and power trowel finish concrete floors | C40: 588 | D40: LS | E40: 3.25 | F40: =C40*E40 -> 1911 | H40: 0 | I40: =G40*H40 -> 0 | K40: =F40+I40+J40 -> 1911
N41: =K37+K44 -> 9488.7
J44: Sub Total | K44: =SUM(K40:K43) -> 1911
A45: CODE | B45: DESCRIPTION | C45: Materials & Equipment | G45: Labor
A46: 03 40 00 | B46: Precast Concrete | C46: Qty | D46: Unit | E46: U. Price | F46: Sub Total | G46: MHrs | H46: U. Price | I46: Sub Total | J46: Quote | K46: Total
D47: LS | E47: 0 | F47: =C47*E47 -> 0 | H47: 0 | I47: =G47*H47 -> 0 | K47: =F47+I47+J47 -> 0
J49: Sub Total | K49: =SUM(K47:K48) -> 0
A50: CODE | B50: DESCRIPTION | C50: Materials & Equipment | G50: Labor
A51: 03 60 00 | B51: Foundation Materials | C51: Qty | D51: Unit | E51: U. Price | F51: Sub Total | G51: MHrs | H51: U. Price | I51: Sub Total | J51: Quote | K51: Total
A52: 03 60 01 | B52: Foundation Wall Insulation | C52: =ROUNDUP((495)/18,0) -> 28 | D52: sheet | E52: 28 | F52: =C52*E52 -> 784 | G52: =C52/5 -> 5.6 | H52: 65 | I52: =G52*H52 -> 364 | K52: =F52+I52+J52 -> 1148
...

Sheet 4
C1: ='Estimate Summary'!C1:H1 -> 0
G5: Masonry | J5: Schedule
D6: ='Estimate Summary'!C11 -> Area: | E6: ='Estimate Summary'!D11 -> 600 | F6: ='Estimate Summary'!E11 -> Sq. Ft. | J6: ='1'!J6 -> 15 | K6: Weeks
A11: CODE | B11: DESCRIPTION | C11: Materials & Equipment | G11: Labor | L11: Sub Contractor | M11: Quote Total | N11: Additional Quote Info
A12: 04 20 00 | B12: Unit Masonry | C12: Qty | D12: Unit | E12: U. Price | F12: Sub Total | G12: MHrs | H12: U. Price | I12: Sub Total | J12: Quote | K12: Total
B13: Masonry | D13: LS | F13: =C13*E13 -> 0 | H13: 0 | I13: =G13*H13 -> 0 | J13: =M15 -> 21700 | K13: =F13+I13+J13 -> 21700 | L13: JP Masonry | N13: to call
D14: LS | E14: 0 | F14: =C14*E14 -> 0 | H14: 0 | I14: =G14*H14 -> 0 | K14: =F14+I14+J14 -> 0 | L14: Ares Masonry | M14: 22900 | O14: =M15-M14 -> -1200 | P14: =O14/M15 -> -0.055299539
D15: LS | E15: 0 | F15: =C15*E15 -> 0 | H15: 0 | I15: =G15*H15 -> 0 | K15: =F15+I15+J15 -> 0 | L15: R.Mainville | M15: 21700 | N15: awarded
D16: LS | E16: 0 | F16: =C16*E16 -> 0 | H16: 0 | I16: =G16*H16 -> 0 | K16: =F16+I16+J16 -> 0 | L16: Wilson Masonry | M16: 25735
D17: LS | E17: 0 | F17: =C17*E17 -> 0 | H17: 0 | I17: =G17*H17 -> 0 | K17: =F17+I17+J17 -> 0
J19: Sub Total | K19: =SUM(K13:K18) -> 21700
A20: CODE | B20: DESCRIPTION | C20: Materials & Equipment | G20: Labor
A21: 04 43 00 | B21: Stone Masonry | C21: Qty | D21: Unit | E21: U. Price | F21: Sub Total | G21: MHrs | H21: U. Price | I21: Sub Total | J21: Quote | K21: Total
D22: LS | E22: 0 | F22: =C22*E22 -> 0 | H22: 0 | I22: =G22*H22 -> 0 | K22: =F22+I22+J22 -> 0
D23: LS | E23: 0 | F23: =C23*E23 -> 0 | H23: 0 | I23: =G23*H23 -> 0 | K23: =F23+I23+J23 -> 0
D24: LS | E24: 0 | F24: =C24*E24 -> 0 | H24: 0 | I24: =G24*H24 -> 0 | K24: =F24+I24+J24 -> 0
D25: LS | E25: 0 | F25: =C25*E25 -> 0 | H25: 0 | I25: =G25*H25 -> 0 | K25: =F25+I25+J25 -> 0
D26: LS | E26: 0 | F26: =C26*E26 -> 0 | H26: 0 | I26: =G26*H26 -> 0 | K26: =F26+I26+J26 -> 0
D27: LS | E27: 0 | F27: =C27*E27 -> 0 | H27: 0 | I27: =G27*H27 -> 0 | K27: =F27+I27+J27 -> 0
D28: LS | E28: 0 | F28: =C28*E28 -> 0 | H28: 0 | I28: =G28*H28 -> 0 | K28: =F28+I28+J28 -> 0
J30: Sub Total | K30: =SUM(K22:K29) -> 0
A31: CODE | B31: DESCRIPTION | C31: Materials & Equipment | G31: Labor
C32: Qty | D32: Unit | E32: U. Price | F32: Sub Total | G32: MHrs | H32: U. Price | I32: Sub Total | J32: Quote | K32: Total
D33: LS | E33: 0 | F33: =C33*E33 -> 0 | H33: 0 | I33: =G33*H33 -> 0 | K33: =F33+I33+J33 -> 0
D34: LS | E34: 0 | F34: =C34*E34 -> 0 | H34: 0 | I34: =G34*H34 -> 0 | K34: =F34+I34+J34 -> 0
D35: LS | E35: 0 | F35: =C35*E35 -> 0 | H35: 0 | I35: =G35*H35 -> 0 | K35: =F35+I35+J35 -> 0
J38: Sub Total | K38: =SUM(K33:K37) -> 0
A39: CODE | B39: DESCRIPTION | C39: Materials & Equipment | G39: Labor
C40: Qty | D40: Unit | E40: U. Price | F40: Sub Total | G40: MHrs | H40: U. Price | I40: Sub Total | J40: Quote | K40: Total
D41: LS | E41: 0 | F41: =C41*E41 -> 0 | H41: 0 | I41: =G41*H41 -> 0 | K41: =F41+I41+J41 -> 0
D42: LS | E42: 0 | F42: =C42*E42 -> 0 | H42: 0 | I42: =G42*H42 -> 0 | K42: =F42+I42+J42 -> 0
D43: LS | E43: 0 | F43: =C43*E43 -> 0 | H43: 0 | I43: =G43*H43 -> 0 | K43: =F43+I43+J43 -> 0
D44: LS | E44: 0 | F44: =C44*E44 -> 0 | H44: 0 | I44: =G44*H44 -> 0 | K44: =F44+I44+J44 -> 0
D45: LS | E45: 0 | F45: =C45*E45 -> 0 | H45: 0 | I45: =G45*H45 -> 0 | K45: =F45+I45+J45 -> 0
J47: Sub Total | K47: =SUM(K41:K46) -> 0
A48: CODE | B48: DESCRIPTION | C48: Materials & Equipment | G48: Labor
C49: Qty | D49: Unit | E49: U. Price | F49: Sub Total | G49: MHrs | H49: U. Price | I49: Sub Total | J49: Quote | K49: Total
D50: LS | E50: 0 | F50: =C50*E50 -> 0 | H50: 0 | I50: =G50*H50 -> 0 | K50: =F50+I50+J50 -> 0
D51: LS | E51: 0 | F51: =C51*E51 -> 0 | H51: 0 | I51: =G51*H51 -> 0 | K51: =F51+I51+J51 -> 0
D52: LS | E52: 0 | F52: =C52*E52 -> 0 | H52: 0 | I52: =G52*H52 -> 0 | K52: =F52+I52+J52 -> 0
...

Sheet 5
C1: ='Estimate Summary'!C1:H1 -> 0
G5: Metals | J5: Schedule
D6: ='Estimate Summary'!C11 -> Area: | E6: ='Estimate Summary'!D11 -> 600 | F6: ='Estimate Summary'!E11 -> Sq. Ft. | J6: ='1'!J6 -> 15 | K6: Weeks
A11: CODE | B11: DESCRIPTION | C11: Materials & Equipment | G11: Labor | L11: Sub Contractor | M11: Quote Total | N11: Additional Quote Info
A12: 05 12 00 | B12: Structural Steel Framing | C12: Qty | D12: Unit | E12: U. Price | F12: Sub Total | G12: MHrs | H12: U. Price | I12: Sub Total | J12: Quote | K12: Total
B13: Structural steel and deck | D13: LS | F13: =C13*E13 -> 0 | H13: 0 | I13: =G13*H13 -> 0 | J13: =M14 -> 64100 | K13: =F13+I13+J13 -> 64100 | L13: MSE | M13: 98341 | N13: confirmed to bid
B14: Lateral support | D14: LS | F14: =C14*E14 -> 0 | H14: 0 | I14: =G14*H14 -> 0 | K14: included | L14: Summit Steel | M14: 64100 | N14: awarded - $ 62,600 | O14: =98341-62600 -> 35741
B15: Shoring of one floor beam (beam to remain during demo by others) | D15: LS | E15: 0 | F15: =C15*E15 -> 0 | H15: 0 | I15: =G15*H15 -> 0 | K15: included | O15: =+O14/62600 -> 0.57094249
B16: Hoist beam to be clarified if included - Yes for summit | D16: LS | E16: 0 | F16: =C16*E16 -> 0 | H16: 0 | I16: =G16*H16 -> 0 | K16: included
D17: LS | E17: 0 | F17: =C17*E17 -> 0 | H17: 0 | I17: =G17*H17 -> 0 | K17: =F17+I17+J17 -> 0
J19: Sub Total | K19: =SUM(K13:K18) -> 64100
A20: CODE | B20: DESCRIPTION | C20: Materials & Equipment | G20: Labor
A21: 05 20 00 | B21: Metal Joists | C21: Qty | D21: Unit | E21: U. Price | F21: Sub Total | G21: MHrs | H21: U. Price | I21: Sub Total | J21: Quote | K21: Total
D22: LS | E22: 0 | F22: =C22*E22 -> 0 | H22: 0 | I22: =G22*H22 -> 0 | K22: =F22+I22+J22 -> 0
D23: LS | E23: 0 | F23: =C23*E23 -> 0 | H23: 0 | I23: =G23*H23 -> 0 | K23: =F23+I23+J23 -> 0
D24: LS | E24: 0 | F24: =C24*E24 -> 0 | H24: 0 | I24: =G24*H24 -> 0 | K24: =F24+I24+J24 -> 0
D25: LS | E25: 0 | F25: =C25*E25 -> 0 | H25: 0 | I25: =G25*H25 -> 0 | K25: =F25+I25+J25 -> 0
D26: LS | E26: 0 | F26: =C26*E26 -> 0 | H26: 0 | I26: =G26*H26 -> 0 | K26: =F26+I26+J26 -> 0
D27: LS | E27: 0 | F27: =C27*E27 -> 0 | H27: 0 | I27: =G27*H27 -> 0 | K27: =F27+I27+J27 -> 0
J29: Sub Total | K29: =SUM(K22:K28) -> 0
A30: CODE | B30: DESCRIPTION | C30: Materials & Equipment | G30: Labor
A31: 05 30 00 | B31: Metal Decking | C31: Qty | D31: Unit | E31: U. Price | F31: Sub Total | G31: MHrs | H31: U. Price | I31: Sub Total | J31: Quote | K31: Total
D32: LS | E32: 0 | F32: =C32*E32 -> 0 | H32: 0 | I32: =G32*H32 -> 0 | K32: =F32+I32+J32 -> 0
D33: LS | E33: 0 | F33: =C33*E33 -> 0 | H33: 0 | I33: =G33*H33 -> 0 | K33: =F33+I33+J33 -> 0
D34: LS | E34: 0 | F34: =C34*E34 -> 0 | H34: 0 | I34: =G34*H34 -> 0 | K34: =F34+I34+J34 -> 0
J37: Sub Total | K37: =SUM(K32:K36) -> 0
A38: CODE | B38: DESCRIPTION | C38: Materials & Equipment | G38: Labor
A39: 05 51 00 | B39: Metal Stairs | C39: Qty | D39: Unit | E39: U. Price | F39: Sub Total | G39: MHrs | H39: U. Price | I39: Sub Total | J39: Quote | K39: Total
D40: LS | E40: 0 | F40: =C40*E40 -> 0 | H40: 0 | I40: =G40*H40 -> 0 | K40: =F40+I40+J40 -> 0
D41: LS | E41: 0 | F41: =C41*E41 -> 0 | H41: 0 | I41: =G41*H41 -> 0 | K41: =F41+I41+J41 -> 0
D42: LS | E42: 0 | F42: =C42*E42 -> 0 | H42: 0 | I42: =G42*H42 -> 0 | K42: =F42+I42+J42 -> 0
D43: LS | E43: 0 | F43: =C43*E43 -> 0 | H43: 0 | I43: =G43*H43 -> 0 | K43: =F43+I43+J43 -> 0
D44: LS | E44: 0 | F44: =C44*E44 -> 0 | H44: 0 | I44: =G44*H44 -> 0 | K44: =F44+I44+J44 -> 0
J46: Sub Total | K46: =SUM(K40:K45) -> 0
A47: CODE | B47: DESCRIPTION | C47: Materials & Equipment | G47: Labor
A48: 05 52 00 | B48: Metal Railings | C48: Qty | D48: Unit | E48: U. Price | F48: Sub Total | G48: MHrs | H48: U. Price | I48: Sub Total | J48: Quote | K48: Total
D49: LS | E49: 0 | F49: =C49*E49 -> 0 | H49: 0 | I49: =G49*H49 -> 0 | K49: =F49+I49+J49 -> 0
D50: LS | E50: 0 | F50: =C50*E50 -> 0 | H50: 0 | I50: =G50*H50 -> 0 | K50: =F50+I50+J50 -> 0
D51: LS | E51: 0 | F51: =C51*E51 -> 0 | H51: 0 | I51: =G51*H51 -> 0 | K51: =F51+I51+J51 -> 0
D52: LS | E52: 0 | F52: =C52*E52 -> 0 | H52: 0 | I52: =G52*H52 -> 0 | K52: =F52+I52+J52 -> 0
...

Sheet 6
C1: ='Estimate Summary'!C1:H1 -> 0
G5: Wood & Plastics | J5: Schedule
D6: ='Estimate Summary'!C11 -> Area: | E6: ='Estimate Summary'!D11 -> 600 | F6: ='Estimate Summary'!E11 -> Sq. Ft. | J6: ='1'!J6 -> 15 | K6: Weeks
A9: CODE | B9: DESCRIPTION | C9: Materials & Equipment | G9: Labor | L9: Sub Contractor | M9: Quote Total | N9: Additional Quote Info
A10: 06 11 00 | B10: Framing Labour | C10: Qty | D10: Unit | E10: U. Price | F10: Sub Total | G10: MHrs | H10: U. Price | I10: Sub Total | J10: Quote | K10: Total
H11: 0 | I11: =G11*H11 -> 0 | K11: =F11+I11+J11 -> 0
H12: 0 | I12: =G12*H12 -> 0 | K12: =F12+I12+J12 -> 0
H13: 0 | I13: =G13*H13 -> 0 | K13: =F13+I13+J13 -> 0
H14: 0 | I14: =G14*H14 -> 0 | K14: =F14+I14+J14 -> 0
H15: 0 | I15: =G15*H15 -> 0 | K15: =F15+I15+J15 -> 0
H16: 0 | I16: =G16*H16 -> 0 | K16: =F16+I16+J16 -> 0
H17: 0 | I17: =G17*H17 -> 0 | K17: =F17+I17+J17 -> 0
J19: Sub Total | K19: =SUM(K11:K18) -> 0
A20: 06 20 00 | B20: Framing Materials | C20: Qty | D20: Unit | E20: U. Price | F20: Sub Total | J20: Quote | K20: Total
B22: 2x4 Stud | D22: ft | E22: 0.5 | F22: =C22*E22 -> 0 | K22: =F22+I22+J22 -> 0
B23: 2x6 Stud | D23: ft | E23: 0.81 | F23: =C23*E23 -> 0 | K23: =F23+I23+J23 -> 0
B24: 2x8 | D24: ft | E24: 1.24 | F24: =C24*E24 -> 0 | K24: =F24+I24+J24 -> 0
B25: 2x10 | D25: ft | E25: 1.61 | F25: =C25*E25 -> 0 | K25: =F25+I25+J25 -> 0
B26: 1x3 | D26: ft | E26: 0.25 | F26: =C26*E26 -> 0 | K26: =F26+I26+J26 -> 0
B27: 1x4 | D27: ft | E27: 0.37 | F27: =C27*E27 -> 0 | K27: =F27+I27+J27 -> 0
B28: PLYWOOD | K28: =F28+I28+J28 -> 0
B29: 1/2" Standard | D29: EA | E29: 30.65 | F29: =C29*E29 -> 0 | K29: =F29+I29+J29 -> 0
B30: 5/8" Standard | D30: EA | E30: 43.69 | F30: =C30*E30 -> 0 | K30: =F30+I30+J30 -> 0
B31: 3/4" Standard | D31: EA | E31: 47.47 | F31: =C31*E31 -> 0 | K31: =F31+I31+J31 -> 0
B33: 5/8" OSB T&G | D33: EA | E33: 22.74 | F33: =C33*E33 -> 0 | K33: =F33+I33+J33 -> 0
J36: Sub Total | K36: =SUM(K21:K35) -> 0
A37: CODE | B37: DESCRIPTION | C37: Materials & Equipment | G37: Labor
A38: 06 22 00 | B38: Millwork | C38: Qty | D38: Unit | E38: U. Price | F38: Sub Total | G38: MHrs | H38: U. Price | I38: Sub Total | J38: Quote | K38: Total
D39: LS | E39: 0 | F39: =C39*E39 -> 0 | H39: 0 | I39: =G39*H39 -> 0 | K39: =F39+I39+J39 -> 0
D40: LS | E40: 0 | F40: =C40*E40 -> 0 | H40: 0 | I40: =G40*H40 -> 0 | K40: =F40+I40+J40 -> 0
D41: LS | E41: 0 | F41: =C41*E41 -> 0 | H41: 0 | I41: =G41*H41 -> 0 | K41: =F41+I41+J41 -> 0
D42: LS | E42: 0 | F42: =C42*E42 -> 0 | H42: 0 | I42: =G42*H42 -> 0 | K42: =F42+I42+J42 -> 0
D43: LS | E43: 0 | F43: =C43*E43 -> 0 | H43: 0 | I43: =G43*H43 -> 0 | K43: =F43+I43+J43 -> 0
D44: LS | E44: 0 | F44: =C44*E44 -> 0 | H44: 0 | I44: =G44*H44 -> 0 | K44: =F44+I44+J44 -> 0
D45: LS | E45: 0 | F45: =C45*E45 -> 0 | H45: 0 | I45: =G45*H45 -> 0 | K45: =F45+I45+J45 -> 0
J47: Sub Total | K47: =SUM(K39:K46) -> 0
A48: CODE | B48: DESCRIPTION | C48: Materials & Equipment | G48: Labor
A49: 06 41 00 | B49: Architechtural Wood Casework | C49: Qty | D49: Unit | E49: U. Price | F49: Sub Total | G49: MHrs | H49: U. Price | I49: Sub Total | J49: Quote | K49: Total
D50: LS | E50: 0 | F50: =C50*E50 -> 0 | H50: 0 | I50: =G50*H50 -> 0 | K50: =F50+I50+J50 -> 0
D51: LS | E51: 0 | F51: =C51*E51 -> 0 | H51: 0 | I51: =G51*H51 -> 0 | K51: =F51+I51+J51 -> 0
...

Sheet 7
C1: ='Estimate Summary'!C1:H1 -> 0
G5: Thermal & Moisture Protection | J5: Schedule
D6: ='Estimate Summary'!C11 -> Area: | E6: ='Estimate Summary'!D11 -> 600 | F6: ='Estimate Summary'!E11 -> Sq. Ft. | J6: ='1'!J6 -> 15 | K6: Weeks
A9: CODE | B9: DESCRIPTION | C9: Materials & Equipment | G9: Labor | L9: Sub Contractor | M9: Quote Total | N9: Additional Quote Info
A10: 07 21 00 | B10: Thermal Insulation | C10: Qty | D10: Unit | E10: U. Price | F10: Sub Total | G10: MHrs | H10: U. Price | I10: Sub Total | J10: Quote | K10: Total
A11: 07 21 16 | B11: Blanket Insulation | D11: LS | E11: 0 | F11: =C11*E11 -> 0 | H11: 0 | I11: =G11*H11 -> 0 | K11: =F11+I11+J11 -> 0
A12: 07 21 26 | B12: Blown Insulation | D12: LS | E12: 0 | F12: =C12*E12 -> 0 | H12: 0 | I12: =G12*H12 -> 0 | K12: =F12+I12+J12 -> 0
A13: 07 21 29 | B13: Sprayed Insulation | D13: LS | E13: 0 | F13: =C13*E13 -> 0 | H13: 0 | I13: =G13*H13 -> 0 | K13: =F13+I13+J13 -> 0
D14: LS | E14: 0 | F14: =C14*E14 -> 0 | H14: 0 | I14: =G14*H14 -> 0 | K14: =F14+I14+J14 -> 0
J16: Sub Total | K16: =SUM(K11:K15) -> 0
A17: CODE | B17: DESCRIPTION | C17: Materials & Equipment | G17: Labor
A18: 07 24 00 | B18: EIFS | C18: Qty | D18: Unit | E18: U. Price | F18: Sub Total | G18: MHrs | H18: U. Price | I18: Sub Total | J18: Quote | K18: Total
D19: LS | E19: 0 | F19: =C19*E19 -> 0 | H19: 0 | I19: =G19*H19 -> 0 | K19: =F19+I19+J19 -> 0
D20: LS | E20: 0 | F20: =C20*E20 -> 0 | H20: 0 | I20: =G20*H20 -> 0 | K20: =F20+I20+J20 -> 0
D21: LS | E21: 0 | F21: =C21*E21 -> 0 | H21: 0 | I21: =G21*H21 -> 0 | K21: =F21+I21+J21 -> 0
J22: Sub Total | K22: =SUM(K19:K21) -> 0
A23: CODE | B23: DESCRIPTION | C23: Materials & Equipment | G23: Labor
A24: 07 31 00 | B24: Shingles | C24: Qty | D24: Unit | E24: U. Price | F24: Sub Total | G24: MHrs | H24: U. Price | I24: Sub Total | J24: Quote | K24: Total
D25: LS | E25: 0 | F25: =C25*E25 -> 0 | H25: 0 | I25: =G25*H25 -> 0 | K25: =F25+I25+J25 -> 0
D26: LS | E26: 0 | F26: =C26*E26 -> 0 | H26: 0 | I26: =G26*H26 -> 0 | K26: =F26+I26+J26 -> 0
J27: Sub Total | K27: =SUM(K25:K26) -> 0
A28: CODE | B28: DESCRIPTION | C28: Materials & Equipment | G28: Labor
A29: 07 42 00 | B29: Wall Panels | C29: Qty | D29: Unit | E29: U. Price | F29: Sub Total | G29: MHrs | H29: U. Price | I29: Sub Total | J29: Quote | K29: Total
D30: LS | E30: 0 | F30: =C30*E30 -> 0 | H30: 0 | I30: =G30*H30 -> 0 | K30: =F30+I30+J30 -> 0
D31: LS | E31: 0 | F31: =C31*E31 -> 0 | H31: 0 | I31: =G31*H31 -> 0 | K31: =F31+I31+J31 -> 0
D32: LS | E32: 0 | F32: =C32*E32 -> 0 | H32: 0 | I32: =G32*H32 -> 0 | K32: =F32+I32+J32 -> 0 | L32: Steelco Ind | M32: 138290
J33: Sub Total | K33: =SUM(K30:K32) -> 0
A34: CODE | B34: DESCRIPTION | C34: Materials & Equipment | G34: Labor
A35: 07 46 00 | B35: Siding | C35: Qty | D35: Unit | E35: U. Price | F35: Sub Total | G35: MHrs | H35: U. Price | I35: Sub Total | J35: Quote | K35: Total
B36: Siding | D36: SF | F36: =C36*E36 -> 0 | H36: 0 | I36: =G36*H36 -> 0 | J36: =M40 -> 77450 | K36: =F36+I36+J36 -> 77450 | L36: Altiro Siding | M36: 8900 | N36: Installation only
L37: PLG Builders | N37: confirmed to bid
D38: LS | E38: 0 | F38: =C38*E38 -> 0 | H38: 0 | I38: =G38*H38 -> 0 | K38: =F38+I38+J38 -> 0 | L38: Steelco Ind | M38: 138290 | N38: add $4,750 plus HST for Engineered Stamp Shop Drawings
D39: LS | E39: 0 | F39: =C39*E39 -> 0 | H39: 0 | I39: =G39*H39 -> 0 | K39: =F39+I39+J39 -> 0 | L39: Atlantic Metaclad | M39: 122500
B40: Flashing captured in roofing | D40: LS | E40: 0 | F40: =C40*E40 -> 0 | H40: 0 | I40: =G40*H40 -> 0 | K40: =F40+I40+J40 -> 0 | L40: Clad-Tech | M40: 77450 | N40: No flashing
D41: LS | E41: 0 | F41: =C41*E41 -> 0 | H41: 0 | I41: =G41*H41 -> 0 | K41: =F41+I41+J41 -> 0
D42: LS | E42: 0 | F42: =C42*E42 -> 0 | H42: 0 | I42: =G42*H42 -> 0 | K42: =F42+I42+J42 -> 0
B43: Siding (if the existing bricks will be removed) | D43: SF | F43: =C43*E43 -> 0 | H43: 0 | I43: =G43*H43 -> 0 | K43: =F43+I43+J43 -> 0 | L43: no details and specification yet (awaiting KUB response)
D44: LS | E44: 0 | F44: =C44*E44 -> 0 | H44: 0 | I44: =G44*H44 -> 0 | K44: =F44+I44+J44 -> 0
J45: Sub Total | K45: =SUM(K36:K44) -> 77450
A46: CODE | B46: DESCRIPTION | C46: Materials & Equipment | G46: Labor
...

Sheet 8
C1: ='Estimate Summary'!C1:H1 -> 0
G5: Openings | J5: Schedule
D6: ='Estimate Summary'!C11 -> Area: | E6: ='Estimate Summary'!D11 -> 600 | F6: ='Estimate Summary'!E11 -> Sq. Ft. | J6: ='1'!J6 -> 15 | K6: Weeks
A11: CODE | B11: DESCRIPTION | C11: Materials & Equipment | G11: Labor | L11: Sub Contractor | M11: Quote Total | N11: Additional Quote Info
A12: 08 11 00 | B12: Metal Doors and Frames | C12: Qty | D12: Unit | E12: U. Price | F12: Sub Total | G12: MHrs | H12: U. Price | I12: Sub Total | J12: Quote | K12: Total
A13: 08 11 13 | B13: Metal Doors and Frames | C13: 3 | D13: EA | F13: =C13*E13 -> 0 | G13: =C13*2 -> 6 | H13: 65 | I13: =G13*H13 -> 390 | J13: =M13 -> 71510 | K13: =F13+I13+J13 -> 71900 | L13: All Access Entrance Sol. | M13: 71510 | N13: Curtain walls + HM doors; will save $4,925.62 with alternative door operator
A14: 08 11 16 | B14: Aluminum Doors and Frames | D14: LS | E14: 0 | F14: =C14*E14 -> 0 | H14: 0 | I14: =G14*H14 -> 0 | K14: =F14+I14+J14 -> 0 | L14: Advantage Hardware | M14: 29650 | N14: 3Doors + 5Hardware
B15: Frame install for daycare door | C15: 1 | D15: EA | E15: 0 | F15: =C15*E15 -> 0 | G15: 2 | H15: 65 | I15: =G15*H15 -> 130 | K15: =F15+I15+J15 -> 130 | L15: Coastal Entrance | M15: 33085 | N15: 3Doors + 5Hardware
D16: LS | E16: 0 | F16: =C16*E16 -> 0 | H16: 0 | I16: =G16*H16 -> 0 | K16: =F16+I16+J16 -> 0
J18: Sub Total | K18: =SUM(K13:K17) -> 72030
A19: CODE | B19: DESCRIPTION | C19: Materials & Equipment | G19: Labor
A20: 08 14 00 | B20: Wood Doors | C20: Qty | D20: Unit | E20: U. Price | F20: Sub Total | G20: MHrs | H20: U. Price | I20: Sub Total | J20: Quote | K20: Total
D21: LS | E21: 0 | F21: =C21*E21 -> 0 | H21: 0 | I21: =G21*H21 -> 0 | K21: =F21+I21+J21 -> 0
D22: LS | E22: 0 | F22: =C22*E22 -> 0 | H22: 0 | I22: =G22*H22 -> 0 | K22: =F22+I22+J22 -> 0
D23: LS | E23: 0 | F23: =C23*E23 -> 0 | H23: 0 | I23: =G23*H23 -> 0 | K23: =F23+I23+J23 -> 0
J24: Sub Total | K24: =SUM(K21:K23) -> 0
A25: CODE | B25: DESCRIPTION | C25: Materials & Equipment | G25: Labor
A26: 08 31 00 | B26: Access Doors and Panels | C26: Qty | D26: Unit | E26: U. Price | F26: Sub Total | G26: MHrs | H26: U. Price | I26: Sub Total | J26: Quote | K26: Total
D27: LS | E27: 0 | F27: =C27*E27 -> 0 | H27: 0 | I27: =G27*H27 -> 0 | K27: =F27+I27+J27 -> 0
D28: LS | E28: 0 | F28: =C28*E28 -> 0 | H28: 0 | I28: =G28*H28 -> 0 | K28: =F28+I28+J28 -> 0
J29: Sub Total | K29: =SUM(K27:K28) -> 0
A30: CODE | B30: DESCRIPTION | C30: Materials & Equipment | G30: Labor
A31: 08 32 00 | B31: Sliding Gates | C31: Qty | D31: Unit | E31: U. Price | F31: Sub Total | G31: MHrs | H31: U. Price | I31: Sub Total | J31: Quote | K31: Total
D32: LS | E32: 0 | F32: =C32*E32 -> 0 | H32: 0 | I32: =G32*H32 -> 0 | K32: =F32+I32+J32 -> 0
D33: LS | E33: 0 | F33: =C33*E33 -> 0 | H33: 0 | I33: =G33*H33 -> 0 | K33: =F33+I33+J33 -> 0
D34: LS | E34: 0 | F34: =C34*E34 -> 0 | H34: 0 | I34: =G34*H34 -> 0 | K34: =F34+I34+J34 -> 0
J35: Sub Total | K35: =SUM(K32:K34) -> 0
A36: CODE | B36: DESCRIPTION | C36: Materials & Equipment | G36: Labor
A37: 08 33 00 | B37: Coiling Doors and Drilles | C37: Qty | D37: Unit | E37: U. Price | F37: Sub Total | G37: MHrs | H37: U. Price | I37: Sub Total | J37: Quote | K37: Total
D38: LS | E38: 0 | F38: =C38*E38 -> 0 | H38: 0 | I38: =G38*H38 -> 0 | K38: =F38+I38+J38 -> 0
D39: LS | E39: 0 | F39: =C39*E39 -> 0 | H39: 0 | I39: =G39*H39 -> 0 | K39: =F39+I39+J39 -> 0
D40: LS | E40: 0 | F40: =C40*E40 -> 0 | H40: 0 | I40: =G40*H40 -> 0 | K40: =F40+I40+J40 -> 0
J41: Sub Total | K41: =SUM(K38:K40) -> 0
A42: CODE | B42: DESCRIPTION | C42: Materials & Equipment | G42: Labor
A43: 08 34 00 | B43: Special Function Doors | C43: Qty | D43: Unit | E43: U. Price | F43: Sub Total | G43: MHrs | H43: U. Price | I43: Sub Total | J43: Quote | K43: Total
D44: LS | E44: 0 | F44: =C44*E44 -> 0 | H44: 0 | I44: =G44*H44 -> 0 | K44: =F44+I44+J44 -> 0
D45: LS | E45: 0 | F45: =C45*E45 -> 0 | H45: 0 | I45: =G45*H45 -> 0 | K45: =F45+I45+J45 -> 0
D46: LS | E46: 0 | F46: =C46*E46 -> 0 | H46: 0 | I46: =G46*H46 -> 0 | K46: =F46+I46+J46 -> 0
J47: Sub Total | K47: =SUM(K44:K46) -> 0
A48: CODE | B48: DESCRIPTION | C48: Materials & Equipment | G48: Labor
...

Sheet 9
C1: ='Estimate Summary'!C1:H1 -> 0
G5: Finishes | J5: Schedule
D6: ='Estimate Summary'!C11 -> Area: | E6: ='Estimate Summary'!D11 -> 600 | F6: ='Estimate Summary'!E11 -> Sq. Ft. | J6: ='1'!J6 -> 15 | K6: Weeks
A9: CODE | B9: DESCRIPTION | C9: Materials & Equipment | G9: Labor | L9: Sub Contractor | M9: Quote Total | N9: Additional Quote Info
A10: 09 20 00 | B10: Plaster and Gypsum Board | C10: Qty | D10: Unit | E10: U. Price | F10: Sub Total | G10: MHrs | H10: U. Price | I10: Sub Total | J10: Quote | K10: Total
B11: Drywall Works | C11: 1 | D11: LS | E11: 0 | F11: =C11*E11 -> 0 | H11: 0 | I11: =G11*H11 -> 0 | J11: =M11 -> 36493.72 | K11: =F11+I11+J11 -> 36493.72 | L11: Fundy Pros | M11: 36493.72
L12: AU Living | M12: 70000 | N12: Drywall/ceiling + Painting + Demolition
L13: AD Restore | M13: 47000.47
L14: Arsenault Bros | M14: 64390
L15: Premium Drywall | M15: 74750
L17: City Reno
L18: Drywall | M18: 29995
L19: Painting | M19: 2954
J25: Sub Total | K25: =SUM(K11:K24) -> 36493.72
A26: CODE | B26: DESCRIPTION | C26: Materials & Equipment | G26: Labor
A27: 09 30 00 | B27: Tiling | C27: Qty | D27: Unit | E27: U. Price | F27: Sub Total | G27: MHrs | H27: U. Price | I27: Sub Total | J27: Quote | K27: Total
D28: SF | E28: 0 | F28: =C28*E28 -> 0 | H28: 0 | I28: =G28*H28 -> 0 | K28: =F28+I28+J28 -> 0
D29: SF | E29: 0 | F29: =C29*E29 -> 0 | H29: 0 | I29: =G29*H29 -> 0 | K29: =F29+I29+J29 -> 0
D30: SF | E30: 0 | F30: =C30*E30 -> 0 | H30: 0 | I30: =G30*H30 -> 0 | K30: =F30+I30+J30 -> 0
D31: SF | E31: 0 | F31: =C31*E31 -> 0 | H31: 0 | I31: =G31*H31 -> 0 | K31: =F31+I31+J31 -> 0
J33: Sub Total | K33: =SUM(K28:K32) -> 0
A34: CODE | B34: DESCRIPTION | C34: Materials & Equipment | G34: Labor
A35: 09 50 00 | B35: Ceiling | C35: Qty | D35: Unit | E35: U. Price | F35: Sub Total | G35: MHrs | H35: U. Price | I35: Sub Total | J35: Quote | K35: Total
D36: SF | E36: 0 | F36: =C36*E36 -> 0 | H36: 0 | I36: =G36*H36 -> 0 | K36: =F36+I36+J36 -> 0
D37: SF | E37: 0 | F37: =C37*E37 -> 0 | H37: 0 | I37: =G37*H37 -> 0 | K37: =F37+I37+J37 -> 0
J39: Sub Total | K39: =SUM(K36:K38) -> 0
A40: CODE | B40: DESCRIPTION | C40: Materials & Equipment | G40: Labor
A41: 09 60 00 | B41: Flooring | C41: Qty | D41: Unit | E41: U. Price | F41: Sub Total | G41: MHrs | H41: U. Price | I41: Sub Total | J41: Quote | K41: Total
A42: 09 61 00 | B42: Concrete Floor Polishing | D42: SF | E42: 0 | F42: =C42*E42 -> 0 | H42: 0 | I42: =G42*H42 -> 0 | K42: =F42+I42+J42 -> 0
D43: SF | E43: 0 | F43: =C43*E43 -> 0 | H43: 0 | I43: =G43*H43 -> 0 | J43: =M49 -> 19250 | K43: =F43+I43+J43 -> 19250 | L43: Coastal/Primo | M43: 23250 | N43: confirmed to bid
A44: 09 62 00 | B44: Specialty Flooring | D44: SF | E44: 0 | F44: =C44*E44 -> 0 | H44: 0 | I44: =G44*H44 -> 0 | K44: =F44+I44+J44 -> 0 | L44: Floor Doctor | M44: 23384.85 | N44: confirmed to bid
A45: 09 64 00 | B45: Wood Flooring | D45: SF | E45: 0 | F45: =C45*E45 -> 0 | H45: 0 | I45: =G45*H45 -> 0 | K45: =F45+I45+J45 -> 0 | L45: Floors Plus Commercial | M45: 25015
A46: 09 65 00 | B46: VCT | D46: SF | E46: 0 | F46: =C46*E46 -> 0 | H46: 0 | I46: =G46*H46 -> 0 | K46: =F46+I46+J46 -> 0
A47: 09 67 00 | B47: LVT | D47: SF | E47: 0 | F47: =C47*E47 -> 0 | H47: 0 | I47: =G47*H47 -> 0 | K47: =F47+I47+J47 -> 0 | L47: Ritchie's | M47: 14000 | N47: Treads not included
A48: 09 68 00 | B48: Carpet Tile | D48: SF | E48: 0 | F48: =C48*E48 -> 0 | H48: 0 | I48: =G48*H48 -> 0 | K48: =F48+I48+J48 -> 0 | M48: 5250 | N48: Tread only
B49: Flooring to elevator cab | D49: SF | F49: =C49*E49 -> 0 | H49: 0 | I49: =G49*H49 -> 0 | K49: =F49+I49+J49 -> 0 | M49: =SUM(M47:M48) -> 19250
B50: Flooring to elevator lobby | D50: SF | F50: =C50*E50 -> 0 | H50: 0 | I50: =G50*H50 -> 0 | K50: =F50+I50+J50 -> 0
J52: Sub Total | K52: =SUM(K42:K51) -> 19250
A53: CODE | B53: DESCRIPTION | C53: Materials & Equipment | G53: Labor
A54: 09 72 00 | B54: Wall Coverings | C54: Qty | D54: Unit | E54: U. Price | F54: Sub Total | G54: MHrs | H54: U. Price | I54: Sub Total | J54: Quote | K54: Total
...

Sheet 10
C1: ='Estimate Summary'!C1:H1 -> 0
G5: Specalties | J5: Schedule
D6: ='Estimate Summary'!C11 -> Area: | E6: ='Estimate Summary'!D11 -> 600 | F6: ='Estimate Summary'!E11 -> Sq. Ft. | J6: ='1'!J6 -> 15 | K6: Weeks
A9: CODE | B9: DESCRIPTION | C9: Materials & Equipment | G9: Labor | L9: Sub Contractor | M9: Quote Total | N9: Additional Quote Info
A10: 10 11 00 | B10: Visual Display Units | C10: Qty | D10: Unit | E10: U. Price | F10: Sub Total | G10: MHrs | H10: U. Price | I10: Sub Total | J10: Quote | K10: Total
D11: LS | E11: 0 | F11: =C11*E11 -> 0 | H11: 0 | I11: =G11*H11 -> 0 | K11: =F11+I11+J11 -> 0
D12: LS | E12: 0 | F12: =C12*E12 -> 0 | H12: 0 | I12: =G12*H12 -> 0 | K12: =F12+I12+J12 -> 0
D13: LS | E13: 0 | F13: =C13*E13 -> 0 | H13: 0 | I13: =G13*H13 -> 0 | K13: =F13+I13+J13 -> 0
D14: LS | E14: 0 | F14: =C14*E14 -> 0 | H14: 0 | I14: =G14*H14 -> 0 | K14: =F14+I14+J14 -> 0
