Workbook
Name Discount: #REF!
Name Discount: #REF!
Name Discount: #REF!
Name Discount: #REF!
Name Discount: #REF!
Name Discount: #REF!
Name Discount: #REF!
Name Discount: #REF!
Name Discount: #REF!
Name Discount: #REF!
Name Discount: #REF!
Name Discount: #REF!
Name Discount: #REF!
Name Discount: #REF!
Name Discount: #REF!

Sheet Cost Data
A1: Division | B1: 2
B2: 01 00 00 | C2: General Requirements
B3: 01 11 00 | C3: Preconstruction Costs | D3: ='1'!K24 -> 0
B4: 01 31 00 | C4: Project Management and Coordination | D4: ='1'!K35 -> 183350
B5: 01 41 00 | C5: Permits | D5: ='1'!K67 -> 17078.206
B6: 01 45 00 | C6: Quality Control | D6: ='1'!K76 -> 8000
B7: 01 51 00 | C7: Temporary Utilities | D7: ='1'!K87 -> 5700
B8: 01 52 00 | C8: Construction Facilities | D8: ='1'!K97 -> 14495.395
B9: 01 54 00 | C9: Construction Aids | D9: ='1'!K105 -> 12471.036
B10: 01 56 00 | C10: Temporary Barriers & Enclosures | D10: ='1'!K128 -> 22425
B11: 01 74 00 | C11: Cleaning & Waste Management | D11: ='1'!K136 -> 19859
A13: Division | B13: 2
B15: 02 00 00 | C15: Existing Conditions
B16: 02 41 00 | C16: Demolition | D16: ='2'!K26 -> 3600
B17: 02 82 00 | C17: Asbestos Remediation | D17: ='2'!K37 -> 0
B18: 02 83 00 | C18: Trenching | D18: ='2'!K48 -> 0
A21: Division | B21: 3
B22: 03 00 00 | C22: Concrete
B23: 03 11 00 | C23: Concrete Forming | D23: ='3'!K26 -> 56820
B24: 03 20 00 | C24: Concrete Reinforcing | D24: ='3'!K37 -> 25280
B25: 03 30 00 | C25: Cast-in-Place Concrete | D25: ='3'!K52 -> 26603.125
B26: 03 35 00 | C26: Concrete Finishing | D26: ='3'!K65 -> 10447.2
B27: 03 40 00 | C27: Precast Concrete | D27: ='3'!K76 -> 0
B28: 03 60 00 | C28: Grouting | D28: ='3'!K85 -> 23375.294
A31: Division | B31: 4
B32: 04 00 00 | C32: Masonry
B33: 04 20 00 | C33: Unit Masonry | D33: ='4'!K26 -> 0
B34: 04 43 00 | C34: Stone Masonry | D34: ='4'!K37 -> 0
A36: Division | B36: 5
B37: 05 00 00 | C37: Metals
B38: 05 12 00 | C38: Structural Steel Framing | D38: ='5'!K26 -> 0
B39: 05 20 00 | C39: Metal Joists | D39: ='5'!K37 -> 0
B40: 05 30 00 | C40: Metal Decking | D40: ='5'!K45 -> 0
B41: 05 51 00 | C41: Metal Stairs | D41: ='5'!K54 -> 0
B42: 05 52 00 | C42: Metal Railings | D42: ='5'!K65 -> 0
B43: 05 59 00 | C43: Metal Specialties | D43: ='5'!K74 -> 0
A46: Division | B46: 6
B47: 06 00 00 | C47: Wood, Plastics, and Composites
B48: 06 11 00 | C48: Framing | D48: ='6'!K29 -> 120000
B49: 06 20 00 | C49: Finish Carpentry | D49: ='6'!K76 -> 92676.18
...

Sheet Cost Report
B1: Division | C1: Sub - Division | D1: Discription | E1: Cost
B2: 01 00 00 | D2: General Requirements | E2: ='Estimate Summary'!H15 -> 353890.15
B3: 01 11 00 | D3: Preconstruction Costs | E3: ='1'!K24 -> 0
B4: 01 31 00 | D4: Project Management and Coordination | E4: ='1'!K35 -> 183350
B5: 01 31 00 | C5: 01 31 01 | D5: Senior Construction Manager | E5: ='1'!K27 -> 0
B6: 01 31 00 | C6: 01 31 02 | D6: Senior Estimator | E6: ='1'!K28 -> 0
B7: 01 31 00 | C7: 01 31 03 | D7: Senior Project Manager | E7: ='1'!K29 -> 38000
B8: 01 31 00 | C8: 01 31 04 | D8: Project Coordinator | E8: ='1'!K30 -> 0
B9: 01 31 00 | C9: 01 31 05 | D9: Project Superintendent | E9: ='1'!K31 -> 145350
B10: 01 31 00 | C10: 01 31 06 | D10: Project Foreman | E10: ='1'!K32 -> 0
B11: 01 32 00 | C11: 01 32 00 | D11: Travel
B12: 01 41 00 | D12: Permits | E12: ='1'!K67 -> 17078.206
B13: 01 45 00 | D13: Quality Control | E13: ='1'!K76 -> 8000
B14: 01 51 00 | D14: Temporary Utilities | E14: ='1'!K87 -> 5700
B15: 01 52 00 | D15: Construction Facilities | E15: ='1'!K97 -> 14495.395
B16: 01 52 00 | C16: 01 52 01 | D16: Construction Field Office | E16: ='1'!K90 -> 7125
B17: 01 52 00 | C17: 01 52 02 | D17: Sanitary Facilities | E17: ='1'!K92 -> 1900
B18: 01 52 00 | C18: 01 52 03 | D18: Drawing Reprographics | E18: ='1'!K93 -> 1055.3948
B19: 01 52 00 | C19: 01 52 04 | D19: First-Aid / Safety | E19: ='1'!K94 -> 2375
B20: 01 52 00 | C20: 01 52 05 | D20: Job Sign | E20: ='1'!K95 -> 200
B21: 01 54 00 | D21: Construction Aids | E21: ='1'!K105 -> 12471.036
B22: 01 55 00 | C22: 01 55 00 | D22: Winter Conditions
B23: 01 56 00 | D23: Temporary Barriers & Enclosures | E23: ='1'!K128 -> 22425
B24: 01 74 00 | D24: Cleaning & Waste Management | E24: ='1'!K136 -> 19859
B25: 01 74 00 | C25: 01 74 01 | D25: Progress Cleaning | E25: ='1'!K131 -> 0
B26: 01 74 00 | C26: 01 74 02 | D26: Site Maintenance | E26: ='1'!K132 -> 9750
B27: 01 74 00 | C27: 01 74 03 | D27: Construction Waste Mgmt & Disposal | E27: ='1'!K133 -> 3300
B28: 01 74 00 | C28: 01 74 04 | D28: Final Cleaning | E28: ='1'!K134 -> 6809
B29: 02 00 00 | D29: Existing Conditions | E29: ='Estimate Summary'!H17 -> 3600
B30: 02 41 00 | D30: Demolition | E30: ='2'!K26 -> 3600
B31: 02 82 00 | D31: Asbestos Remediation | E31: ='2'!K37 -> 0
B32: 02 83 00 | D32: Trenching | E32: ='2'!K48 -> 0
B33: 03 00 00 | D33: Concrete | E33: ='Estimate Summary'!H19 -> 142525.62
B34: 03 11 00 | D34: Concrete Forming | E34: ='3'!K26 -> 56820
B35: 03 20 00 | D35: Concrete Reinforcing | E35: ='3'!K37 -> 25280
B36: 03 30 00 | D36: Cast-in-Place Concrete | E36: ='3'!K52 -> 26603.125
B37: 03 35 00 | D37: Concrete Finishing | E37: ='3'!K65 -> 10447.2
B38: 03 40 00 | D38: Precast Concrete | E38: ='3'!K76 -> 0
B39: 03 60 00 | D39: Foundation Materials | E39: ='3'!K85 -> 23375.294
B40: 03 60 00 | C40: 03 60 01 | D40: Insulation | E40: ='3'!K79 -> 14977.625
...

Sheet DATA
B2: Quarter | C2: Column1 | D2: Province | H2: Project Definition | J2: Contract Type | K2: Payment Method | M2: A | N2: >5M
B3: Q1 | D3: NB | H3: Multi Residential | J3: CCDC 2 | K3: Stipulated Price | M3: B | N3: 2-5M
B4: Q2 | D4: PEI | H4: Office | J4: CCDC 5B | K4: Fixed Fee | M4: C | N4: 500K - 2M | R4: Status | T4: Result
B5: Q3 | D5: NS | H5: Retail | J5: CCDC 5A | M5: D | N5: 100K - 500K | R5: Awarded | T5: Successful
B6: Q4 | D6: Other | H6: Food | J6: Design Build | M6: E | N6: less than 100K | R6: Not Awarded | T6: Unsuccessful
R7: Pending
A10: Closing Date | B10: Budget Year | C10: Quarter | D10: Province | E10: City/Town | F10: Estimate Number | G10: Estimate Name | H10: Type of Construction | I10: Area | J10: Contract Type | K10: Payment Method | L10: Estimate Price | M10: Price Category | N10: Schedule | O10: Soft Cost | P10: Cost per Week | Q10: Margin | R10: Status | S10: Bid Docs | T10: Successful / Unsuccessful
A11: =+'Estimate Summary'!B3 -> January 29th, 2026 | B11: =+'Estimate Summary'!B7 -> 2026 | C11: =+'Estimate Summary'!B8 -> Q1 | D11: =+'Estimate Summary'!B5 -> NB | E11: ='Estimate Summary'!B6 -> St George | F11: ='Estimate Summary'!B4 -> 3091 | G11: ='Estimate Summary'!D5 -> St George YMCA Daycare | H11: =+'Estimate Summary'!F8 -> 0 | I11: =+'Estimate Summary'!D11 -> 6190 | J11: ='Estimate Summary'!D7 -> CCDC 2 | K11: =+'Estimate Summary'!D8 -> 0 | L11: =+'Estimate Summary'!D75 -> 2386430 | M11: =IF(L11<100000,"E",IF(L11<500000,"D",IF(L11<2000000,"C",IF(L11<5000000,"B",IF(L11>=5000000,"A"))))) -> B | N11: ='Estimate Summary'!D81 -> 38 | O11: ='Estimate Summary'!D82 -> 280996.93 | P11: ='Estimate Summary'!E82 -> 7394.6559 | Q11: ='Estimate Summary'!D84 -> 0.11774782 | R11: ='Estimate Summary'!F6 -> 0 | S11: ='Estimate Summary'!F5 -> 0 | T11: ='Estimate Summary'!F7 -> 0

Sheet Estimate Version Comparison
B2: ='Estimate Summary'!D5 -> St George YMCA Daycare | I2: CLIENT SUMMARY
B3: ='Estimate Summary'!D6 -> Eastern Chalotte/YMCA
B4: Date: | C4: ='Estimate Summary'!B3 -> January 29th, 2026
G7: ='Estimate Summary'!B3 -> January 29th, 2026 | H7: ='Estimate Summary'!G8 -> 0
B8: 01 00 00 | C8: General Requirements | E8: =SUM(D9:D17) -> 0 | H8: =SUM(G9:G17) -> 283378.64 | J8: =IF(H8>E8,"Increase","Decrease or No Change") -> Increase | K8: =H8-E8 -> 283378.64
B9: 01 11 00 | C9: Preconstruction Costs | D9: 0 | G9: ='1'!K24 -> 0
B10: 01 31 00 | C10: Project Management and Coordination | D10: 0 | G10: ='1'!K35 -> 183350
B11: 01 41 00 | C11: Permits | D11: 0 | G11: ='1'!K67 -> 17078.206
B12: 01 45 00 | C12: Quality Control | D12: 0 | G12: ='1'!K76 -> 8000
B13: 01 51 00 | C13: Temporary Utilities | D13: 0 | G13: ='1'!K87 -> 5700
B14: 01 52 00 | C14: Construction Facilities | D14: 0 | G14: ='1'!K97 -> 14495.395
B15: 01 54 00 | C15: Construction Aids | D15: 0 | G15: ='1'!K105 -> 12471.036
B16: 01 56 00 | C16: Temporary Barriers & Enclosures | D16: 0 | G16: ='1'!K128 -> 22425
B17: 01 74 00 | C17: Cleaning & Waste Management | D17: 0 | G17: ='1'!K136 -> 19859
B19: 02 00 00 | C19: Existing Conditions | E19: =SUM(D20:D22) -> 0 | H19: =SUM(G20:G22) -> 0 | J19: =IF(H19>E19,"Increase","Decrease or No Change") -> Decrease or No Change | K19: =H19-E19 -> 0
B20: 02 41 00 | C20: Demolition | D20: 0 | G20: ='2'!K13 -> 0
B21: 02 82 00 | C21: Asbestos Remediation | D21: 0 | G21: ='2'!K37 -> 0
B22: 02 83 00 | C22: Trenching | D22: 0 | G22: ='2'!K48 -> 0
B24: 03 00 00 | C24: Concrete | E24: =SUM(D25:D29) -> 0 | H24: =SUM(G25:G29) -> 142525.62 | J24: =IF(H24>E24,"Increase","Decrease or No Change") -> Increase | K24: =H24-E24 -> 142525.62
B25: 03 11 00 | C25: Concrete Forming | D25: 0 | G25: ='3'!K26 -> 56820
B26: 03 20 00 | C26: Concrete Reinforcing | D26: 0 | G26: ='3'!K37 -> 25280
B27: 03 30 00 | C27: Cast-in-Place Concrete | D27: 0 | G27: ='3'!K52+'3'!K65 -> 37050.325
B28: 03 40 00 | C28: Precast Concrete | D28: 0 | G28: ='3'!K76 -> 0
B29: 03 60 00 | C29: Grouting | D29: 0 | G29: ='3'!K85 -> 23375.294
B31: 04 00 00 | C31: Masonry | E31: =SUM(D32:D33) -> 0 | H31: =SUM(G32:G33) -> 0 | J31: =IF(H31>E31,"Increase","Decrease or No Change") -> Decrease or No Change | K31: =H31-E31 -> 0
B32: 04 20 00 | C32: Unit Masonry | D32: 0 | G32: ='4'!K26 -> 0
B33: 04 40 00 | C33: Stone Assemblies | D33: 0 | G33: ='4'!K37 -> 0
B35: 05 00 00 | C35: Metals | E35: =SUM(D36:D39) -> 0 | H35: =SUM(G36:G39) -> 0 | J35: =IF(H35>E35,"Increase","Decrease or No Change") -> Decrease or No Change | K35: =H35-E35 -> 0
B36: 05 12 00 | C36: Structural Steel Framing | D36: 0 | G36: ='5'!K26 -> 0
B37: 05 20 00 | C37: Metal Joists | D37: 0 | G37: ='5'!K37 -> 0
B38: 05 30 00 | C38: Metal Decking | D38: 0 | G38: ='5'!K45 -> 0
B39: 05 50 00 | C39: Metal Fabrications | D39: 0 | G39: ='5'!K54+'5'!K65+'5'!K74 -> 0
B41: 06 00 00 | C41: Wood, Plastics, and Composites | E41: =SUM(D42:D45) -> 0 | H41: =SUM(G42:G45) -> 337170.18 | J41: =IF(H41>E41,"Increase","Decrease or No Change") -> Increase | K41: =H41-E41 -> 337170.18
B42: 06 11 00 | C42: Framing Labour | D42: 0 | G42: ='6'!K29 -> 120000
B43: 06 11 00 | C43: Framing Material | D43: 0 | G43: ='6'!K76 -> 92676.18
B44: 06 22 00 | C44: Millwork | D44: 0 | G44: ='6'!K90 -> 124494
B45: 06 40 00 | C45: Architectural Woodwork | D45: 0 | G45: ='6'!K98+'6'!K107+'6'!K118+'6'!K127+'6'!K134 -> 0
B47: 07 00 00 | C47: Thermal and Moisture Protection | E47: =SUM(D48:D57) -> 0 | H47: =SUM(G48:G57) -> 142026.54 | J47: =IF(H47>E47,"Increase","Decrease or No Change") -> Increase | K47: =H47-E47 -> 142026.54
B48: 07 21 00 | C48: Thermal Insulation | D48: 0 | G48: ='7'!K32 -> 39041.34
B49: 07 24 00 | C49: EIFS | D49: 0 | G49: ='7'!K38 -> 0
...

Sheet Client  Detailed Summary 
B3: ='Estimate Summary'!D5 -> St George YMCA Daycare | F3: CLIENT SUMMARY
B4: ='Estimate Summary'!D6 -> Eastern Chalotte/YMCA
B5: Date: | C5: ='Estimate Summary'!B3 -> January 29th, 2026
B7: 01 00 00 | C7: General Requirements | H7: =SUM(G8:G17) -> 353890.15
B8: 01 11 00 | C8: Preconstruction Costs | G8: ='1'!K24 -> 0
B9: 01 31 00 | C9: Project Management and Coordination | G9: ='1'!K35 -> 183350
B10: 01 32 00 | C10: Insurance and Travel | G10: ='1'!K45+'1'!K56 -> 61946.518
B11: 01 41 00 | C11: Permits | G11: ='1'!K67 -> 17078.206
B12: 01 45 00 | C12: Quality Control | G12: ='1'!K76 -> 8000
B13: 01 51 00 | C13: Temporary Utilities | G13: ='1'!K87 -> 5700
B14: 01 52 00 | C14: Construction Facilities | G14: ='1'!K97 -> 14495.395
B15: 01 54 00 | C15: Construction Aids & Winter Conditions | G15: ='1'!K105+'1'!K120 -> 21036.036
B16: 01 56 00 | C16: Temporary Barriers & Enclosures | G16: ='1'!K128 -> 22425
B17: 01 74 00 | C17: Cleaning & Waste Management | G17: ='1'!K136 -> 19859
B19: 02 00 00 | C19: Existing Conditions | H19: =SUM(G20:G22) -> 0
B20: 02 41 00 | C20: Demolition | G20: $
B21: 02 82 00 | C21: Asbestos Remediation | G21: ='2'!K37 -> 0
B22: 02 83 00 | C22: Trenching | G22: ='2'!K48 -> 0
B24: 03 00 00 | C24: Concrete | H24: =SUM(G25:G29) -> 142525.62
B25: 03 11 00 | C25: Concrete Forming | G25: ='3'!K26 -> 56820
B26: 03 20 00 | C26: Concrete Reinforcing | G26: ='3'!K37 -> 25280
B27: 03 30 00 | C27: Cast-in-Place Concrete | G27: ='3'!K52+'3'!K65 -> 37050.325
B28: 03 40 00 | C28: Precast Concrete | G28: ='3'!K76 -> 0
B29: 03 60 00 | C29: Grouting | G29: ='3'!K85 -> 23375.294
B31: 04 00 00 | C31: Masonry | H31: =SUM(G32:G33) -> 0
B32: 04 20 00 | C32: Unit Masonry | G32: ='4'!K26 -> 0
B33: 04 40 00 | C33: Stone Assemblies | G33: ='4'!K37 -> 0
B35: 05 00 00 | C35: Metals | H35: =SUM(G36:G39) -> 0
B36: 05 12 00 | C36: Structural Steel Framing | G36: ='5'!K26 -> 0
B37: 05 20 00 | C37: Metal Joists | G37: ='5'!K37 -> 0
B38: 05 30 00 | C38: Metal Decking | G38: ='5'!K45 -> 0
B39: 05 50 00 | C39: Metal Fabrications | G39: ='5'!K54+'5'!K65+'5'!K74 -> 0
B41: 06 00 00 | C41: Wood, Plastics, and Composites | H41: =SUM(G42:G45) -> 337170.18
B42: 06 11 00 | C42: Framing Labour | G42: ='6'!K29 -> 120000
B43: 06 11 00 | C43: Framing Material | G43: ='6'!K76 -> 92676.18
B44: 06 22 00 | C44: Millwork | G44: ='6'!K90 -> 124494
B45: 06 40 00 | C45: Architectural Woodwork | G45: ='6'!K98+'6'!K107+'6'!K118+'6'!K127+'6'!K134 -> 0
B47: 07 00 00 | C47: Thermal and Moisture Protection | H47: =SUM(G48:G57) -> 142026.54
B48: 07 21 00 | C48: Thermal Insulation | G48: ='7'!K32 -> 39041.34
B49: 07 24 00 | C49: EIFS | G49: ='7'!K38 -> 0
...

Sheet Estimate Summary
A2: Project Information
A3: Closing Date : | B3: January 29th, 2026
A4: Estimate # E- | B4: 3091 | C4: Area: | D4: 6190
A5: Province : | B5: NB | C5: Estimate Name : | D5: St George YMCA Daycare | E5: Bid Documents :
A6: City/Town : | B6: St George | C6: Client : | D6: Eastern Chalotte/YMCA | E6: Status : | K6: =52-4 -> 48
A7: Budget Year : | B7: 2026 | C7: Contract Type : | D7: CCDC 2 | E7: Result:
A8: Quarter: | B8: Q1 | C8: Payment Method :
C11: Area: | D11: =D4 -> 6190 | E11: Sq. Ft. | K11: 2700 sf | L11: 12028 sf | M11: 11141 sf
A13: CODE | B13: DESCRIPTION | D13: M&E $$ | E13: M-HRS | F13: LAB $$ | G13: SUB CONT. | H13: Total | K13: Sackville Smiles | L13: Wee College MacNaughton | M13: Beaurivage Fire Hall
C14: % | I14: $/SF
A15: 01 00 00 | B15: General Requirements | C15: =H15/D$66 -> 0.15570739 | D15: =SUM('1'!F139:F140) -> 114680.95 | E15: =SUM('1'!G139:G140) -> 205 | F15: =SUM('1'!I139:I140) -> 193100 | G15: =SUM('1'!J139:J140) -> 46109.2 | H15: =D15+F15+G15 -> 353890.15 | I15: =ROUNDUP(H15/D$11,1)&"$/SF" -> 57.2$/SF | K15: 75.6$/SF | L15: 9.8$/SF | M15: 42.6$/SF
A17: 02 00 00 | B17: Existing Conditions | C17: =H17/D$66 -> 0.0015839565 | D17: =SUM('2'!F51:F52) -> 0 | E17: =SUM('2'!G51:G52) -> 0 | F17: =SUM('2'!I51:I52) -> 0 | G17: =SUM('2'!J51:J52) -> 3600 | H17: =D17+F17+G17 -> 3600 | I17: =ROUNDUP(H17/D$11,1)&"$/SF" -> 0.6$/SF | K17: 0$/SF | L17: 3.1$/SF | M17: 4.5$/SF
A19: 03 00 00 | B19: Concrete | C19: =H19/D$66 -> 0.062709549 | D19: =SUM('3'!F88:F89) -> 48158.419 | E19: =SUM('3'!G88:G89) -> 28 | F19: =SUM('3'!I88:I89) -> 1820 | G19: =SUM('3'!J88:J89) -> 92547.2 | H19: =D19+F19+G19 -> 142525.62 | I19: =ROUNDUP(H19/D$11,1)&"$/SF" -> 23.1$/SF | K19: 21.7$/SF | L19: 0$/SF | M19: 32.2$/SF
A21: 04 00 00 | B21: Masonry | C21: =H21/D$66 -> 0 | D21: =SUM('4'!F68:F69) -> 0 | E21: =SUM('4'!G68:G69) -> 0 | F21: =SUM('4'!I68:I69) -> 0 | G21: =SUM('4'!J68:J69) -> 0 | H21: =D21+F21+G21 -> 0 | I21: =ROUNDUP(H21/D$11,1)&"$/SF" -> 0$/SF | K21: 9.5$/SF | L21: 0$/SF | M21: 0$/SF
A23: 05 00 00 | B23: Metals | C23: =H23/D$66 -> 0 | D23: =SUM('5'!F77:F78) -> 0 | E23: =SUM('5'!G77:G78) -> 0 | F23: =SUM('5'!I77:I78) -> 0 | G23: =SUM('5'!J77:J78) -> 0 | H23: =D23+F23+G23 -> 0 | I23: =ROUNDUP(H23/D$11,1)&"$/SF" -> 0$/SF | K23: 0$/SF | L23: 0$/SF | M23: 17$/SF
A25: 06 00 00 | B25: Wood, Plastics, and Composites | C25: =H25/D$66 -> 0.1483508 | D25: =SUM('6'!F137:F138) -> 9500 | E25: =SUM('6'!G137:G138) -> 0 | F25: =SUM('6'!I137:I138) -> 0 | G25: =SUM('6'!J137:J138) -> 327670.18 | H25: =D25+F25+G25 -> 337170.18 | I25: =ROUNDUP(H25/D$11,1)&"$/SF" -> 54.5$/SF | K25: 40$/SF | L25: 0.2$/SF | M25: 36.2$/SF
A27: 07 00 00 | B27: Thermal and Moisture Protection | C27: =H27/D$66 -> 0.062489961 | D27: =SUM('7'!F137:F138) -> 2140 | E27: =SUM('7'!G137:G138) -> 0 | F27: =SUM('7'!I137:I138) -> 0 | G27: =SUM('7'!J137:J138) -> 139886.54 | H27: =D27+F27+G27 -> 142026.54 | I27: =ROUNDUP(H27/D$11,1)&"$/SF" -> 23$/SF | K27: 29.1$/SF | L27: 1.1$/SF | M27: 29.8$/SF
A29: 08 00 00 | B29: Openings | C29: =H29/D$66 -> 0.059911926 | D29: =SUM('8'!F128:F129) -> 21730.21 | E29: =SUM('8'!G128:G129) -> 56 | F29: =SUM('8'!I128:I129) -> 3640 | G29: =SUM('8'!J128:J129) -> 110797 | H29: =D29+F29+G29 -> 136167.21 | I29: =ROUNDUP(H29/D$11,1)&"$/SF" -> 22$/SF | K29: 22.4$/SF | L29: 5.3$/SF | M29: 25.3$/SF
A31: 09 00 00 | B31: Finishes | C31: =H31/D$66 -> 0.082600968 | D31: =SUM('9'!F77:F78) -> 0 | E31: =SUM('9'!G77:G78) -> 0 | F31: =SUM('9'!I77:I78) -> 0 | G31: =SUM('9'!J77:J78) -> 187734.63 | H31: =D31+F31+G31 -> 187734.63 | I31: =ROUNDUP(H31/D$11,1)&"$/SF" -> 30.4$/SF | K31: 42.2$/SF | L31: 16.5$/SF | M31: 15$/SF
A33: 10 00 00 | B33: Specialties | C33: =H33/D$66 -> 0.0047584693 | D33: =SUM('10'!F76:F77) -> 0 | E33: =SUM('10'!G76:G77) -> 32 | F33: =SUM('10'!I76:I77) -> 2080 | G33: =SUM('10'!J76:J77) -> 8735 | H33: =D33+F33+G33 -> 10815 | I33: =ROUNDUP(H33/D$11,1)&"$/SF" -> 1.8$/SF | K33: 2.3$/SF | L33: 2.3$/SF | M33: 3.8$/SF
A35: 11 00 00 | B35: Equipment | C35: =H35/D$66 -> 0 | D35: =SUM('11'!F99:F100) -> 0 | E35: =SUM('11'!G99:G100) -> 0 | F35: =SUM('11'!I99:I100) -> 0 | G35: =SUM('11'!J99:J100) -> 0 | H35: =D35+F35+G35 -> 0 | I35: =ROUNDUP(H35/D$11,1)&"$/SF" -> 0$/SF | K35: 0$/SF | L35: 0$/SF | M35: 0$/SF
A37: 12 00 00 | B37: Furnishings | C37: =H37/D$66 -> 0 | D37: =SUM('12'!F99:F100) -> 0 | E37: =SUM('12'!G99:G100) -> 0 | F37: =SUM('12'!I99:I100) -> 0 | G37: =SUM('12'!J99:J100) -> 0 | H37: =D37+F37+G37 -> 0 | I37: =ROUNDUP(H37/D$11,1)&"$/SF" -> 0$/SF | K37: 0.8$/SF | L37: 0.7$/SF | M37: 0.3$/SF
A39: 13 00 00 | B39: Special Construction | C39: =H39/D$66 -> 0 | D39: =+SUM('13'!F99:F100) -> 0 | E39: =SUM('13'!G99:G100) -> 0 | F39: =SUM('13'!I99:I100) -> 0 | G39: =SUM('13'!J99:J100) -> 0 | H39: =D39+F39+G39 -> 0 | I39: =ROUNDUP(H39/D$11,1)&"$/SF" -> 0$/SF | K39: 0$/SF | L39: 0$/SF | M39: 0$/SF
A41: 14 00 00 | B41: Conveying Equipment | C41: =H41/D$66 -> 0 | D41: =SUM('14'!F99:F100) -> 0 | E41: =SUM('14'!G99:G100) -> 0 | F41: =SUM('14'!I99:I100) -> 0 | G41: =SUM('14'!J99:J100) -> 0 | H41: =D41+F41+G41 -> 0 | I41: =ROUNDUP(H41/D$11,1)&"$/SF" -> 0$/SF | K41: 0$/SF | L41: 0$/SF | M41: 0$/SF
A43: 21 00 00 | B43: Fire Suppression | C43: =H43/D$66 -> 0 | D43: =SUM('21'!F99:F100) -> 0 | E43: =SUM('21'!G99:G100) -> 0 | F43: =SUM('21'!I99:I100) -> 0 | G43: =SUM('21'!J99:J100) -> 0 | H43: =D43+F43+G43 -> 0 | I43: =ROUNDUP(H43/D$11,1)&"$/SF" -> 0$/SF | K43: 0$/SF | L43: 22.3$/SF | M43: 0$/SF
A45: 22 00 00 | B45: Plumbing | C45: =H45/D$66 -> 0.049432642 | D45: =SUM('22'!F94:F95) -> 0 | E45: =SUM('22'!G94:G95) -> 0 | F45: =SUM('22'!I94:I95) -> 0 | G45: =SUM('22'!J94:J95) -> 112350 | H45: =D45+F45+G45 -> 112350 | I45: =ROUNDUP(H45/D$11,1)&"$/SF" -> 18.2$/SF | K45: 33.3$/SF | L45: 7.4$/SF | M45: 46.1$/SF
A47: 23 00 00 | B47: HVAC | C47: =H47/D$66 -> 0.058430395 | D47: =SUM('23'!F102:F103) -> 0 | E47: =SUM('23'!G102:G103) -> 0 | F47: =SUM('23'!I102:I103) -> 0 | G47: =SUM('23'!J102:J103) -> 132800 | H47: =D47+F47+G47 -> 132800 | I47: =ROUNDUP(H47/D$11,1)&"$/SF" -> 21.5$/SF | K47: 43.7$/SF | L47: 14.2$/SF | M47: 24.2$/SF
A49: 25 00 00 | B49: Integrated Automation | C49: =H49/D$66 -> 0 | D49: =SUM('25'!F54:F55) -> 0 | E49: =SUM('25'!G54:G55) -> 0 | F49: =SUM('25'!I54:I55) -> 0 | G49: =SUM('25'!J54:J55) -> 0 | H49: =D49+F49+G49 -> 0 | I49: =ROUNDUP(H49/D$11,1)&"$/SF" -> 0$/SF | K49: 0$/SF | L49: 0$/SF | M49: 0$/SF
A51: 26 00 00 | B51: Electrical | C51: =H51/D$66 -> 0.10426902 | D51: =SUM('26'!F57:F58) -> 0 | E51: =SUM('26'!G57:G58) -> 0 | F51: =SUM('26'!I57:I58) -> 0 | G51: =SUM('26'!J57:J58) -> 236981.55 | H51: =D51+F51+G51 -> 236981.55 | I51: =ROUNDUP(H51/D$11,1)&"$/SF" -> 38.3$/SF | K51: 64.9$/SF | L51: 14.3$/SF | M51: 46.7$/SF
A53: 27 00 00 | B53: Communications | C53: =H53/D$66 -> 0 | D53: =SUM('27'!F99:F100) -> 0 | E53: =SUM('27'!G99:G100) -> 0 | F53: =SUM('27'!I99:I100) -> 0 | G53: =SUM('27'!J99:J100) -> 0 | H53: =D53+F53+G53 -> 0 | I53: =ROUNDUP(H53/D$11,1)&"$/SF" -> 0$/SF | K53: 0$/SF | L53: 0$/SF | M53: 0$/SF
A55: 28 00 00 | B55: Electronic Safety and Security | C55: =H55/D$66 -> 0 | D55: =SUM('28'!F55:F56) -> 0 | E55: =SUM('28'!G55:G56) -> 0 | F55: =SUM('28'!I55:I56) -> 0 | G55: =SUM('28'!J55:J56) -> 0 | H55: =D55+F55+G55 -> 0 | I55: =ROUNDUP(H55/D$11,1)&"$/SF" -> 0$/SF | K55: 0$/SF | L55: 0$/SF | M55: 0$/SF
A57: 31 00 00 | B57: Earthwork | C57: =H57/D$66 -> 0.12285555 | D57: =SUM('31'!F89:F90) -> 0 | E57: =SUM('31'!G89:G90) -> 0 | F57: =SUM('31'!I89:I90) -> 0 | G57: =SUM('31'!J89:J90) -> 279224.83 | H57: =D57+F57+G57 -> 279224.83 | I57: =ROUNDUP(H57/D$11,1)&"$/SF" -> 45.2$/SF | K57: 102.9$/SF | L57: 3.3$/SF | M57: 43.4$/SF
A59: 32 00 00 | B59: Exterior Improvements | C59: =H59/D$66 -> 0.086899373 | D59: =SUM('32'!F105:F106) -> 0 | E59: =SUM('32'!G105:G106) -> 0 | F59: =SUM('32'!I105:I106) -> 0 | G59: =SUM('32'!J105:J106) -> 197504 | H59: =D59+F59+G59 -> 197504 | I59: =ROUNDUP(H59/D$11,1)&"$/SF" -> 32$/SF | K59: 59.3$/SF | L59: 0$/SF | M59: 17.4$/SF
A61: 33 00 00 | B61: Utilities | C61: =H61/D$66 -> 0 | D61: =SUM('33'!F57:F58) -> 0 | E61: =SUM('33'!G57:G58) -> 0 | F61: =SUM('33'!I57:I58) -> 0 | G61: =SUM('33'!J57:J58) -> 0 | H61: =D61+F61+G61 -> 0 | I61: =ROUNDUP(H61/D$11,1)&"$/SF" -> 0$/SF | K61: 0$/SF | L61: 0$/SF | M61: 0$/SF
B64: Sub Totals>>>>>> | C64: =SUM(C15:C63) -> 1 | D64: =SUM(D15:D63) -> 196209.58 | E64: =SUM(E15:E63) -> 321 | F64: =SUM(F15:F63) -> 200640 | G64: =SUM(G15:G63) -> 1875940.1 | H64: =SUM(H15:H63) -> 2272789.7 | I64: =ROUNDUP(H64/D$11,1)&"$/SF" -> 367.2$/SF | K64: 546.9$/SF | L64: 100$/SF | M64: 383.8$/SF
B66: Total Construction Cost>>>>>> | D66: =D64+F64+G64 -> 2272789.7 | K66: 1476573.9 | L66: 1201723.8 | M66: 4275638.2
B68: OH&P>>>>>> | D68: =(D66*E68) -> 90911.589 | E68: 0.04 | K68: 66445.827 | L68: 60086.19 | M68: 342051.06
B69: Bond Fee | D69: =+D66/1000*10 -> 22727.897 | F69: HST | G69: TOTAL | M69: 42756.382
D70: 0.8 | F70: 0.15
B71: Estimated Price | D71: =D68+D66+D69+D70 -> 2386430 | F71: =D71*F70 -> 357964.5 | G71: =D71+F71 -> 2744394.5 | K71: 1543019.8 | L71: 1261810 | M71: 4660445.6
...

Sheet 1
C1: ='Estimate Summary'!C1:H1 -> 0
G5: General Requirements | J5: Schedule
D6: ='Estimate Summary'!C11 -> Area: | E6: ='Estimate Summary'!D11 -> 6190 | F6: ='Estimate Summary'!E11 -> Sq. Ft. | J6: ='Estimate Summary'!D81 -> 38 | K6: Weeks
A9: CODE | B9: DESCRIPTION | C9: Materials & Equipment | G9: Labor | L9: Sub Contractor | M9: Quote Total | N9: Additional Quote Info
A10: 01 11 00 | B10: Preconstruction Costs | C10: Qty | D10: Unit | E10: U. Price | F10: Sub Total | G10: MHrs | H10: U. Price | I10: Sub Total | J10: Quote | K10: Total
A11: 01 11 13 | B11: Senior Construction Manager | D11: LS | E11: 0 | F11: =C11*E11 -> 0 | H11: 0 | I11: =G11*H11 -> 0 | K11: =F11+I11+J11 -> 0
A12: 01 11 16 | B12: Senior Estimator | D12: LS | E12: 0 | F12: =C12*E12 -> 0 | H12: 0 | I12: =G12*H12 -> 0 | K12: =F12+I12+J12 -> 0
A13: 01 11 19 | B13: Junior Estimator | D13: LS | E13: 0 | F13: =C13*E13 -> 0 | H13: 0 | I13: =G13*H13 -> 0 | K13: =F13+I13+J13 -> 0
A14: 01 11 23 | B14: Reprographics | D14: LS | E14: 0 | F14: =C14*E14 -> 0 | H14: 0 | I14: =G14*H14 -> 0 | K14: =F14+I14+J14 -> 0
A15: 01 11 26 | B15: Design Costs | D15: LS | E15: 0 | F15: =C15*E15 -> 0 | H15: 0 | I15: =G15*H15 -> 0 | K15: =F15+I15+J15 -> 0
A16: 01 11 26.13 | B16: Architectural | D16: LS | E16: 0 | F16: =C16*E16 -> 0 | H16: 0 | I16: =G16*H16 -> 0 | K16: =F16+I16+J16 -> 0
A17: 01 11 26.16 | B17: Civil | D17: LS | E17: 0 | F17: =C17*E17 -> 0 | H17: 0 | I17: =G17*H17 -> 0 | K17: =F17+I17+J17 -> 0
A18: 01 11 26.19 | B18: Structural | D18: LS | E18: 0 | F18: =C18*E18 -> 0 | H18: 0 | I18: =G18*H18 -> 0 | K18: =F18+I18+J18 -> 0
A19: 01 11 26.23 | B19: HVAC | D19: LS | E19: 0 | F19: =C19*E19 -> 0 | H19: 0 | I19: =G19*H19 -> 0 | K19: =F19+I19+J19 -> 0
A20: 01 11 26.26 | B20: Plumbing | D20: LS | E20: 0 | F20: =C20*E20 -> 0 | H20: 0 | I20: =G20*H20 -> 0 | K20: =F20+I20+J20 -> 0
A21: 01 11 26.29 | B21: Electrical | D21: LS | E21: 0 | F21: =C21*E21 -> 0 | H21: 0 | I21: =G21*H21 -> 0 | K21: =F21+I21+J21 -> 0
A22: 01 11 26.33 | B22: Geotechnical | D22: LS | E22: 0 | F22: =C22*E22 -> 0 | H22: 0 | I22: =G22*H22 -> 0 | K22: =F22+I22+J22 -> 0
J24: Sub Total | K24: =SUM(K11:K23) -> 0
A25: CODE | B25: DESCRIPTION | C25: Materials & Equipment | G25: Labor
A26: 01 31 00 | B26: Project Management and Coordination | C26: Qty | D26: Unit | E26: U. Price | F26: Sub Total | G26: MHrs | H26: U. Price | I26: Sub Total | J26: Quote | K26: Total
A27: 01 31 01 | B27: Senior Construction Manager | D27: LS | E27: 0 | F27: =C27*E27 -> 0 | H27: 0 | I27: =G27*H27 -> 0 | K27: =F27+I27+J27 -> 0
A28: 01 31 02 | B28: Senior Estimator | D28: LS | E28: 0 | F28: =C28*E28 -> 0 | H28: 0 | I28: =G28*H28 -> 0 | K28: =F28+I28+J28 -> 0
A29: 01 31 03 | B29: Senior Project Manager | C29: =J6 -> 38 | D29: LS | E29: 0 | F29: =C29*E29 -> 0 | G29: 10 | H29: 100 | I29: =H29*G29*C29 -> 38000 | K29: =F29+I29+J29 -> 38000
A30: 01 31 04 | B30: Project Coordinator | C30: =J6 -> 38 | D30: LS | E30: 0 | F30: =C30*E30 -> 0 | H30: 75 | I30: =H30*G30*C30 -> 0 | K30: =F30+I30+J30 -> 0
A31: 01 31 05 | B31: Project Superintendent | C31: =J6 -> 38 | D31: LS | E31: 0 | F31: =C31*E31 -> 0 | G31: 45 | H31: 85 | I31: =H31*G31*C31 -> 145350 | K31: =F31+I31+J31 -> 145350
A32: 01 31 06 | B32: Project Foreman | D32: LS | E32: 0 | F32: =C32*E32 -> 0 | H32: 0 | I32: =G32*H32 -> 0 | K32: =F32+I32+J32 -> 0
D33: LS | E33: 0 | F33: =C33*E33 -> 0 | H33: 0 | I33: =G33*H33 -> 0 | K33: =F33+I33+J33 -> 0
K34: =F34+I34+J34 -> 0
J35: Sub Total | K35: =SUM(K27:K34) -> 183350
A36: CODE | B36: DESCRIPTION
A37: 01 32 00 | B37: Insurance | D37: /$1000 | E37: Cost | F37: Rate | G37: Toll Cost | H37: Frequency | J37: Sub Total | K37: Total
A38: 01 32 01 | B38: General Liability & Contractor's Pollution Liability | C38: =SUM('Estimate Summary'!H17:H61)/1000 -> 1918.8996 | D38: /$1000 | E38: 0.63 | F38: =C38*E38 -> 1208.9067 | K38: =F38 -> 1208.9067
B39: Contractor's Pollution Liability | C39: =SUM('Estimate Summary'!H17:H61)/1000 -> 1918.8996 | D39: /$1000 | E39: 1.29 | F39: =C39*E39 -> 2475.3804 | K39: =F39 -> 2475.3804
B40: Builders Risk | C40: =+J6/4.5 -> 8.4444444 | D40: $1000/month | E40: 0.75 | F40: =C40*E40*C41 -> 12153.031 | K40: =F40 -> 12153.031
B41: Wrap-up Liability | C41: =SUM('Estimate Summary'!H17:H61)/1000 -> 1918.8996 | D41: /$1000 | F41: =C41*E41 -> 0 | K41: =F41 -> 0
A45: 01 32 00 | J45: Sub Total | K45: =SUM(K38:K44) -> 15837.318
A46: CODE | B46: DESCRIPTION | C46: Materials & Equipment | G46: Labor
A47: CODE | B47: DESCRIPTION
A48: 01 32 00 | B48: Travel | C48: Frequency | D48: Weeks | E48: Distance (Round Trip) | F48: Rate | G48: Toll Cost | H48: Frequency | J48: Sub Total | K48: Total
B49: PM KM | C49: 1 | D49: =J6 -> 38 | E49: =228*2 -> 456 | F49: 0.45 | H49: =C49*D49 -> 38 | J49: =C49*D49*E49*F49+G49*H49 -> 7797.6 | K49: =J49+(G49*H49) -> 7797.6
...

Sheet 2
C1: ='Estimate Summary'!C1:H1 -> 0
G5: Existing Conditions | J5: Schedule
D6: ='Estimate Summary'!C11 -> Area: | E6: ='Estimate Summary'!D11 -> 6190 | F6: ='Estimate Summary'!E11 -> Sq. Ft. | J6: ='1'!J6 -> 38 | K6: Weeks
A11: CODE | B11: DESCRIPTION | C11: Materials & Equipment | G11: Labor | L11: Sub Contractor | M11: Quote Total | N11: Additional Quote Info
A12: 02 00 00 | B12: Existing Conditions | C12: Qty | D12: Unit | E12: U. Price | F12: Sub Total | G12: MHrs | H12: U. Price | I12: Sub Total | J12: Quote | K12: Total
A13: 02 41 00 | B13: Demolition | D13: LS | E13: 0 | F13: =C13*E13 -> 0 | H13: 0 | I13: =G13*H13 -> 0 | K13: =F13+I13+J13 -> 0
B14: Removal and disposal of existing chain link fence at the skatepark | C14: 325 | D14: LF | E14: 0 | F14: =C14*E14 -> 0 | H14: 0 | I14: =G14*H14 -> 0 | J14: =M14 -> 3600 | K14: =F14+I14+J14 -> 3600 | L14: Fundy Fence | M14: 3600
D15: LS | E15: 0 | F15: =C15*E15 -> 0 | H15: 0 | I15: =G15*H15 -> 0 | K15: =F15+I15+J15 -> 0 | L15: Enviro | M15: 3900
D16: LS | E16: 0 | F16: =C16*E16 -> 0 | H16: 0 | I16: =G16*H16 -> 0 | K16: =F16+I16+J16 -> 0
D17: LS | E17: 0 | F17: =C17*E17 -> 0 | H17: 0 | I17: =G17*H17 -> 0 | K17: =F17+I17+J17 -> 0
D18: LS | E18: 0 | F18: =C18*E18 -> 0 | H18: 0 | I18: =G18*H18 -> 0 | K18: =F18+I18+J18 -> 0
D19: LS | E19: 0 | F19: =C19*E19 -> 0 | H19: 0 | I19: =G19*H19 -> 0 | K19: =F19+I19+J19 -> 0
D20: LS | E20: 0 | F20: =C20*E20 -> 0 | H20: 0 | I20: =G20*H20 -> 0 | K20: =F20+I20+J20 -> 0
D21: LS | E21: 0 | F21: =C21*E21 -> 0 | H21: 0 | I21: =G21*H21 -> 0 | K21: =F21+I21+J21 -> 0
D22: LS | E22: 0 | F22: =C22*E22 -> 0 | H22: 0 | I22: =G22*H22 -> 0 | K22: =F22+I22+J22 -> 0
D23: LS | E23: 0 | F23: =C23*E23 -> 0 | H23: 0 | I23: =G23*H23 -> 0 | K23: =F23+I23+J23 -> 0
D24: LS | E24: 0 | F24: =C24*E24 -> 0 | H24: 0 | I24: =G24*H24 -> 0 | K24: =F24+I24+J24 -> 0
J26: Sub Total | K26: =SUM(K13:K25) -> 3600
A27: CODE | B27: DESCRIPTION | C27: Materials & Equipment | G27: Labor
A28: 02 82 00 | B28: Asbestos Remediation | C28: Qty | D28: Unit | E28: U. Price | F28: Sub Total | G28: MHrs | H28: U. Price | I28: Sub Total | J28: Quote | K28: Total
D29: LS | E29: 0 | F29: =C29*E29 -> 0 | H29: 0 | I29: =G29*H29 -> 0 | K29: =F29+I29+J29 -> 0
D30: LS | E30: 0 | F30: =C30*E30 -> 0 | H30: 0 | I30: =G30*H30 -> 0 | K30: =F30+I30+J30 -> 0
D31: LS | E31: 0 | F31: =C31*E31 -> 0 | H31: 0 | I31: =G31*H31 -> 0 | K31: =F31+I31+J31 -> 0
D32: LS | E32: 0 | F32: =C32*E32 -> 0 | H32: 0 | I32: =G32*H32 -> 0 | K32: =F32+I32+J32 -> 0
D33: LS | E33: 0 | F33: =C33*E33 -> 0 | H33: 0 | I33: =G33*H33 -> 0 | K33: =F33+I33+J33 -> 0
D34: LS | E34: 0 | F34: =C34*E34 -> 0 | H34: 0 | I34: =G34*H34 -> 0 | K34: =F34+I34+J34 -> 0
D35: LS | E35: 0 | F35: =C35*E35 -> 0 | H35: 0 | I35: =G35*H35 -> 0 | K35: =F35+I35+J35 -> 0
J37: Sub Total | K37: =SUM(K29:K36) -> 0
A38: CODE | B38: DESCRIPTION | C38: Materials & Equipment | G38: Labor
A39: 02 83 00 | B39: Trenching | C39: Qty | D39: Unit | E39: U. Price | F39: Sub Total | G39: MHrs | H39: U. Price | I39: Sub Total | J39: Quote | K39: Total
D40: LS | E40: 0 | F40: =C40*E40 -> 0 | H40: 0 | I40: =G40*H40 -> 0 | K40: =F40+I40+J40 -> 0
B41: Sanitary Trenching | D41: ft | E41: 65 | F41: =C41*E41 -> 0 | H41: 0 | I41: =G41*H41 -> 0 | K41: =F41+I41+J41 -> 0
D42: LS | E42: 0 | F42: =C42*E42 -> 0 | H42: 0 | I42: =G42*H42 -> 0 | K42: =F42+I42+J42 -> 0
B43: Conduit Trenching | D43: ft | E43: 35 | F43: =C43*E43 -> 0 | H43: 0 | I43: =G43*H43 -> 0 | K43: =F43+I43+J43 -> 0
D44: LS | E44: 0 | F44: =C44*E44 -> 0 | H44: 0 | I44: =G44*H44 -> 0 | K44: =F44+I44+J44 -> 0
D45: LS | E45: 0 | F45: =C45*E45 -> 0 | H45: 0 | I45: =G45*H45 -> 0 | K45: =F45+I45+J45 -> 0
D46: LS | E46: 0 | F46: =C46*E46 -> 0 | H46: 0 | I46: =G46*H46 -> 0 | K46: =F46+I46+J46 -> 0
J48: Sub Total | K48: =SUM(K40:K47) -> 0
F49: Material Total | G49: Total Hours | I49: Labor Total | J49: Contractor Total | K49: TOTAL
A50: $ / Sq.Ft | B50: TOTAL DIVISION 2
...

Sheet 3
C1: ='Estimate Summary'!C1:H1 -> 0
G5: Concrete | J5: Schedule
D6: ='Estimate Summary'!C11 -> Area: | E6: ='Estimate Summary'!D11 -> 6190 | F6: ='Estimate Summary'!E11 -> Sq. Ft. | J6: ='1'!J6 -> 38 | K6: Weeks
A11: CODE | B11: DESCRIPTION | C11: Materials & Equipment | G11: Labor | L11: Sub Contractor | M11: Quote Total | N11: Additional Quote Info
A12: 03 11 00 | B12: Concrete Forming | C12: Qty | D12: Unit | E12: U. Price | F12: Sub Total | G12: MHrs | H12: U. Price | I12: Sub Total | J12: Quote | K12: Total
A13: 03 11 01 | B13: Contractor Quote | K13: =F13+I13+J13 -> 0
A14: 03 11 02.1 | B14: Footings | C14: =349*2 -> 698 | D14: LF | E14: 0 | F14: =C14*E14 -> 0 | H14: 0 | I14: =G14*H14 -> 0 | J14: 56820 | K14: =F14+I14+J14 -> 56820 | L14: Orr Foundation | M14: 56820 | N14: Includes Concrete for foundation (footings, walls, & 5 pillars)
A15: 03 11 02.2 | B15: Walls | C15: 3417 | D15: SF | E15: 0 | F15: =C15*E15 -> 0 | H15: 0 | I15: =G15*H15 -> 0 | K15: =F15+I15+J15 -> 0 | L15: Orr Foundation | M15: 38580 | N15: No concrete | O15: Difference | P15: =+M14-M15 -> 18240
A16: 03 11 02.3 | B16: Piers (300 dia; 1.5 m high) | C16: 5 | D16: EA | E16: 0 | F16: =C16*E16 -> 0 | H16: 0 | I16: =G16*H16 -> 0 | K16: =F16+I16+J16 -> 0 | L16: Arthur Sivret & fils
B17: Edges of slab - (350 LF) | D17: LS | E17: 0 | F17: =C17*E17 -> 0 | H17: 0 | I17: =G17*H17 -> 0 | K17: =F17+I17+J17 -> 0
D18: LS | E18: 0 | F18: =C18*E18 -> 0 | H18: 0 | I18: =G18*H18 -> 0 | K18: =F18+I18+J18 -> 0
D19: LS | E19: 0 | F19: =C19*E19 -> 0 | H19: 0 | I19: =G19*H19 -> 0 | K19: =F19+I19+J19 -> 0
D20: LS | E20: 0 | F20: =C20*E20 -> 0 | H20: 0 | I20: =G20*H20 -> 0 | K20: =F20+I20+J20 -> 0
J26: Sub Total | K26: =SUM(K13:K25) -> 56820
A27: CODE | B27: DESCRIPTION | C27: Materials & Equipment | G27: Labor
A28: 03 20 00 | B28: Concrete Reinforcing | C28: Qty | D28: Unit | E28: U. Price | F28: Sub Total | G28: MHrs | H28: U. Price | I28: Sub Total | J28: Quote | K28: Total
A29: 03 20 01 | B29: Contractor Quote | K29: =F29+I29+J29 -> 0 | T29: Type | U29: Width | W29: Height
A30: 03 20 02 | B30: Rebar | D30: LS | E30: 0 | F30: =C30*E30 -> 0 | H30: 0 | I30: =G30*H30 -> 0 | J30: =+M33 -> 16430 | K30: =F30+I30+J30 -> 16430 | L30: Harris Rebar | U30: A | V30: B | W30: D | X30: Quantity | Y30: Volume m3
A31: 03 20 03 | B31: Mesh | D31: LS | E31: 0 | F31: =C31*E31 -> 0 | H31: 0 | I31: =G31*H31 -> 0 | J31: =+M34 -> 8850 | K31: =F31+I31+J31 -> 8850 | L31: Osco Rebar | S31: Footings | T31: 1 | Y31: =U31*V31*W31*0.0000163871*X31 -> 0
D32: LS | E32: 0 | F32: =C32*E32 -> 0 | H32: 0 | I32: =G32*H32 -> 0 | K32: =F32+I32+J32 -> 0 | L32: Nucor Rebar | T32: 2 | Y32: =U32*V32*W32*0.0000163871*X32 -> 0
D33: LS | E33: 0 | F33: =C33*E33 -> 0 | H33: 0 | I33: =G33*H33 -> 0 | K33: =F33+I33+J33 -> 0 | L33: Rebar | M33: 16430 | U33: Length (FT) | V33: Width (ft) | W33: Height (ft)
D34: LS | E34: 0 | F34: =C34*E34 -> 0 | H34: 0 | I34: =G34*H34 -> 0 | K34: =F34+I34+J34 -> 0 | L34: Wire Mesh | M34: 8850 | S34: Strip Footing | Y34: =U34*V34*W34*0.028 -> 0
D35: LS | E35: 0 | F35: =C35*E35 -> 0 | H35: 0 | I35: =G35*H35 -> 0 | K35: =F35+I35+J35 -> 0 | S35: Walls | Y35: =U35*V35*W35*0.028 -> 0
S36: Piers | Y36: =U36*V36*W36*0.028*X36 -> 0
J37: Sub Total | K37: =SUM(K29:K36) -> 25280 | U37: Area (SF) | W37: Thickness (ft)
A38: CODE | B38: DESCRIPTION | C38: Materials & Equipment | G38: Labor | S38: Slab - ground floor | Y38: =U38*W38*0.028 -> 0
A39: 03 30 00 | B39: Cast-in-Place Concrete | C39: Qty | D39: Unit | E39: U. Price | F39: Sub Total | G39: MHrs | H39: U. Price | I39: Sub Total | J39: Quote | K39: Total | S39: Slab - 2nd floor | Y39: =U39*W39*0.028 -> 0
A40: 03 30 01 | B40: Slab - 35MPa | C40: 75 | D40: m3 | E40: =+N41 -> 287 | F40: =C40*E40 -> 21525 | H40: 0 | I40: =G40*H40 -> 0 | K40: =F40+I40+J40 -> 21525 | M40: 25 MPA | N40: 32MPA | O40: 35MPA
A41: 03 30 02 | B41: Footing - 25MPa | C41: 23 | D41: m3 | E41: =+M41 -> 267 | H41: 0 | I41: =G41*H41 -> 0 | K41: =F41+I41+J41 -> 0 | L41: Fundy Contractors | M41: 267 | N41: 287 | O41: 303 | S41: Exterior Pads | Y41: =U41*W41*0.028 -> 0
A42: 03 30 03 | B42: Foundation Wall + circular columns (5nrs) - 25MPa | C42: 33 | D42: m3 | E42: =E41 -> 267 | H42: 0 | I42: =G42*H42 -> 0 | K42: =F42+I42+J42 -> 0 | L42: Hi Roc
A43: 03 30 04 | B43: Exterior Concrete - Sidewalks -- 35MPa - (40m3) | D43: m3 | E43: =E40 -> 287 | F43: =C43*E43 -> 0 | H43: 0 | I43: =G43*H43 -> 0 | K43: =F43+I43+J43 -> 0 | L43: Benton
A44: 03 30 04 | B44: Exterior Concrete - On grade slab - 35MPa | C44: 5 | D44: m3 | E44: =E43 -> 287 | F44: =C44*E44 -> 1435 | H44: 0 | I44: =G44*H44 -> 0 | K44: =F44+I44+J44 -> 1435
A45: 03 30 04 | B45: Add waste for - 35MPa | C45: =(C40)*10% -> 7.5 | D45: m3 | E45: =E44 -> 287 | F45: =C45*E45 -> 2152.5 | H45: 0 | I45: =G45*H45 -> 0 | K45: =F45+I45+J45 -> 2152.5
A46: 03 30 04 | B46: Add waste for - 25MPa | C46: =(C41+C42)*10% -> 5.6 | D46: m3 | E46: =E40 -> 287 | H46: 0 | I46: =G46*H46 -> 0 | K46: =F46+I46+J46 -> 0
A47: 03 30 04 | B47: Pump | C47: =+C40 -> 75 | D47: m3 | E47: 3 | F47: =C47*E47 -> 225 | H47: 0 | I47: =G47*H47 -> 0 | K47: =F47+I47+J47 -> 225
A48: 03 30 04 | B48: Pump hours | C48: =C47/16 -> 4.6875 | D48: m3 | E48: 270 | F48: =C48*E48 -> 1265.625 | H48: 0 | I48: =G48*H48 -> 0 | K48: =F48+I48+J48 -> 1265.625
A49: 03 30 04 | B49: Heating | C49: =C47 -> 75 | D49: m3 | F49: =C49*E49 -> 0 | H49: 0 | I49: =G49*H49 -> 0 | K49: =F49+I49+J49 -> 0
D50: LS | E50: 0 | F50: =C50*E50 -> 0 | H50: 0 | I50: =G50*H50 -> 0 | K50: =F50+I50+J50 -> 0 | W50: Total Volume - Slab | Y50: =Y38+Y39 -> 0
A51: 03 30 04 | B51: Pump | D51: m3 | E51: 3 | F51: =C51*E51 -> 0 | H51: 0 | I51: =G51*H51 -> 0 | K51: =F51+I51+J51 -> 0 | W51: Total Volume - Footing | Y51: =Y31+Y32+Y34 -> 0
J52: Sub Total | K52: =SUM(K40:K51) -> 26603.125 | W52: Total Volume - Walls | Y52: =Y35+Y36 -> 0
...

Sheet 4
C1: ='Estimate Summary'!C1:H1 -> 0
G5: Masonry | J5: Schedule
D6: ='Estimate Summary'!C11 -> Area: | E6: ='Estimate Summary'!D11 -> 6190 | F6: ='Estimate Summary'!E11 -> Sq. Ft. | J6: ='1'!J6 -> 38 | K6: Weeks
A11: CODE | B11: DESCRIPTION | C11: Materials & Equipment | G11: Labor | L11: Sub Contractor | M11: Quote Total | N11: Additional Quote Info
A12: 04 20 00 | B12: Unit Masonry | C12: Qty | D12: Unit | E12: U. Price | F12: Sub Total | G12: MHrs | H12: U. Price | I12: Sub Total | J12: Quote | K12: Total
D13: LS | E13: 0 | F13: =C13*E13 -> 0 | H13: 0 | I13: =G13*H13 -> 0 | K13: =F13+I13+J13 -> 0
D14: LS | E14: 0 | F14: =C14*E14 -> 0 | H14: 0 | I14: =G14*H14 -> 0 | K14: =F14+I14+J14 -> 0
D15: LS | E15: 0 | F15: =C15*E15 -> 0 | H15: 0 | I15: =G15*H15 -> 0 | K15: =F15+I15+J15 -> 0
D16: LS | E16: 0 | F16: =C16*E16 -> 0 | H16: 0 | I16: =G16*H16 -> 0 | K16: =F16+I16+J16 -> 0
D17: LS | E17: 0 | F17: =C17*E17 -> 0 | H17: 0 | I17: =G17*H17 -> 0 | K17: =F17+I17+J17 -> 0
D18: LS | E18: 0 | F18: =C18*E18 -> 0 | H18: 0 | I18: =G18*H18 -> 0 | K18: =F18+I18+J18 -> 0
D19: LS | E19: 0 | F19: =C19*E19 -> 0 | H19: 0 | I19: =G19*H19 -> 0 | K19: =F19+I19+J19 -> 0
D20: LS | E20: 0 | F20: =C20*E20 -> 0 | H20: 0 | I20: =G20*H20 -> 0 | K20: =F20+I20+J20 -> 0
D21: LS | E21: 0 | F21: =C21*E21 -> 0 | H21: 0 | I21: =G21*H21 -> 0 | K21: =F21+I21+J21 -> 0
D22: LS | E22: 0 | F22: =C22*E22 -> 0 | H22: 0 | I22: =G22*H22 -> 0 | K22: =F22+I22+J22 -> 0
D23: LS | E23: 0 | F23: =C23*E23 -> 0 | H23: 0 | I23: =G23*H23 -> 0 | K23: =F23+I23+J23 -> 0
D24: LS | E24: 0 | F24: =C24*E24 -> 0 | H24: 0 | I24: =G24*H24 -> 0 | K24: =F24+I24+J24 -> 0
J26: Sub Total | K26: =SUM(K13:K25) -> 0
A27: CODE | B27: DESCRIPTION | C27: Materials & Equipment | G27: Labor
A28: 04 43 00 | B28: Stone Masonry | C28: Qty | D28: Unit | E28: U. Price | F28: Sub Total | G28: MHrs | H28: U. Price | I28: Sub Total | J28: Quote | K28: Total
D29: LS | E29: 0 | F29: =C29*E29 -> 0 | H29: 0 | I29: =G29*H29 -> 0 | K29: =F29+I29+J29 -> 0
D30: LS | E30: 0 | F30: =C30*E30 -> 0 | H30: 0 | I30: =G30*H30 -> 0 | K30: =F30+I30+J30 -> 0
D31: LS | E31: 0 | F31: =C31*E31 -> 0 | H31: 0 | I31: =G31*H31 -> 0 | K31: =F31+I31+J31 -> 0
D32: LS | E32: 0 | F32: =C32*E32 -> 0 | H32: 0 | I32: =G32*H32 -> 0 | K32: =F32+I32+J32 -> 0
D33: LS | E33: 0 | F33: =C33*E33 -> 0 | H33: 0 | I33: =G33*H33 -> 0 | K33: =F33+I33+J33 -> 0
D34: LS | E34: 0 | F34: =C34*E34 -> 0 | H34: 0 | I34: =G34*H34 -> 0 | K34: =F34+I34+J34 -> 0
D35: LS | E35: 0 | F35: =C35*E35 -> 0 | H35: 0 | I35: =G35*H35 -> 0 | K35: =F35+I35+J35 -> 0
J37: Sub Total | K37: =SUM(K29:K36) -> 0
A38: CODE | B38: DESCRIPTION | C38: Materials & Equipment | G38: Labor
C39: Qty | D39: Unit | E39: U. Price | F39: Sub Total | G39: MHrs | H39: U. Price | I39: Sub Total | J39: Quote | K39: Total
D40: LS | E40: 0 | F40: =C40*E40 -> 0 | H40: 0 | I40: =G40*H40 -> 0 | K40: =F40+I40+J40 -> 0
D41: LS | E41: 0 | F41: =C41*E41 -> 0 | H41: 0 | I41: =G41*H41 -> 0 | K41: =F41+I41+J41 -> 0
D42: LS | E42: 0 | F42: =C42*E42 -> 0 | H42: 0 | I42: =G42*H42 -> 0 | K42: =F42+I42+J42 -> 0
J45: Sub Total | K45: =SUM(K40:K44) -> 0
A46: CODE | B46: DESCRIPTION | C46: Materials & Equipment | G46: Labor
C47: Qty | D47: Unit | E47: U. Price | F47: Sub Total | G47: MHrs | H47: U. Price | I47: Sub Total | J47: Quote | K47: Total
D48: LS | E48: 0 | F48: =C48*E48 -> 0 | H48: 0 | I48: =G48*H48 -> 0 | K48: =F48+I48+J48 -> 0
D49: LS | E49: 0 | F49: =C49*E49 -> 0 | H49: 0 | I49: =G49*H49 -> 0 | K49: =F49+I49+J49 -> 0
D50: LS | E50: 0 | F50: =C50*E50 -> 0 | H50: 0 | I50: =G50*H50 -> 0 | K50: =F50+I50+J50 -> 0
D51: LS | E51: 0 | F51: =C51*E51 -> 0 | H51: 0 | I51: =G51*H51 -> 0 | K51: =F51+I51+J51 -> 0
...

Sheet 5
C1: ='Estimate Summary'!C1:H1 -> 0
G5: Metals | J5: Schedule
D6: ='Estimate Summary'!C11 -> Area: | E6: ='Estimate Summary'!D11 -> 6190 | F6: ='Estimate Summary'!E11 -> Sq. Ft. | J6: ='1'!J6 -> 38 | K6: Weeks
A11: CODE | B11: DESCRIPTION | C11: Materials & Equipment | G11: Labor | L11: Sub Contractor | M11: Quote Total | N11: Additional Quote Info
A12: 05 12 00 | B12: Structural Steel Framing | C12: Qty | D12: Unit | E12: U. Price | F12: Sub Total | G12: MHrs | H12: U. Price | I12: Sub Total | J12: Quote | K12: Total
D13: LS | E13: 0 | F13: =C13*E13 -> 0 | H13: 0 | I13: =G13*H13 -> 0 | K13: =F13+I13+J13 -> 0
D14: LS | E14: 0 | F14: =C14*E14 -> 0 | H14: 0 | I14: =G14*H14 -> 0 | K14: =F14+I14+J14 -> 0
D15: LS | E15: 0 | F15: =C15*E15 -> 0 | H15: 0 | I15: =G15*H15 -> 0 | K15: =F15+I15+J15 -> 0
D16: LS | E16: 0 | F16: =C16*E16 -> 0 | H16: 0 | I16: =G16*H16 -> 0 | K16: =F16+I16+J16 -> 0
D17: LS | E17: 0 | F17: =C17*E17 -> 0 | H17: 0 | I17: =G17*H17 -> 0 | K17: =F17+I17+J17 -> 0
D18: LS | E18: 0 | F18: =C18*E18 -> 0 | H18: 0 | I18: =G18*H18 -> 0 | K18: =F18+I18+J18 -> 0
D19: LS | E19: 0 | F19: =C19*E19 -> 0 | H19: 0 | I19: =G19*H19 -> 0 | K19: =F19+I19+J19 -> 0
D20: LS | E20: 0 | F20: =C20*E20 -> 0 | H20: 0 | I20: =G20*H20 -> 0 | K20: =F20+I20+J20 -> 0
D21: LS | E21: 0 | F21: =C21*E21 -> 0 | H21: 0 | I21: =G21*H21 -> 0 | K21: =F21+I21+J21 -> 0
D22: LS | E22: 0 | F22: =C22*E22 -> 0 | H22: 0 | I22: =G22*H22 -> 0 | K22: =F22+I22+J22 -> 0
D23: LS | E23: 0 | F23: =C23*E23 -> 0 | H23: 0 | I23: =G23*H23 -> 0 | K23: =F23+I23+J23 -> 0
D24: LS | E24: 0 | F24: =C24*E24 -> 0 | H24: 0 | I24: =G24*H24 -> 0 | K24: =F24+I24+J24 -> 0
J26: Sub Total | K26: =SUM(K13:K25) -> 0
A27: CODE | B27: DESCRIPTION | C27: Materials & Equipment | G27: Labor
A28: 05 20 00 | B28: Metal Joists | C28: Qty | D28: Unit | E28: U. Price | F28: Sub Total | G28: MHrs | H28: U. Price | I28: Sub Total | J28: Quote | K28: Total
D29: LS | E29: 0 | F29: =C29*E29 -> 0 | H29: 0 | I29: =G29*H29 -> 0 | K29: =F29+I29+J29 -> 0
D30: LS | E30: 0 | F30: =C30*E30 -> 0 | H30: 0 | I30: =G30*H30 -> 0 | K30: =F30+I30+J30 -> 0
D31: LS | E31: 0 | F31: =C31*E31 -> 0 | H31: 0 | I31: =G31*H31 -> 0 | K31: =F31+I31+J31 -> 0
D32: LS | E32: 0 | F32: =C32*E32 -> 0 | H32: 0 | I32: =G32*H32 -> 0 | K32: =F32+I32+J32 -> 0
D33: LS | E33: 0 | F33: =C33*E33 -> 0 | H33: 0 | I33: =G33*H33 -> 0 | K33: =F33+I33+J33 -> 0
D34: LS | E34: 0 | F34: =C34*E34 -> 0 | H34: 0 | I34: =G34*H34 -> 0 | K34: =F34+I34+J34 -> 0
D35: LS | E35: 0 | F35: =C35*E35 -> 0 | H35: 0 | I35: =G35*H35 -> 0 | K35: =F35+I35+J35 -> 0
J37: Sub Total | K37: =SUM(K29:K36) -> 0
A38: CODE | B38: DESCRIPTION | C38: Materials & Equipment | G38: Labor
A39: 05 30 00 | B39: Metal Decking | C39: Qty | D39: Unit | E39: U. Price | F39: Sub Total | G39: MHrs | H39: U. Price | I39: Sub Total | J39: Quote | K39: Total
D40: LS | E40: 0 | F40: =C40*E40 -> 0 | H40: 0 | I40: =G40*H40 -> 0 | K40: =F40+I40+J40 -> 0
D41: LS | E41: 0 | F41: =C41*E41 -> 0 | H41: 0 | I41: =G41*H41 -> 0 | K41: =F41+I41+J41 -> 0
D42: LS | E42: 0 | F42: =C42*E42 -> 0 | H42: 0 | I42: =G42*H42 -> 0 | K42: =F42+I42+J42 -> 0
J45: Sub Total | K45: =SUM(K40:K44) -> 0
A46: CODE | B46: DESCRIPTION | C46: Materials & Equipment | G46: Labor
A47: 05 51 00 | B47: Metal Stairs | C47: Qty | D47: Unit | E47: U. Price | F47: Sub Total | G47: MHrs | H47: U. Price | I47: Sub Total | J47: Quote | K47: Total
D48: LS | E48: 0 | F48: =C48*E48 -> 0 | H48: 0 | I48: =G48*H48 -> 0 | K48: =F48+I48+J48 -> 0
D49: LS | E49: 0 | F49: =C49*E49 -> 0 | H49: 0 | I49: =G49*H49 -> 0 | K49: =F49+I49+J49 -> 0
D50: LS | E50: 0 | F50: =C50*E50 -> 0 | H50: 0 | I50: =G50*H50 -> 0 | K50: =F50+I50+J50 -> 0
D51: LS | E51: 0 | F51: =C51*E51 -> 0 | H51: 0 | I51: =G51*H51 -> 0 | K51: =F51+I51+J51 -> 0
...

Sheet 6
C1: ='Estimate Summary'!C1:H1 -> 0
G5: Wood & Plastics | J5: Schedule
D6: ='Estimate Summary'!C11 -> Area: | E6: ='Estimate Summary'!D11 -> 6190 | F6: ='Estimate Summary'!E11 -> Sq. Ft. | J6: ='1'!J6 -> 38 | K6: Weeks
A9: CODE | B9: DESCRIPTION | C9: Materials & Equipment | G9: Labor | L9: Sub Contractor | M9: Quote Total | N9: Additional Quote Info
A10: 06 11 00 | B10: Framing Labour | C10: Qty | D10: Unit | E10: U. Price | F10: Sub Total | G10: MHrs | H10: U. Price | I10: Sub Total | J10: Quote | K10: Total
H11: 0 | I11: =G11*H11 -> 0 | J11: =M11 -> 120000 | K11: =F11+I11+J11 -> 120000 | L11: East Coast Framing | M11: 120000
B12: Wall framing | H12: 0 | I12: =G12*H12 -> 0 | K12: =F12+I12+J12 -> 0 | L12: Legacy Outdoors
B13: Roof framing | H13: 0 | I13: =G13*H13 -> 0 | K13: =F13+I13+J13 -> 0 | L13: Evolve Construction
B14: Wood siding installation | H14: 0 | I14: =G14*H14 -> 0 | J14: =M19 -> 0 | K14: =F14+I14+J14 -> 0 | L14: Burge Builders
H15: 0 | I15: =G15*H15 -> 0 | K15: =F15+I15+J15 -> 0 | L15: PLG Builders | M15: 189277.02 | N15: see Detailed breakdown
H16: 0 | I16: =G16*H16 -> 0 | K16: =F16+I16+J16 -> 0
H17: 0 | I17: =G17*H17 -> 0 | K17: =F17+I17+J17 -> 0
H18: 0 | I18: =G18*H18 -> 0 | K18: =F18+I18+J18 -> 0 | L18: Wood siding
H19: 0 | I19: =G19*H19 -> 0 | K19: =F19+I19+J19 -> 0 | L19: Evolve Construction | N19: Labour
H20: 0 | I20: =G20*H20 -> 0 | K20: =F20+I20+J20 -> 0
H21: 0 | I21: =G21*H21 -> 0 | K21: =F21+I21+J21 -> 0
H22: 0 | I22: =G22*H22 -> 0 | K22: =F22+I22+J22 -> 0
H23: 0 | I23: =G23*H23 -> 0 | K23: =F23+I23+J23 -> 0
H24: 0 | I24: =G24*H24 -> 0 | K24: =F24+I24+J24 -> 0
H25: 0 | I25: =G25*H25 -> 0 | K25: =F25+I25+J25 -> 0
H26: 0 | I26: =G26*H26 -> 0 | K26: =F26+I26+J26 -> 0 | L26: =K29+J32 -> 160299.55 | N26: Kent + East Coast | O26: =K29+K32 -> 160299.55
H27: 0 | I27: =G27*H27 -> 0 | K27: =F27+I27+J27 -> 0
J29: Sub Total | K29: =SUM(K11:K28) -> 120000
A30: 06 20 00 | B30: Framing Materials | C30: Qty | D30: Unit | E30: U. Price | F30: Sub Total | J30: Quote | K30: Total
L31: Lumber, strapping & Plywood
B32: 2x4 Stud | C32: 4408 | D32: ft | E32: 0.61 | J32: =M32 -> 40299.55 | K32: =F32+I32+J32 -> 40299.55 | L32: Kent Building Supplies | M32: 40299.55
B33: 2x6 Stud | C33: =9936+344 -> 10280 | D33: ft | E33: 1.05 | K33: =F33+I33+J33 -> 0
B34: 2x10 Lintel | C34: 669 | D34: ft | E34: 2.25 | K34: =F34+I34+J34 -> 0
B35: 2x4 Lintel | C35: 446 | D35: ft | E35: 0.61 | K35: =F35+I35+J35 -> 0
B36: 2x4 Perimeter blocking | C36: 1041 | D36: ft | E36: 0.61 | K36: =F36+I36+J36 -> 0
B37: 6"x6" wood post (3.1 m - 5 nrs) | C37: =12*5 -> 60 | D37: ft | E37: 5.85 | K37: =F37+I37+J37 -> 0
B38: 1x3 | D38: ft | E38: 0.25 | K38: =F38+I38+J38 -> 0
B39: 1x4 vertical strapping wall | C39: 3530 | D39: ft | E39: 0.46 | K39: =F39+I39+J39 -> 0
B40: 1x4 strapping ceiling | C40: 6190 | D40: ft | E40: 0.46 | K40: =F40+I40+J40 -> 0
B41: 2x10 | D41: ft | E41: 1.61 | K41: =F41+I41+J41 -> 0
B42: 1x3 | D42: ft | E42: 0.25 | K42: =F42+I42+J42 -> 0
B43: PLYWOOD | K43: =F43+I43+J43 -> 0
B44: 1/2" Standard | D44: EA | E44: 30.65 | K44: =F44+I44+J44 -> 0
B45: 5/8" Exterior - OSB - walls sheathing W1 | C45: =3530/32 -> 110.3125 | D45: EA | E45: 23.98 | K45: =F45+I45+J45 -> 0 | O45: Additional fee for crane service
B46: 5/8" Exterior - OSB- Roof gable sheathing - W2 | C46: =104/32 -> 3.25 | D46: EA | E46: =E45 -> 23.98 | K46: =F46+I46+J46 -> 0
...

Sheet 7
C1: ='Estimate Summary'!C1:H1 -> 0
G5: Thermal & Moisture Protection | J5: Schedule
D6: ='Estimate Summary'!C11 -> Area: | E6: ='Estimate Summary'!D11 -> 6190 | F6: ='Estimate Summary'!E11 -> Sq. Ft. | J6: ='1'!J6 -> 38 | K6: Weeks
A9: CODE | B9: DESCRIPTION | C9: Materials & Equipment | G9: Labor | L9: Sub Contractor | M9: Quote Total | N9: Additional Quote Info
A10: 07 21 00 | B10: Thermal Insulation | C10: Qty | D10: Unit | E10: U. Price | F10: Sub Total | G10: MHrs | H10: U. Price | I10: Sub Total | J10: Quote | K10: Total
A11: 07 21 16 | B11: Blanket Insulation | D11: LS | E11: 0 | F11: =C11*E11 -> 0 | H11: 0 | I11: =G11*H11 -> 0 | K11: =F11+I11+J11 -> 0
A12: 07 21 26 | B12: R-20 Batt insulation - Ext Wall W1 | C12: 3530 | D12: SF | F12: =C12*E12 -> 0 | H12: 0 | I12: =G12*H12 -> 0 | J12: =M15 -> 37853.11 | K12: =F12+I12+J12 -> 37853.11 | L12: Trinity Maintenance Solution | M12: 47789 | N12: All
A13: 07 21 26 | B13: Sound Batt insulation - Int wall P1, & P2 | C13: 5074 | D13: SF | E13: 0 | F13: =C13*E13 -> 0 | H13: 0 | I13: =G13*H13 -> 0 | K13: =F13+I13+J13 -> 0 | L13: Huff 'n' Puff
A14: 07 21 26 | B14: Mineral wool insulation - Int wall P3, & P4 | C14: 1010 | D14: SF | E14: 0 | F14: =C14*E14 -> 0 | H14: 0 | I14: =G14*H14 -> 0 | K14: =F14+I14+J14 -> 0
A15: 07 21 26 | B15: R-50 Blown-in cellulose Insulation - Roof R1 | C15: 6190 | D15: SF | E15: 0 | F15: =C15*E15 -> 0 | H15: 0 | I15: =G15*H15 -> 0 | K15: =F15+I15+J15 -> 0 | L15: Fundy Pros | M15: 37853.11 | N15: Cellulose, batt, sound, mineral wool
A16: 07 21 26 | B16: Blown Insulation | D16: LS | E16: 0 | F16: =C16*E16 -> 0 | H16: 0 | I16: =G16*H16 -> 0 | K16: =F16+I16+J16 -> 0 | L16: Fundy Pros | M16: 1188.23 | N16: Fire stopping
A17: 07 21 26 | B17: 6 Mil Vapour barrier | C17: 9614 | D17: SF | E17: 0 | F17: =C17*E17 -> 0 | H17: 0 | I17: =G17*H17 -> 0 | K17: =F17+I17+J17 -> 0
A18: 07 21 26 | B18: Air/weather barrier | C18: 3530 | D18: SF | E18: 0 | F18: =C18*E18 -> 0 | H18: 0 | I18: =G18*H18 -> 0 | K18: =F18+I18+J18 -> 0 | L18: Koop Insulation
A19: 07 21 29 | B19: Sprayed Insulation | D19: LS | E19: 0 | F19: =C19*E19 -> 0 | H19: 0 | I19: =G19*H19 -> 0 | K19: =F19+I19+J19 -> 0 | L19: Fire stopping | M19: 3500
D20: LS | E20: 0 | F20: =C20*E20 -> 0 | H20: 0 | I20: =G20*H20 -> 0 | K20: =F20+I20+J20 -> 0 | L20: Cellulose Blow Insul | M20: 21148.26
B21: Fire stopping | D21: LS | E21: 0 | F21: =C21*E21 -> 0 | H21: 0 | I21: =G21*H21 -> 0 | J21: =M16 -> 1188.23 | K21: =F21+I21+J21 -> 1188.23 | L21: Batt Insul | M21: 9199
D22: LS | E22: 0 | F22: =C22*E22 -> 0 | H22: 0 | I22: =G22*H22 -> 0 | K22: =F22+I22+J22 -> 0 | L22: Sound Batt | M22: 8446 | O22: 46847.2
D23: LS | E23: 0 | F23: =C23*E23 -> 0 | H23: 0 | I23: =G23*H23 -> 0 | K23: =F23+I23+J23 -> 0 | L23: Mineral wool | M23: 7184 | O23: =J67 -> 36630.2
D24: LS | E24: 0 | F24: =C24*E24 -> 0 | H24: 0 | I24: =G24*H24 -> 0 | K24: =F24+I24+J24 -> 0 | L24: Fuel/accommodation | M24: 4342 | O24: =O22-O23 -> 10217
D25: LS | E25: 0 | F25: =C25*E25 -> 0 | H25: 0 | I25: =G25*H25 -> 0 | K25: =F25+I25+J25 -> 0 | M25: =SUM(M19:M24) -> 53819.26
D26: LS | E26: 0 | F26: =C26*E26 -> 0 | H26: 0 | I26: =G26*H26 -> 0 | K26: =F26+I26+J26 -> 0
D27: LS | E27: 0 | F27: =C27*E27 -> 0 | H27: 0 | I27: =G27*H27 -> 0 | K27: =F27+I27+J27 -> 0
D28: LS | E28: 0 | F28: =C28*E28 -> 0 | H28: 0 | I28: =G28*H28 -> 0 | K28: =F28+I28+J28 -> 0 | L28: Precision | M28: 252990 | N28: Siding+ Insulation + trough + metal flashing
D29: LS | E29: 0 | F29: =C29*E29 -> 0 | H29: 0 | I29: =G29*H29 -> 0 | K29: =F29+I29+J29 -> 0
D30: LS | E30: 0 | F30: =C30*E30 -> 0 | H30: 0 | I30: =G30*H30 -> 0 | K30: =F30+I30+J30 -> 0
J32: Sub Total | K32: =SUM(K11:K31) -> 39041.34
A33: CODE | B33: DESCRIPTION | C33: Materials & Equipment | G33: Labor
A34: 07 24 00 | B34: EIFS | C34: Qty | D34: Unit | E34: U. Price | F34: Sub Total | G34: MHrs | H34: U. Price | I34: Sub Total | J34: Quote | K34: Total
D35: LS | E35: 0 | F35: =C35*E35 -> 0 | H35: 0 | I35: =G35*H35 -> 0 | K35: =F35+I35+J35 -> 0
D36: LS | E36: 0 | F36: =C36*E36 -> 0 | H36: 0 | I36: =G36*H36 -> 0 | K36: =F36+I36+J36 -> 0
D37: LS | E37: 0 | F37: =C37*E37 -> 0 | H37: 0 | I37: =G37*H37 -> 0 | K37: =F37+I37+J37 -> 0 | L37: Evolve Construction | M37: 46940 | N37: Siding + roofing +co labour
J38: Sub Total | K38: =SUM(K35:K37) -> 0
A39: CODE | B39: DESCRIPTION | C39: Materials & Equipment | G39: Labor
A40: 07 31 00 | B40: Shingles | C40: Qty | D40: Unit | E40: U. Price | F40: Sub Total | G40: MHrs | H40: U. Price | I40: Sub Total | J40: Quote | K40: Total | S40: 1254.54
B41: Asphalt shingles | C41: 6190 | D41: LS | E41: 0 | F41: =C41*E41 -> 0 | H41: 0 | I41: =G41*H41 -> 0 | K41: =F41+I41+J41 -> 0 | L41: Belvue Roofing | M41: 44398.12 | N41: Mat + Lab | S41: 504.7
B42: Material | D42: LS | E42: 0 | F42: =C42*E42 -> 0 | H42: 0 | I42: =G42*H42 -> 0 | J42: =+M49 -> 15275 | K42: =F42+I42+J42 -> 15275 | L42: GE Bourgoin | S42: 343.2
B43: Labour | D43: LS | E43: 0 | F43: =C43*E43 -> 0 | H43: 0 | I43: =G43*H43 -> 0 | J43: =M53 -> 12538 | K43: =F43+I43+J43 -> 12538 | L43: Evolve Construction | S43: 738
B44: labour | D44: LS | E44: 0 | F44: =C44*E44 -> 0 | H44: 0 | I44: =G44*H44 -> 0 | J44: 50 | K44: =F44+I44+J44 -> 50 | S44: 1107
D45: LS | E45: 0 | F45: =C45*E45 -> 0 | H45: 0 | I45: =G45*H45 -> 0 | K45: =F45+I45+J45 -> 0 | S45: 56.45
D46: LS | E46: 0 | F46: =C46*E46 -> 0 | H46: 0 | I46: =G46*H46 -> 0 | K46: =F46+I46+J46 -> 0 | L46: Kent Building Supplies | M46: 13924.85 | N46: Material | S46: =SUM(S40:S45) -> 4003.89
...

Sheet 8
C1: ='Estimate Summary'!C1:H1 -> 0
G5: Openings | J5: Schedule
D6: ='Estimate Summary'!C11 -> Area: | E6: ='Estimate Summary'!D11 -> 6190 | F6: ='Estimate Summary'!E11 -> Sq. Ft. | J6: ='1'!J6 -> 38 | K6: Weeks
A11: CODE | B11: DESCRIPTION | C11: Materials & Equipment | G11: Labor | L11: Sub Contractor | M11: Quote Total | N11: Additional Quote Info
A12: 08 11 00 | B12: Metal Doors and Frames | C12: Qty | D12: Unit | E12: U. Price | F12: Sub Total | G12: MHrs | H12: U. Price | I12: Sub Total | J12: Quote | K12: Total
A13: 08 11 13 | B13: Hollow Metal Doors and Frames: | D13: LS | E13: 0 | F13: =C13*E13 -> 0 | H13: 0 | I13: =G13*H13 -> 0 | J13: =M26 -> 105487 | K13: =F13+I13+J13 -> 105487
A14: 08 11 13 | B14: With insulated glass unit - Typ D: | D14: EA | E14: 0 | F14: =C14*E14 -> 0 | H14: 0 | I14: =G14*H14 -> 0 | K14: =F14+I14+J14 -> 0 | L14: All access | M14: 149410 | N14: Doors + Glazing + Hardwares
A15: 08 11 13 | B15: Double 915 x 2135 | C15: 1 | D15: EA | E15: 0 | F15: =C15*E15 -> 0 | G15: =C15*2 -> 2 | H15: 65 | I15: =G15*H15 -> 130 | K15: =F15+I15+J15 -> 130 | L15: Coastal Entrance Solution | M15: 112415
A16: 08 11 13 | B16: Single 915 x 2135 | C16: 2 | D16: EA | E16: 0 | F16: =C16*E16 -> 0 | G16: =C16*2 -> 4 | H16: 65 | I16: =G16*H16 -> 260 | K16: =F16+I16+J16 -> 260 | L16: Baytown Hardware Ltd | N16: note- remove glazing and hardware below
A17: 08 11 13 | B17: With cleared tempered glass - Typ D: | D17: EA | E17: 0 | F17: =C17*E17 -> 0 | H17: 0 | I17: =G17*H17 -> 0 | K17: =F17+I17+J17 -> 0 | L17: Legacy Outdoors
A18: 08 11 13 | B18: Double 915 x 2135 | C18: 1 | D18: EA | E18: 0 | F18: =C18*E18 -> 0 | G18: =C18*2 -> 2 | H18: 65 | I18: =G18*H18 -> 130 | K18: =F18+I18+J18 -> 130
A19: 08 11 13 | B19: Single 915 x 2135 | C19: 1 | D19: EA | E19: 0 | F19: =C19*E19 -> 0 | G19: =C19*2 -> 2 | H19: 65 | I19: =G19*H19 -> 130 | K19: =F19+I19+J19 -> 130 | L19: Baytown Hardware Ltd
A20: 08 11 13 | B20: Single 1220 x 2135 | C20: 1 | D20: EA | E20: 0 | F20: =C20*E20 -> 0 | G20: =C20*2 -> 2 | H20: 65 | I20: =G20*H20 -> 130 | K20: =F20+I20+J20 -> 130 | L20: HM Doors | M20: 29270
A21: 08 11 13 | B21: With cleared tempered glass - Typ C: | D21: EA | E21: 0 | F21: =C21*E21 -> 0 | H21: 0 | I21: =G21*H21 -> 0 | K21: =F21+I21+J21 -> 0 | L21: 6 stall Bobrick | M21: 5430 | N21: also in the Rodney in Div 10
A22: 08 11 13 | B22: Single 915 x 2135 | C22: 2 | D22: EA | E22: 0 | F22: =C22*E22 -> 0 | G22: =C22*2 -> 4 | H22: 65 | I22: =G22*H22 -> 260 | K22: =F22+I22+J22 -> 260 | L22: Door Accessories | M22: 310
A23: 08 11 13 | B23: With cleared tempered glass - Typ B: | D23: EA | E23: 0 | F23: =C23*E23 -> 0 | H23: 0 | I23: =G23*H23 -> 0 | K23: =F23+I23+J23 -> 0 | M23: 520
A24: 08 11 13 | B24: Single 915 x 2135 | C24: 3 | D24: EA | E24: 0 | F24: =C24*E24 -> 0 | G24: =C24*2 -> 6 | H24: 65 | I24: =G24*H24 -> 390 | K24: =F24+I24+J24 -> 390 | M24: 67
A25: 08 11 13 | B25: Single 915 x 2135 with Side lite | C25: 4 | D25: EA | E25: 0 | F25: =C25*E25 -> 0 | G25: =C25*2 -> 8 | H25: 65 | I25: =G25*H25 -> 520 | K25: =F25+I25+J25 -> 520 | L25: Hardwares + Install | M25: 69890
A26: 08 11 13 | B26: With no glazing: | D26: EA | E26: 0 | F26: =C26*E26 -> 0 | H26: 0 | I26: =G26*H26 -> 0 | K26: =F26+I26+J26 -> 0 | M26: =SUM(M20:M25) -> 105487
A27: 08 11 13 | B27: Single - 915 x 2135 - Typ A, 1HR fire rated | C27: 2 | D27: EA | E27: 0 | F27: =C27*E27 -> 0 | G27: =C27*2 -> 4 | H27: 65 | I27: =G27*H27 -> 260 | K27: =F27+I27+J27 -> 260
A28: 08 11 13 | B28: Single - 915 x 2135 - Typ A | C28: 10 | D28: EA | E28: 0 | F28: =C28*E28 -> 0 | G28: =C28*2 -> 20 | H28: 65 | I28: =G28*H28 -> 1300 | K28: =F28+I28+J28 -> 1300 | L28: Advantage Hardware | M28: 110000
A29: 08 11 13 | B29: Single - 915 x 2135 - Dutch door - Typ E | C29: 1 | D29: EA | E29: 0 | F29: =C29*E29 -> 0 | G29: =C29*2 -> 2 | H29: 65 | I29: =G29*H29 -> 130 | K29: =F29+I29+J29 -> 130
A30: 08 11 16 | B30: Aluminum Doors and Frames | D30: LS | E30: 0 | F30: =C30*E30 -> 0 | H30: 0 | I30: =G30*H30 -> 0 | K30: =F30+I30+J30 -> 0
D31: LS | E31: 0 | F31: =C31*E31 -> 0 | H31: 0 | I31: =G31*H31 -> 0 | K31: =F31+I31+J31 -> 0
D32: LS | E32: 0 | F32: =C32*E32 -> 0 | H32: 0 | I32: =G32*H32 -> 0 | K32: =F32+I32+J32 -> 0
M33: =K34+K101 -> 114437 | N33: Baytown + Glass guru + Labour
J34: Sub Total | K34: =SUM(K13:K33) -> 109127
A35: CODE | B35: DESCRIPTION | C35: Materials & Equipment | G35: Labor
A36: 08 14 00 | B36: Wood Doors | C36: Qty | D36: Unit | E36: U. Price | F36: Sub Total | G36: MHrs | H36: U. Price | I36: Sub Total | J36: Quote | K36: Total
D37: LS | E37: 0 | F37: =C37*E37 -> 0 | H37: 0 | I37: =G37*H37 -> 0 | K37: =F37+I37+J37 -> 0
D38: LS | E38: 0 | F38: =C38*E38 -> 0 | H38: 0 | I38: =G38*H38 -> 0 | K38: =F38+I38+J38 -> 0
D39: LS | E39: 0 | F39: =C39*E39 -> 0 | H39: 0 | I39: =G39*H39 -> 0 | K39: =F39+I39+J39 -> 0
J40: Sub Total | K40: =SUM(K37:K39) -> 0
A41: CODE | B41: DESCRIPTION | C41: Materials & Equipment | G41: Labor
A42: 08 31 00 | B42: Access Doors and Panels | C42: Qty | D42: Unit | E42: U. Price | F42: Sub Total | G42: MHrs | H42: U. Price | I42: Sub Total | J42: Quote | K42: Total
D43: LS | E43: 0 | F43: =C43*E43 -> 0 | H43: 0 | I43: =G43*H43 -> 0 | K43: =F43+I43+J43 -> 0
D44: LS | E44: 0 | F44: =C44*E44 -> 0 | H44: 0 | I44: =G44*H44 -> 0 | K44: =F44+I44+J44 -> 0
J45: Sub Total | K45: =SUM(K43:K44) -> 0
A46: CODE | B46: DESCRIPTION | C46: Materials & Equipment | G46: Labor
A47: 08 32 00 | B47: Sliding Gates | C47: Qty | D47: Unit | E47: U. Price | F47: Sub Total | G47: MHrs | H47: U. Price | I47: Sub Total | J47: Quote | K47: Total
...

Sheet 9
C1: ='Estimate Summary'!C1:H1 -> 0
G5: Finishes | J5: Schedule
D6: ='Estimate Summary'!C11 -> Area: | E6: ='Estimate Summary'!D11 -> 6190 | F6: ='Estimate Summary'!E11 -> Sq. Ft. | J6: ='1'!J6 -> 38 | K6: Weeks
A9: CODE | B9: DESCRIPTION | C9: Materials & Equipment | G9: Labor | L9: Sub Contractor | M9: Quote Total | N9: Additional Quote Info
A10: 09 20 00 | B10: Plaster and Gypsum Board | C10: Qty | D10: Unit | E10: U. Price | F10: Sub Total | G10: MHrs | H10: U. Price | I10: Sub Total | J10: Quote | K10: Total
B11: 5/8" Gypsum board | C11: 3530 | D11: SF | E11: 0 | F11: =C11*E11 -> 0 | H11: 0 | I11: =G11*H11 -> 0 | J11: =M12 -> 99233.36 | K11: =F11+I11+J11 -> 99233.36
